Workbook

Sheet Defaults
B1: Values in Model | C1: Original
A2: v | B2: =1/psi -> 6.6666667 | C2: =1/psi -> 6.6666667
A3: w | B3: =1/alpha -> -1 | C3: =1/alpha -> -1
A4: y | B4: =EXP(alpha*zeta) -> 0.29229258 | C4: =EXP(alpha*zeta) -> 0.29229258
A5: Beta | B5: 180 | C5: 180
A6: Theta | B6: 0.08 | C6: 0.017
A7: Gamma | B7: 0 | C7: 0
A8: Phi | B8: 0.018 | C8: 0.018
A9: alpha | B9: -1 | C9: -1
A10: psi | B10: 0.15 | C10: 0.15
A11: zeta | B11: 1.23 | C11: 1.23
A12: kappa | B12: 90 | C12: 90

Sheet S-Toll (All-Tax)
A1: Tau | B1: OldTau | C1: Size | D1: a | E1: b | F1: ij | G1: jj | H1: BUTIJ | I1: BUTII | J1: BCCIJ | K1: BCCJJ | L1: BCk | M1: BCS | N1: BCPTJJ | O1: BCPTIJ | P1: BCPTII | Q1: BRIJ | R1: BRJJ | S1: Toll | T1: Welfare | U1: Utility | V1: Profit | W1: Revenue | X1: Cost
A2: 0 | B2: 0 | C2: 10 | D2: 0 | E2: =Size-a -> 10 | F2: =(EXP(alpha*(Tau+OldTau+zeta-2*a*psi))*((EXP(alpha*a*psi)-EXP(alpha*b*psi))^2))/((EXP(alpha*a*psi)-EXP(alpha*(2*OldTau+b*psi)))*(alpha^2)*(psi^2)) -> 10.092146 | G2: =(EXP(alpha*(zeta+(2*b-a)*psi))*(-1+EXP(alpha*(-1)*Size*psi))*(EXP(alpha*(2*(Tau+OldTau)+a*psi))-EXP(alpha*(2*(Tau+OldTau)+b*psi))))/(((EXP(alpha*a*psi)-EXP(alpha*(2*OldTau+b*psi)))^2)*(alpha^2)*(psi^2)) -> 2.8986351 | H2: =-Beta/alpha -> 180 | I2: =(-EXP(alpha*zeta)*Beta*(-1+EXP(alpha*Size*psi)-Size*alpha*psi))/((alpha^3)*(psi^2)) -> 1690.9246 | J2: =Beta*Theta -> 14.4 | K2: =Beta*Theta -> 14.4 | L2: =kappa -> 90 | M2: =Gamma*Size -> 0 | N2: =Size*Beta*Phi -> 32.4 | O2: =-(EXP(alpha*a*psi)+EXP(alpha*b*psi)*(-1+Size*psi*alpha))*(Beta*Phi)/((alpha*psi)*(EXP(alpha*a*psi)-EXP(alpha*b*psi))) -> 12.294172 | P2: =(EXP(alpha*(zeta-a*psi))*Beta*Phi*(-EXP(alpha*a*psi)*(-2+(-1)*Size*alpha*psi)+EXP(alpha*b*psi)*(-2+Size*alpha*psi)))/((alpha^3)*(psi^3)) -> 78.836376 | Q2: =Tau*Beta -> 0 | R2: =Tau*Beta -> 0 | S2: =Tau -> 0 | T2: =Profit+Utility -> 3086.6096 | U2: =ij*BUTIJ+BUTII -> 3507.5109 | V2: =Revenue-Cost -> -420.90131 | W2: =(2*ij*BRIJ)+(2)*jj*BRJJ -> 0 | X2: =BCS+jj*BCPTJJ+2*(ij*BCPTIJ)+BCPTII -> 420.90131
A3: 0 | B3: 0 | C3: 10 | D3: 0 | E3: =Size-a -> 10 | F3: =(EXP(alpha*(Tau+OldTau+zeta-2*a*psi))*((EXP(alpha*a*psi)-EXP(alpha*b*psi))^2))/((EXP(alpha*a*psi)-EXP(alpha*(2*OldTau+b*psi)))*(alpha^2)*(psi^2)) -> 10.092146 | G3: =(EXP(alpha*(zeta+(2*b-a)*psi))*(-1+EXP(alpha*(-1)*Size*psi))*(EXP(alpha*(2*(Tau+OldTau)+a*psi))-EXP(alpha*(2*(Tau+OldTau)+b*psi))))/(((EXP(alpha*a*psi)-EXP(alpha*(2*OldTau+b*psi)))^2)*(alpha^2)*(psi^2)) -> 2.8986351 | H3: =-Beta/alpha -> 180 | I3: =(-EXP(alpha*zeta)*Beta*(-1+EXP(alpha*Size*psi)-Size*alpha*psi))/((alpha^3)*(psi^2)) -> 1690.9246 | J3: =Beta*Theta -> 14.4 | K3: =Beta*Theta -> 14.4 | L3: =kappa -> 90 | M3: =Gamma*Size -> 0 | N3: =Size*Beta*Phi -> 32.4 | O3: =-(EXP(alpha*a*psi)+EXP(alpha*b*psi)*(-1+Size*psi*alpha))*(Beta*Phi)/((alpha*psi)*(EXP(alpha*a*psi)-EXP(alpha*b*psi))) -> 12.294172 | P3: =(EXP(alpha*(zeta-a*psi))*Beta*Phi*(-EXP(alpha*a*psi)*(-2+(-1)*Size*alpha*psi)+EXP(alpha*b*psi)*(-2+Size*alpha*psi)))/((alpha^3)*(psi^3)) -> 78.836376 | Q3: =Tau*Beta -> 0 | R3: =Tau*Beta -> 0 | S3: =Tau -> 0 | T3: =Profit+Utility -> 2622.4751 | U3: =ij*BUTIJ+BUTII -> 3507.5109 | V3: =Revenue-Cost -> -885.03581 | W3: =(2*ij*BRIJ)+(2)*jj*BRJJ -> 0 | X3: =2*(ij*BCCIJ)+(2*jj*BCCJJ)+BCS+jj*BCPTJJ+2*(ij*BCPTIJ)+BCPTII+BCk -> 885.03581
A4: =A2+0.1 -> 0.1 | B4: 0 | C4: 10 | D4: 0 | E4: =Size-a -> 10 | F4: =(EXP(alpha*(Tau+OldTau+zeta-2*a*psi))*((EXP(alpha*a*psi)-EXP(alpha*b*psi))^2))/((EXP(alpha*a*psi)-EXP(alpha*(2*OldTau+b*psi)))*(alpha^2)*(psi^2)) -> 9.1317515 | G4: =(EXP(alpha*(zeta+(2*b-a)*psi))*(-1+EXP(alpha*(-1)*Size*psi))*(EXP(alpha*(2*(Tau+OldTau)+a*psi))-EXP(alpha*(2*(Tau+OldTau)+b*psi))))/(((EXP(alpha*a*psi)-EXP(alpha*(2*OldTau+b*psi)))^2)*(alpha^2)*(psi^2)) -> 2.3732017 | H4: =-Beta/alpha -> 180 | I4: =(-EXP(alpha*zeta)*Beta*(-1+EXP(alpha*Size*psi)-Size*alpha*psi))/((alpha^3)*(psi^2)) -> 1690.9246 | J4: =Beta*Theta -> 14.4 | K4: =Beta*Theta -> 14.4 | L4: =kappa -> 90 | M4: =Gamma*Size -> 0 | N4: =Size*Beta*Phi -> 32.4 | O4: =-(EXP(alpha*a*psi)+EXP(alpha*b*psi)*(-1+Size*psi*alpha))*(Beta*Phi)/((alpha*psi)*(EXP(alpha*a*psi)-EXP(alpha*b*psi))) -> 12.294172 | P4: =(EXP(alpha*(zeta-a*psi))*Beta*Phi*(-EXP(alpha*a*psi)*(-2+(-1)*Size*alpha*psi)+EXP(alpha*b*psi)*(-2+Size*alpha*psi)))/((alpha^3)*(psi^3)) -> 78.836376 | Q4: =Tau*Beta -> 18 | R4: =Tau*Beta -> 18 | S4: =Tau -> 0.1 | T4: =Profit+Utility -> 2947.2128 | U4: =ij*BUTIJ+BUTII -> 3334.6399 | V4: =Revenue-Cost -> -387.42709 | W4: =(2*ij*BRIJ)+(2)*jj*BRJJ -> 414.17831 | X4: =2*(ij*BCCIJ)+(2*jj*BCCJJ)+BCS+jj*BCPTJJ+2*(ij*BCPTIJ)+BCPTII+BCk -> 801.60541
A5: =A4+0.1 -> 0.2 | B5: 0 | C5: 10 | D5: 0 | E5: =Size-a -> 10 | F5: =(EXP(alpha*(Tau+OldTau+zeta-2*a*psi))*((EXP(alpha*a*psi)-EXP(alpha*b*psi))^2))/((EXP(alpha*a*psi)-EXP(alpha*(2*OldTau+b*psi)))*(alpha^2)*(psi^2)) -> 8.2627504 | G5: =(EXP(alpha*(zeta+(2*b-a)*psi))*(-1+EXP(alpha*(-1)*Size*psi))*(EXP(alpha*(2*(Tau+OldTau)+a*psi))-EXP(alpha*(2*(Tau+OldTau)+b*psi))))/(((EXP(alpha*a*psi)-EXP(alpha*(2*OldTau+b*psi)))^2)*(alpha^2)*(psi^2)) -> 1.9430132 | H5: =-Beta/alpha -> 180 | I5: =(-EXP(alpha*zeta)*Beta*(-1+EXP(alpha*Size*psi)-Size*alpha*psi))/((alpha^3)*(psi^2)) -> 1690.9246 | J5: =Beta*Theta -> 14.4 | K5: =Beta*Theta -> 14.4 | L5: =kappa -> 90 | M5: =Gamma*Size -> 0 | N5: =Size*Beta*Phi -> 32.4 | O5: =-(EXP(alpha*a*psi)+EXP(alpha*b*psi)*(-1+Size*psi*alpha))*(Beta*Phi)/((alpha*psi)*(EXP(alpha*a*psi)-EXP(alpha*b*psi))) -> 12.294172 | P5: =(EXP(alpha*(zeta-a*psi))*Beta*Phi*(-EXP(alpha*a*psi)*(-2+(-1)*Size*alpha*psi)+EXP(alpha*b*psi)*(-2+Size*alpha*psi)))/((alpha^3)*(psi^3)) -> 78.836376 | Q5: =Tau*Beta -> 36 | R5: =Tau*Beta -> 36 | S5: =Tau -> 0.2 | T5: =Profit+Utility -> 3184.1513 | U5: =ij*BUTIJ+BUTII -> 3178.2197 | V5: =Revenue-Cost -> 5.9316365 | W5: =(2*ij*BRIJ)+(2)*jj*BRJJ -> 734.81498 | X5: =2*(ij*BCCIJ)+(2*jj*BCCJJ)+BCS+jj*BCPTJJ+2*(ij*BCPTIJ)+BCPTII+BCk -> 728.88334
A6: =A5+0.1 -> 0.3 | B6: 0 | C6: 10 | D6: 0 | E6: =Size-a -> 10 | F6: =(EXP(alpha*(Tau+OldTau+zeta-2*a*psi))*((EXP(alpha*a*psi)-EXP(alpha*b*psi))^2))/((EXP(alpha*a*psi)-EXP(alpha*(2*OldTau+b*psi)))*(alpha^2)*(psi^2)) -> 7.4764457 | G6: =(EXP(alpha*(zeta+(2*b-a)*psi))*(-1+EXP(alpha*(-1)*Size*psi))*(EXP(alpha*(2*(Tau+OldTau)+a*psi))-EXP(alpha*(2*(Tau+OldTau)+b*psi))))/(((EXP(alpha*a*psi)-EXP(alpha*(2*OldTau+b*psi)))^2)*(alpha^2)*(psi^2)) -> 1.5908047 | H6: =-Beta/alpha -> 180 | I6: =(-EXP(alpha*zeta)*Beta*(-1+EXP(alpha*Size*psi)-Size*alpha*psi))/((alpha^3)*(psi^2)) -> 1690.9246 | J6: =Beta*Theta -> 14.4 | K6: =Beta*Theta -> 14.4 | L6: =kappa -> 90 | M6: =Gamma*Size -> 0 | N6: =Size*Beta*Phi -> 32.4 | O6: =-(EXP(alpha*a*psi)+EXP(alpha*b*psi)*(-1+Size*psi*alpha))*(Beta*Phi)/((alpha*psi)*(EXP(alpha*a*psi)-EXP(alpha*b*psi))) -> 12.294172 | P6: =(EXP(alpha*(zeta-a*psi))*Beta*Phi*(-EXP(alpha*a*psi)*(-2+(-1)*Size*alpha*psi)+EXP(alpha*b*psi)*(-2+Size*alpha*psi)))/((alpha^3)*(psi^3)) -> 78.836376 | Q6: =Tau*Beta -> 54 | R6: =Tau*Beta -> 54 | S6: =Tau -> 0.3 | T6: =Profit+Utility -> 3350.5992 | U6: =ij*BUTIJ+BUTII -> 3036.6849 | V6: =Revenue-Cost -> 313.91437 | W6: =(2*ij*BRIJ)+(2)*jj*BRJJ -> 979.26304 | X6: =2*(ij*BCCIJ)+(2*jj*BCCJJ)+BCS+jj*BCPTJJ+2*(ij*BCPTIJ)+BCPTII+BCk -> 665.34868
A7: =A6+0.1 -> 0.4 | B7: 0 | C7: 10 | D7: 0 | E7: =Size-a -> 10 | F7: =(EXP(alpha*(Tau+OldTau+zeta-2*a*psi))*((EXP(alpha*a*psi)-EXP(alpha*b*psi))^2))/((EXP(alpha*a*psi)-EXP(alpha*(2*OldTau+b*psi)))*(alpha^2)*(psi^2)) -> 6.7649679 | G7: =(EXP(alpha*(zeta+(2*b-a)*psi))*(-1+EXP(alpha*(-1)*Size*psi))*(EXP(alpha*(2*(Tau+OldTau)+a*psi))-EXP(alpha*(2*(Tau+OldTau)+b*psi))))/(((EXP(alpha*a*psi)-EXP(alpha*(2*OldTau+b*psi)))^2)*(alpha^2)*(psi^2)) -> 1.3024407 | H7: =-Beta/alpha -> 180 | I7: =(-EXP(alpha*zeta)*Beta*(-1+EXP(alpha*Size*psi)-Size*alpha*psi))/((alpha^3)*(psi^2)) -> 1690.9246 | J7: =Beta*Theta -> 14.4 | K7: =Beta*Theta -> 14.4 | L7: =kappa -> 90 | M7: =Gamma*Size -> 0 | N7: =Size*Beta*Phi -> 32.4 | O7: =-(EXP(alpha*a*psi)+EXP(alpha*b*psi)*(-1+Size*psi*alpha))*(Beta*Phi)/((alpha*psi)*(EXP(alpha*a*psi)-EXP(alpha*b*psi))) -> 12.294172 | P7: =(EXP(alpha*(zeta-a*psi))*Beta*Phi*(-EXP(alpha*a*psi)*(-2+(-1)*Size*alpha*psi)+EXP(alpha*b*psi)*(-2+Size*alpha*psi)))/((alpha^3)*(psi^3)) -> 78.836376 | Q7: =Tau*Beta -> 72 | R7: =Tau*Beta -> 72 | S7: =Tau -> 0.4 | T7: =Profit+Utility -> 3460.6095 | U7: =ij*BUTIJ+BUTII -> 2908.6188 | V7: =Revenue-Cost -> 551.99066 | W7: =(2*ij*BRIJ)+(2)*jj*BRJJ -> 1161.7068 | X7: =2*(ij*BCCIJ)+(2*jj*BCCJJ)+BCS+jj*BCPTJJ+2*(ij*BCPTIJ)+BCPTII+BCk -> 609.71618
A8: =A7+0.1 -> 0.5 | B8: 0 | C8: 10 | D8: 0 | E8: =Size-a -> 10 | F8: =(EXP(alpha*(Tau+OldTau+zeta-2*a*psi))*((EXP(alpha*a*psi)-EXP(alpha*b*psi))^2))/((EXP(alpha*a*psi)-EXP(alpha*(2*OldTau+b*psi)))*(alpha^2)*(psi^2)) -> 6.1211961 | G8: =(EXP(alpha*(zeta+(2*b-a)*psi))*(-1+EXP(alpha*(-1)*Size*psi))*(EXP(alpha*(2*(Tau+OldTau)+a*psi))-EXP(alpha*(2*(Tau+OldTau)+b*psi))))/(((EXP(alpha*a*psi)-EXP(alpha*(2*OldTau+b*psi)))^2)*(alpha^2)*(psi^2)) -> 1.0663483 | H8: =-Beta/alpha -> 180 | I8: =(-EXP(alpha*zeta)*Beta*(-1+EXP(alpha*Size*psi)-Size*alpha*psi))/((alpha^3)*(psi^2)) -> 1690.9246 | J8: =Beta*Theta -> 14.4 | K8: =Beta*Theta -> 14.4 | L8: =kappa -> 90 | M8: =Gamma*Size -> 0 | N8: =Size*Beta*Phi -> 32.4 | O8: =-(EXP(alpha*a*psi)+EXP(alpha*b*psi)*(-1+Size*psi*alpha))*(Beta*Phi)/((alpha*psi)*(EXP(alpha*a*psi)-EXP(alpha*b*psi))) -> 12.294172 | P8: =(EXP(alpha*(zeta-a*psi))*Beta*Phi*(-EXP(alpha*a*psi)*(-2+(-1)*Size*alpha*psi)+EXP(alpha*b*psi)*(-2+Size*alpha*psi)))/((alpha^3)*(psi^3)) -> 78.836376 | Q8: =Tau*Beta -> 90 | R8: =Tau*Beta -> 90 | S8: =Tau -> 0.5 | T8: =Profit+Utility -> 3525.6005 | U8: =ij*BUTIJ+BUTII -> 2792.7399 | V8: =Revenue-Cost -> 732.86057 | W8: =(2*ij*BRIJ)+(2)*jj*BRJJ -> 1293.758 | X8: =2*(ij*BCCIJ)+(2*jj*BCCJJ)+BCS+jj*BCPTJJ+2*(ij*BCPTIJ)+BCPTII+BCk -> 560.89741
A9: =A8+0.1 -> 0.6 | B9: 0 | C9: 10 | D9: 0 | E9: =Size-a -> 10 | F9: =(EXP(alpha*(Tau+OldTau+zeta-2*a*psi))*((EXP(alpha*a*psi)-EXP(alpha*b*psi))^2))/((EXP(alpha*a*psi)-EXP(alpha*(2*OldTau+b*psi)))*(alpha^2)*(psi^2)) -> 5.5386872 | G9: =(EXP(alpha*(zeta+(2*b-a)*psi))*(-1+EXP(alpha*(-1)*Size*psi))*(EXP(alpha*(2*(Tau+OldTau)+a*psi))-EXP(alpha*(2*(Tau+OldTau)+b*psi))))/(((EXP(alpha*a*psi)-EXP(alpha*(2*OldTau+b*psi)))^2)*(alpha^2)*(psi^2)) -> 0.87305211 | H9: =-Beta/alpha -> 180 | I9: =(-EXP(alpha*zeta)*Beta*(-1+EXP(alpha*Size*psi)-Size*alpha*psi))/((alpha^3)*(psi^2)) -> 1690.9246 | J9: =Beta*Theta -> 14.4 | K9: =Beta*Theta -> 14.4 | L9: =kappa -> 90 | M9: =Gamma*Size -> 0 | N9: =Size*Beta*Phi -> 32.4 | O9: =-(EXP(alpha*a*psi)+EXP(alpha*b*psi)*(-1+Size*psi*alpha))*(Beta*Phi)/((alpha*psi)*(EXP(alpha*a*psi)-EXP(alpha*b*psi))) -> 12.294172 | P9: =(EXP(alpha*(zeta-a*psi))*Beta*Phi*(-EXP(alpha*a*psi)*(-2+(-1)*Size*alpha*psi)+EXP(alpha*b*psi)*(-2+Size*alpha*psi)))/((alpha^3)*(psi^3)) -> 78.836376 | Q9: =Tau*Beta -> 108 | R9: =Tau*Beta -> 108 | S9: =Tau -> 0.6 | T9: =Profit+Utility -> 3554.8555 | U9: =ij*BUTIJ+BUTII -> 2687.8883 | V9: =Revenue-Cost -> 866.9672 | W9: =(2*ij*BRIJ)+(2)*jj*BRJJ -> 1384.9357 | X9: =2*(ij*BCCIJ)+(2*jj*BCCJJ)+BCS+jj*BCPTJJ+2*(ij*BCPTIJ)+BCPTII+BCk -> 517.9685
A10: =A9+0.1 -> 0.7 | B10: 0 | C10: 10 | D10: 0 | E10: =Size-a -> 10 | F10: =(EXP(alpha*(Tau+OldTau+zeta-2*a*psi))*((EXP(alpha*a*psi)-EXP(alpha*b*psi))^2))/((EXP(alpha*a*psi)-EXP(alpha*(2*OldTau+b*psi)))*(alpha^2)*(psi^2)) -> 5.0116115 | G10: =(EXP(alpha*(zeta+(2*b-a)*psi))*(-1+EXP(alpha*(-1)*Size*psi))*(EXP(alpha*(2*(Tau+OldTau)+a*psi))-EXP(alpha*(2*(Tau+OldTau)+b*psi))))/(((EXP(alpha*a*psi)-EXP(alpha*(2*OldTau+b*psi)))^2)*(alpha^2)*(psi^2)) -> 0.71479461 | H10: =-Beta/alpha -> 180 | I10: =(-EXP(alpha*zeta)*Beta*(-1+EXP(alpha*Size*psi)-Size*alpha*psi))/((alpha^3)*(psi^2)) -> 1690.9246 | J10: =Beta*Theta -> 14.4 | K10: =Beta*Theta -> 14.4 | L10: =kappa -> 90 | M10: =Gamma*Size -> 0 | N10: =Size*Beta*Phi -> 32.4 | O10: =-(EXP(alpha*a*psi)+EXP(alpha*b*psi)*(-1+Size*psi*alpha))*(Beta*Phi)/((alpha*psi)*(EXP(alpha*a*psi)-EXP(alpha*b*psi))) -> 12.294172 | P10: =(EXP(alpha*(zeta-a*psi))*Beta*Phi*(-EXP(alpha*a*psi)*(-2+(-1)*Size*alpha*psi)+EXP(alpha*b*psi)*(-2+Size*alpha*psi)))/((alpha^3)*(psi^3)) -> 78.836376 | Q10: =Tau*Beta -> 126 | R10: =Tau*Beta -> 126 | S10: =Tau -> 0.7 | T10: =Profit+Utility -> 3555.9256 | U10: =ij*BUTIJ+BUTII -> 2593.0147 | V10: =Revenue-Cost -> 962.91089 | W10: =(2*ij*BRIJ)+(2)*jj*BRJJ -> 1443.0543 | X10: =2*(ij*BCCIJ)+(2*jj*BCCJJ)+BCS+jj*BCPTJJ+2*(ij*BCPTIJ)+BCPTII+BCk -> 480.14344
A11: =A10+0.1 -> 0.8 | B11: 0 | C11: 10 | D11: 0 | E11: =Size-a -> 10 | F11: =(EXP(alpha*(Tau+OldTau+zeta-2*a*psi))*((EXP(alpha*a*psi)-EXP(alpha*b*psi))^2))/((EXP(alpha*a*psi)-EXP(alpha*(2*OldTau+b*psi)))*(alpha^2)*(psi^2)) -> 4.5346936 | G11: =(EXP(alpha*(zeta+(2*b-a)*psi))*(-1+EXP(alpha*(-1)*Size*psi))*(EXP(alpha*(2*(Tau+OldTau)+a*psi))-EXP(alpha*(2*(Tau+OldTau)+b*psi))))/(((EXP(alpha*a*psi)-EXP(alpha*(2*OldTau+b*psi)))^2)*(alpha^2)*(psi^2)) -> 0.58522433 | H11: =-Beta/alpha -> 180 | I11: =(-EXP(alpha*zeta)*Beta*(-1+EXP(alpha*Size*psi)-Size*alpha*psi))/((alpha^3)*(psi^2)) -> 1690.9246 | J11: =Beta*Theta -> 14.4 | K11: =Beta*Theta -> 14.4 | L11: =kappa -> 90 | M11: =Gamma*Size -> 0 | N11: =Size*Beta*Phi -> 32.4 | O11: =-(EXP(alpha*a*psi)+EXP(alpha*b*psi)*(-1+Size*psi*alpha))*(Beta*Phi)/((alpha*psi)*(EXP(alpha*a*psi)-EXP(alpha*b*psi))) -> 12.294172 | P11: =(EXP(alpha*(zeta-a*psi))*Beta*Phi*(-EXP(alpha*a*psi)*(-2+(-1)*Size*alpha*psi)+EXP(alpha*b*psi)*(-2+Size*alpha*psi)))/((alpha^3)*(psi^3)) -> 78.836376 | Q11: =Tau*Beta -> 144 | R11: =Tau*Beta -> 144 | S11: =Tau -> 0.8 | T11: =Profit+Utility -> 3534.9539 | U11: =ij*BUTIJ+BUTII -> 2507.1695 | V11: =Revenue-Cost -> 1027.7845 | W11: =(2*ij*BRIJ)+(2)*jj*BRJJ -> 1474.5364 | X11: =2*(ij*BCCIJ)+(2*jj*BCCJJ)+BCS+jj*BCPTJJ+2*(ij*BCPTIJ)+BCPTII+BCk -> 446.75188
A12: =A11+0.1 -> 0.9 | B12: 0 | C12: 10 | D12: 0 | E12: =Size-a -> 10 | F12: =(EXP(alpha*(Tau+OldTau+zeta-2*a*psi))*((EXP(alpha*a*psi)-EXP(alpha*b*psi))^2))/((EXP(alpha*a*psi)-EXP(alpha*(2*OldTau+b*psi)))*(alpha^2)*(psi^2)) -> 4.1031604 | G12: =(EXP(alpha*(zeta+(2*b-a)*psi))*(-1+EXP(alpha*(-1)*Size*psi))*(EXP(alpha*(2*(Tau+OldTau)+a*psi))-EXP(alpha*(2*(Tau+OldTau)+b*psi))))/(((EXP(alpha*a*psi)-EXP(alpha*(2*OldTau+b*psi)))^2)*(alpha^2)*(psi^2)) -> 0.47914116 | H12: =-Beta/alpha -> 180 | I12: =(-EXP(alpha*zeta)*Beta*(-1+EXP(alpha*Size*psi)-Size*alpha*psi))/((alpha^3)*(psi^2)) -> 1690.9246 | J12: =Beta*Theta -> 14.4 | K12: =Beta*Theta -> 14.4 | L12: =kappa -> 90 | M12: =Gamma*Size -> 0 | N12: =Size*Beta*Phi -> 32.4 | O12: =-(EXP(alpha*a*psi)+EXP(alpha*b*psi)*(-1+Size*psi*alpha))*(Beta*Phi)/((alpha*psi)*(EXP(alpha*a*psi)-EXP(alpha*b*psi))) -> 12.294172 | P12: =(EXP(alpha*(zeta-a*psi))*Beta*Phi*(-EXP(alpha*a*psi)*(-2+(-1)*Size*alpha*psi)+EXP(alpha*b*psi)*(-2+Size*alpha*psi)))/((alpha^3)*(psi^3)) -> 78.836376 | Q12: =Tau*Beta -> 162 | R12: =Tau*Beta -> 162 | S12: =Tau -> 0.9 | T12: =Profit+Utility -> 3496.9385 | U12: =ij*BUTIJ+BUTII -> 2429.4935 | V12: =Revenue-Cost -> 1067.445 | W12: =(2*ij*BRIJ)+(2)*jj*BRJJ -> 1484.6657 | X12: =2*(ij*BCCIJ)+(2*jj*BCCJJ)+BCS+jj*BCPTJJ+2*(ij*BCPTIJ)+BCPTII+BCk -> 417.22075
A13: =A12+0.1 -> 1 | B13: 0 | C13: 10 | D13: 0 | E13: =Size-a -> 10 | F13: =(EXP(alpha*(Tau+OldTau+zeta-2*a*psi))*((EXP(alpha*a*psi)-EXP(alpha*b*psi))^2))/((EXP(alpha*a*psi)-EXP(alpha*(2*OldTau+b*psi)))*(alpha^2)*(psi^2)) -> 3.7126931 | G13: =(EXP(alpha*(zeta+(2*b-a)*psi))*(-1+EXP(alpha*(-1)*Size*psi))*(EXP(alpha*(2*(Tau+OldTau)+a*psi))-EXP(alpha*(2*(Tau+OldTau)+b*psi))))/(((EXP(alpha*a*psi)-EXP(alpha*(2*OldTau+b*psi)))^2)*(alpha^2)*(psi^2)) -> 0.3922876 | H13: =-Beta/alpha -> 180 | I13: =(-EXP(alpha*zeta)*Beta*(-1+EXP(alpha*Size*psi)-Size*alpha*psi))/((alpha^3)*(psi^2)) -> 1690.9246 | J13: =Beta*Theta -> 14.4 | K13: =Beta*Theta -> 14.4 | L13: =kappa -> 90 | M13: =Gamma*Size -> 0 | N13: =Size*Beta*Phi -> 32.4 | O13: =-(EXP(alpha*a*psi)+EXP(alpha*b*psi)*(-1+Size*psi*alpha))*(Beta*Phi)/((alpha*psi)*(EXP(alpha*a*psi)-EXP(alpha*b*psi))) -> 12.294172 | P13: =(EXP(alpha*(zeta-a*psi))*Beta*Phi*(-EXP(alpha*a*psi)*(-2+(-1)*Size*alpha*psi)+EXP(alpha*b*psi)*(-2+Size*alpha*psi)))/((alpha^3)*(psi^3)) -> 78.836376 | Q13: =Tau*Beta -> 180 | R13: =Tau*Beta -> 180 | S13: =Tau -> 1 | T13: =Profit+Utility -> 3445.9435 | U13: =ij*BUTIJ+BUTII -> 2359.2094 | V13: =Revenue-Cost -> 1086.7341 | W13: =(2*ij*BRIJ)+(2)*jj*BRJJ -> 1477.793 | X13: =2*(ij*BCCIJ)+(2*jj*BCCJJ)+BCS+jj*BCPTJJ+2*(ij*BCPTIJ)+BCPTII+BCk -> 391.05891
A14: =A13+0.1 -> 1.1 | B14: 0 | C14: 10 | D14: 0 | E14: =Size-a -> 10 | F14: =(EXP(alpha*(Tau+OldTau+zeta-2*a*psi))*((EXP(alpha*a*psi)-EXP(alpha*b*psi))^2))/((EXP(alpha*a*psi)-EXP(alpha*(2*OldTau+b*psi)))*(alpha^2)*(psi^2)) -> 3.3593836 | G14: =(EXP(alpha*(zeta+(2*b-a)*psi))*(-1+EXP(alpha*(-1)*Size*psi))*(EXP(alpha*(2*(Tau+OldTau)+a*psi))-EXP(alpha*(2*(Tau+OldTau)+b*psi))))/(((EXP(alpha*a*psi)-EXP(alpha*(2*OldTau+b*psi)))^2)*(alpha^2)*(psi^2)) -> 0.32117792 | H14: =-Beta/alpha -> 180 | I14: =(-EXP(alpha*zeta)*Beta*(-1+EXP(alpha*Size*psi)-Size*alpha*psi))/((alpha^3)*(psi^2)) -> 1690.9246 | J14: =Beta*Theta -> 14.4 | K14: =Beta*Theta -> 14.4 | L14: =kappa -> 90 | M14: =Gamma*Size -> 0 | N14: =Size*Beta*Phi -> 32.4 | O14: =-(EXP(alpha*a*psi)+EXP(alpha*b*psi)*(-1+Size*psi*alpha))*(Beta*Phi)/((alpha*psi)*(EXP(alpha*a*psi)-EXP(alpha*b*psi))) -> 12.294172 | P14: =(EXP(alpha*(zeta-a*psi))*Beta*Phi*(-EXP(alpha*a*psi)*(-2+(-1)*Size*alpha*psi)+EXP(alpha*b*psi)*(-2+Size*alpha*psi)))/((alpha^3)*(psi^3)) -> 78.836376 | Q14: =Tau*Beta -> 198 | R14: =Tau*Beta -> 198 | S14: =Tau -> 1.1 | T14: =Profit+Utility -> 3385.2717 | U14: =ij*BUTIJ+BUTII -> 2295.6137 | V14: =Revenue-Cost -> 1089.658 | W14: =(2*ij*BRIJ)+(2)*jj*BRJJ -> 1457.5024 | X14: =2*(ij*BCCIJ)+(2*jj*BCCJJ)+BCS+jj*BCPTJJ+2*(ij*BCPTIJ)+BCPTII+BCk -> 367.84439
A15: =A14+0.1 -> 1.2 | B15: 0 | C15: 10 | D15: 0 | E15: =Size-a -> 10 | F15: =(EXP(alpha*(Tau+OldTau+zeta-2*a*psi))*((EXP(alpha*a*psi)-EXP(alpha*b*psi))^2))/((EXP(alpha*a*psi)-EXP(alpha*(2*OldTau+b*psi)))*(alpha^2)*(psi^2)) -> 3.039696 | G15: =(EXP(alpha*(zeta+(2*b-a)*psi))*(-1+EXP(alpha*(-1)*Size*psi))*(EXP(alpha*(2*(Tau+OldTau)+a*psi))-EXP(alpha*(2*(Tau+OldTau)+b*psi))))/(((EXP(alpha*a*psi)-EXP(alpha*(2*OldTau+b*psi)))^2)*(alpha^2)*(psi^2)) -> 0.26295824 | H15: =-Beta/alpha -> 180 | I15: =(-EXP(alpha*zeta)*Beta*(-1+EXP(alpha*Size*psi)-Size*alpha*psi))/((alpha^3)*(psi^2)) -> 1690.9246 | J15: =Beta*Theta -> 14.4 | K15: =Beta*Theta -> 14.4 | L15: =kappa -> 90 | M15: =Gamma*Size -> 0 | N15: =Size*Beta*Phi -> 32.4 | O15: =-(EXP(alpha*a*psi)+EXP(alpha*b*psi)*(-1+Size*psi*alpha))*(Beta*Phi)/((alpha*psi)*(EXP(alpha*a*psi)-EXP(alpha*b*psi))) -> 12.294172 | P15: =(EXP(alpha*(zeta-a*psi))*Beta*Phi*(-EXP(alpha*a*psi)*(-2+(-1)*Size*alpha*psi)+EXP(alpha*b*psi)*(-2+Size*alpha*psi)))/((alpha^3)*(psi^3)) -> 78.836376 | Q15: =Tau*Beta -> 216 | R15: =Tau*Beta -> 216 | S15: =Tau -> 1.2 | T15: =Profit+Utility -> 3317.6028 | U15: =ij*BUTIJ+BUTII -> 2238.0699 | V15: =Revenue-Cost -> 1079.5329 | W15: =(2*ij*BRIJ)+(2)*jj*BRJJ -> 1426.7466 | X15: =2*(ij*BCCIJ)+(2*jj*BCCJJ)+BCS+jj*BCPTJJ+2*(ij*BCPTIJ)+BCPTII+BCk -> 347.21376
A16: =A15+0.1 -> 1.3 | B16: 0 | C16: 10 | D16: 0 | E16: =Size-a -> 10 | F16: =(EXP(alpha*(Tau+OldTau+zeta-2*a*psi))*((EXP(alpha*a*psi)-EXP(alpha*b*psi))^2))/((EXP(alpha*a*psi)-EXP(alpha*(2*OldTau+b*psi)))*(alpha^2)*(psi^2)) -> 2.7504307 | G16: =(EXP(alpha*(zeta+(2*b-a)*psi))*(-1+EXP(alpha*(-1)*Size*psi))*(EXP(alpha*(2*(Tau+OldTau)+a*psi))-EXP(alpha*(2*(Tau+OldTau)+b*psi))))/(((EXP(alpha*a*psi)-EXP(alpha*(2*OldTau+b*psi)))^2)*(alpha^2)*(psi^2)) -> 0.215292 | H16: =-Beta/alpha -> 180 | I16: =(-EXP(alpha*zeta)*Beta*(-1+EXP(alpha*Size*psi)-Size*alpha*psi))/((alpha^3)*(psi^2)) -> 1690.9246 | J16: =Beta*Theta -> 14.4 | K16: =Beta*Theta -> 14.4 | L16: =kappa -> 90 | M16: =Gamma*Size -> 0 | N16: =Size*Beta*Phi -> 32.4 | O16: =-(EXP(alpha*a*psi)+EXP(alpha*b*psi)*(-1+Size*psi*alpha))*(Beta*Phi)/((alpha*psi)*(EXP(alpha*a*psi)-EXP(alpha*b*psi))) -> 12.294172 | P16: =(EXP(alpha*(zeta-a*psi))*Beta*Phi*(-EXP(alpha*a*psi)*(-2+(-1)*Size*alpha*psi)+EXP(alpha*b*psi)*(-2+Size*alpha*psi)))/((alpha^3)*(psi^3)) -> 78.836376 | Q16: =Tau*Beta -> 234 | R16: =Tau*Beta -> 234 | S16: =Tau -> 1.3 | T16: =Profit+Utility -> 3245.1072 | U16: =ij*BUTIJ+BUTII -> 2186.0022 | V16: =Revenue-Cost -> 1059.105 | W16: =(2*ij*BRIJ)+(2)*jj*BRJJ -> 1387.9582 | X16: =2*(ij*BCCIJ)+(2*jj*BCCJJ)+BCS+jj*BCPTJJ+2*(ij*BCPTIJ)+BCPTII+BCk -> 328.85319
... A51: =A50+0.1 -> 4.8 | B51: 0 | C51: 10 | D51: 0 | E51: =Size-a -> 10 | F51: =(EXP(alpha*(Tau+OldTau+zeta-2*a*psi))*((EXP(alpha*a*psi)-EXP(alpha*b*psi))^2))/((EXP(alpha*a*psi)-EXP(alpha*(2*OldTau+b*psi)))*(alpha^2)*(psi^2)) -> 0.08305581 | G51: =(EXP(alpha*(zeta+(2*b-a)*psi))*(-1+EXP(alpha*(-1)*Size*psi))*(EXP(alpha*(2*(Tau+OldTau)+a*psi))-EXP(alpha*(2*(Tau+OldTau)+b*psi))))/(((EXP(alpha*a*psi)-EXP(alpha*(2*OldTau+b*psi)))^2)*(alpha^2)*(psi^2)) -> 0.00019632089 | H51: =-Beta/alpha -> 180 | I51: =(-EXP(alpha*zeta)*Beta*(-1+EXP(alpha*Size*psi)-Size*alpha*psi))/((alpha^3)*(psi^2)) -> 1690.9246 | J51: =Beta*Theta -> 14.4 | K51: =Beta*Theta -> 14.4 | L51: =kappa -> 90 | M51: =Gamma*Size -> 0 | N51: =Size*Beta*Phi -> 32.4 | O51: =-(EXP(alpha*a*psi)+EXP(alpha*b*psi)*(-1+Size*psi*alpha))*(Beta*Phi)/((alpha*psi)*(EXP(alpha*a*psi)-EXP(alpha*b*psi))) -> 12.294172 | P51: =(EXP(alpha*(zeta-a*psi))*Beta*Phi*(-EXP(alpha*a*psi)*(-2+(-1)*Size*alpha*psi)+EXP(alpha*b*psi)*(-2+Size*alpha*psi)))/((alpha^3)*(psi^3)) -> 78.836376 | Q51: =Tau*Beta -> 864 | R51: =Tau*Beta -> 864 | S51: =Tau -> 4.8 | T51: =Profit+Utility -> 1676.4518 | U51: =ij*BUTIJ+BUTII -> 1705.8747 | V51: =Revenue-Cost -> -29.422921 | W51: =(2*ij*BRIJ)+(2)*jj*BRJJ -> 143.85968 | X51: =2*(ij*BCCIJ)+(2*jj*BCCJJ)+BCS+jj*BCPTJJ+2*(ij*BCPTIJ)+BCPTII+BCk -> 173.2826

Sheet S-Toll(All-Toll)
A1: Tau | B1: OldTau | C1: Size | D1: a | E1: b | F1: ij | G1: jj | H1: BUTIJ | I1: BUTII | J1: BCCIJ | K1: BCCJJ | L1: BCk | M1: BCS | N1: BCPTJJ | O1: BCPTIJ | P1: BCPTII | Q1: BRIJ | R1: BRJJ | S1: Toll | T1: Welfare | U1: Utility | V1: Profit | W1: Revenue | X1: Cost
A2: 0 | B2: 0.6 | C2: 10 | D2: 0 | E2: =Size-a -> 10 | F2: =(EXP(alpha*(Tau+OldTau+zeta-2*a*psi))*((EXP(alpha*a*psi)-EXP(alpha*b*psi))^2))/((EXP(alpha*a*psi)-EXP(alpha*(2*OldTau+b*psi)))*(alpha^2)*(psi^2)) -> 4.6128479 | G2: =(EXP(alpha*(zeta+(2*b-a)*psi))*(-1+EXP(alpha*(-1)*Size*psi))*(EXP(alpha*(2*(Tau+OldTau)+a*psi))-EXP(alpha*(2*(Tau+OldTau)+b*psi))))/(((EXP(alpha*a*psi)-EXP(alpha*(2*OldTau+b*psi)))^2)*(alpha^2)*(psi^2)) -> 0.60557055 | H2: =-Beta/alpha -> 180 | I2: =(-EXP(alpha*zeta)*Beta*(-1+EXP(alpha*Size*psi)-Size*alpha*psi))/((alpha^3)*(psi^2)) -> 1690.9246 | J2: =Beta*Theta -> 14.4 | K2: =Beta*Theta -> 14.4 | L2: =kappa -> 90 | M2: =Gamma*Size -> 0 | N2: =Size*Beta*Phi -> 32.4 | O2: =-(EXP(alpha*a*psi)+EXP(alpha*b*psi)*(-1+Size*psi*alpha))*(Beta*Phi)/((alpha*psi)*(EXP(alpha*a*psi)-EXP(alpha*b*psi))) -> 12.294172 | P2: =(EXP(alpha*(zeta-a*psi))*Beta*Phi*(-EXP(alpha*a*psi)*(-2+(-1)*Size*alpha*psi)+EXP(alpha*b*psi)*(-2+Size*alpha*psi)))/((alpha^3)*(psi^3)) -> 78.836376 | Q2: =Tau*Beta -> 0 | R2: =Tau*Beta -> 0 | S2: =Tau -> 0 | T2: =Profit+Utility -> 2309.3581 | U2: =ij*BUTIJ+BUTII -> 2521.2372 | V2: =Revenue-Cost -> -211.87915 | W2: =(2*ij*BRIJ)+(2)*jj*BRJJ -> 0 | X2: =BCS+jj*BCPTJJ+2*(ij*BCPTIJ)+BCPTII -> 211.87915
A3: 0 | B3: 0.6 | C3: 10 | D3: 0 | E3: =Size-a -> 10 | F3: =(EXP(alpha*(Tau+OldTau+zeta-2*a*psi))*((EXP(alpha*a*psi)-EXP(alpha*b*psi))^2))/((EXP(alpha*a*psi)-EXP(alpha*(2*OldTau+b*psi)))*(alpha^2)*(psi^2)) -> 4.6128479 | G3: =(EXP(alpha*(zeta+(2*b-a)*psi))*(-1+EXP(alpha*(-1)*Size*psi))*(EXP(alpha*(2*(Tau+OldTau)+a*psi))-EXP(alpha*(2*(Tau+OldTau)+b*psi))))/(((EXP(alpha*a*psi)-EXP(alpha*(2*OldTau+b*psi)))^2)*(alpha^2)*(psi^2)) -> 0.60557055 | H3: =-Beta/alpha -> 180 | I3: =(-EXP(alpha*zeta)*Beta*(-1+EXP(alpha*Size*psi)-Size*alpha*psi))/((alpha^3)*(psi^2)) -> 1690.9246 | J3: =Beta*Theta -> 14.4 | K3: =Beta*Theta -> 14.4 | L3: =kappa -> 90 | M3: =Gamma*Size -> 0 | N3: =Size*Beta*Phi -> 32.4 | O3: =-(EXP(alpha*a*psi)+EXP(alpha*b*psi)*(-1+Size*psi*alpha))*(Beta*Phi)/((alpha*psi)*(EXP(alpha*a*psi)-EXP(alpha*b*psi))) -> 12.294172 | P3: =(EXP(alpha*(zeta-a*psi))*Beta*Phi*(-EXP(alpha*a*psi)*(-2+(-1)*Size*alpha*psi)+EXP(alpha*b*psi)*(-2+Size*alpha*psi)))/((alpha^3)*(psi^3)) -> 78.836376 | Q3: =Tau*Beta -> 0 | R3: =Tau*Beta -> 0 | S3: =Tau -> 0 | T3: =Profit+Utility -> 2069.0676 | U3: =ij*BUTIJ+BUTII -> 2521.2372 | V3: =Revenue-Cost -> -452.1696 | W3: =(2*ij*BRIJ)+(2)*jj*BRJJ -> 0 | X3: =2*(ij*BCCIJ)+(2*jj*BCCJJ)+BCS+jj*BCPTJJ+2*(ij*BCPTIJ)+BCPTII+BCk -> 452.1696
A4: =A2+0.1 -> 0.1 | B4: 0.6 | C4: 10 | D4: 0 | E4: =Size-a -> 10 | F4: =(EXP(alpha*(Tau+OldTau+zeta-2*a*psi))*((EXP(alpha*a*psi)-EXP(alpha*b*psi))^2))/((EXP(alpha*a*psi)-EXP(alpha*(2*OldTau+b*psi)))*(alpha^2)*(psi^2)) -> 4.1738774 | G4: =(EXP(alpha*(zeta+(2*b-a)*psi))*(-1+EXP(alpha*(-1)*Size*psi))*(EXP(alpha*(2*(Tau+OldTau)+a*psi))-EXP(alpha*(2*(Tau+OldTau)+b*psi))))/(((EXP(alpha*a*psi)-EXP(alpha*(2*OldTau+b*psi)))^2)*(alpha^2)*(psi^2)) -> 0.49579924 | H4: =-Beta/alpha -> 180 | I4: =(-EXP(alpha*zeta)*Beta*(-1+EXP(alpha*Size*psi)-Size*alpha*psi))/((alpha^3)*(psi^2)) -> 1690.9246 | J4: =Beta*Theta -> 14.4 | K4: =Beta*Theta -> 14.4 | L4: =kappa -> 90 | M4: =Gamma*Size -> 0 | N4: =Size*Beta*Phi -> 32.4 | O4: =-(EXP(alpha*a*psi)+EXP(alpha*b*psi)*(-1+Size*psi*alpha))*(Beta*Phi)/((alpha*psi)*(EXP(alpha*a*psi)-EXP(alpha*b*psi))) -> 12.294172 | P4: =(EXP(alpha*(zeta-a*psi))*Beta*Phi*(-EXP(alpha*a*psi)*(-2+(-1)*Size*alpha*psi)+EXP(alpha*b*psi)*(-2+Size*alpha*psi)))/((alpha^3)*(psi^3)) -> 78.836376 | Q4: =Tau*Beta -> 18 | R4: =Tau*Beta -> 18 | S4: =Tau -> 0.1 | T4: =Profit+Utility -> 2188.3152 | U4: =ij*BUTIJ+BUTII -> 2442.2226 | V4: =Revenue-Cost -> -253.90733 | W4: =(2*ij*BRIJ)+(2)*jj*BRJJ -> 168.10836 | X4: =2*(ij*BCCIJ)+(2*jj*BCCJJ)+BCS+jj*BCPTJJ+2*(ij*BCPTIJ)+BCPTII+BCk -> 422.01569
A5: =A4+0.1 -> 0.2 | B5: 0.6 | C5: 10 | D5: 0 | E5: =Size-a -> 10 | F5: =(EXP(alpha*(Tau+OldTau+zeta-2*a*psi))*((EXP(alpha*a*psi)-EXP(alpha*b*psi))^2))/((EXP(alpha*a*psi)-EXP(alpha*(2*OldTau+b*psi)))*(alpha^2)*(psi^2)) -> 3.7766804 | G5: =(EXP(alpha*(zeta+(2*b-a)*psi))*(-1+EXP(alpha*(-1)*Size*psi))*(EXP(alpha*(2*(Tau+OldTau)+a*psi))-EXP(alpha*(2*(Tau+OldTau)+b*psi))))/(((EXP(alpha*a*psi)-EXP(alpha*(2*OldTau+b*psi)))^2)*(alpha^2)*(psi^2)) -> 0.40592608 | H5: =-Beta/alpha -> 180 | I5: =(-EXP(alpha*zeta)*Beta*(-1+EXP(alpha*Size*psi)-Size*alpha*psi))/((alpha^3)*(psi^2)) -> 1690.9246 | J5: =Beta*Theta -> 14.4 | K5: =Beta*Theta -> 14.4 | L5: =kappa -> 90 | M5: =Gamma*Size -> 0 | N5: =Size*Beta*Phi -> 32.4 | O5: =-(EXP(alpha*a*psi)+EXP(alpha*b*psi)*(-1+Size*psi*alpha))*(Beta*Phi)/((alpha*psi)*(EXP(alpha*a*psi)-EXP(alpha*b*psi))) -> 12.294172 | P5: =(EXP(alpha*(zeta-a*psi))*Beta*Phi*(-EXP(alpha*a*psi)*(-2+(-1)*Size*alpha*psi)+EXP(alpha*b*psi)*(-2+Size*alpha*psi)))/((alpha^3)*(psi^3)) -> 78.836376 | Q5: =Tau*Beta -> 36 | R5: =Tau*Beta -> 36 | S5: =Tau -> 0.2 | T5: =Profit+Utility -> 2276.565 | U5: =ij*BUTIJ+BUTII -> 2370.7271 | V5: =Revenue-Cost -> -94.162097 | W5: =(2*ij*BRIJ)+(2)*jj*BRJJ -> 301.14767 | X5: =2*(ij*BCCIJ)+(2*jj*BCCJJ)+BCS+jj*BCPTJJ+2*(ij*BCPTIJ)+BCPTII+BCk -> 395.30976
A6: =A5+0.1 -> 0.3 | B6: 0.6 | C6: 10 | D6: 0 | E6: =Size-a -> 10 | F6: =(EXP(alpha*(Tau+OldTau+zeta-2*a*psi))*((EXP(alpha*a*psi)-EXP(alpha*b*psi))^2))/((EXP(alpha*a*psi)-EXP(alpha*(2*OldTau+b*psi)))*(alpha^2)*(psi^2)) -> 3.4172818 | G6: =(EXP(alpha*(zeta+(2*b-a)*psi))*(-1+EXP(alpha*(-1)*Size*psi))*(EXP(alpha*(2*(Tau+OldTau)+a*psi))-EXP(alpha*(2*(Tau+OldTau)+b*psi))))/(((EXP(alpha*a*psi)-EXP(alpha*(2*OldTau+b*psi)))^2)*(alpha^2)*(psi^2)) -> 0.33234417 | H6: =-Beta/alpha -> 180 | I6: =(-EXP(alpha*zeta)*Beta*(-1+EXP(alpha*Size*psi)-Size*alpha*psi))/((alpha^3)*(psi^2)) -> 1690.9246 | J6: =Beta*Theta -> 14.4 | K6: =Beta*Theta -> 14.4 | L6: =kappa -> 90 | M6: =Gamma*Size -> 0 | N6: =Size*Beta*Phi -> 32.4 | O6: =-(EXP(alpha*a*psi)+EXP(alpha*b*psi)*(-1+Size*psi*alpha))*(Beta*Phi)/((alpha*psi)*(EXP(alpha*a*psi)-EXP(alpha*b*psi))) -> 12.294172 | P6: =(EXP(alpha*(zeta-a*psi))*Beta*Phi*(-EXP(alpha*a*psi)*(-2+(-1)*Size*alpha*psi)+EXP(alpha*b*psi)*(-2+Size*alpha*psi)))/((alpha^3)*(psi^3)) -> 78.836376 | Q6: =Tau*Beta -> 54 | R6: =Tau*Beta -> 54 | S6: =Tau -> 0.3 | T6: =Profit+Utility -> 2339.3761 | U6: =ij*BUTIJ+BUTII -> 2306.0353 | V6: =Revenue-Cost -> 33.340747 | W6: =(2*ij*BRIJ)+(2)*jj*BRJJ -> 404.9596 | X6: =2*(ij*BCCIJ)+(2*jj*BCCJJ)+BCS+jj*BCPTJJ+2*(ij*BCPTIJ)+BCPTII+BCk -> 371.61885
A7: =A6+0.1 -> 0.4 | B7: 0.6 | C7: 10 | D7: 0 | E7: =Size-a -> 10 | F7: =(EXP(alpha*(Tau+OldTau+zeta-2*a*psi))*((EXP(alpha*a*psi)-EXP(alpha*b*psi))^2))/((EXP(alpha*a*psi)-EXP(alpha*(2*OldTau+b*psi)))*(alpha^2)*(psi^2)) -> 3.0920844 | G7: =(EXP(alpha*(zeta+(2*b-a)*psi))*(-1+EXP(alpha*(-1)*Size*psi))*(EXP(alpha*(2*(Tau+OldTau)+a*psi))-EXP(alpha*(2*(Tau+OldTau)+b*psi))))/(((EXP(alpha*a*psi)-EXP(alpha*(2*OldTau+b*psi)))^2)*(alpha^2)*(psi^2)) -> 0.27210039 | H7: =-Beta/alpha -> 180 | I7: =(-EXP(alpha*zeta)*Beta*(-1+EXP(alpha*Size*psi)-Size*alpha*psi))/((alpha^3)*(psi^2)) -> 1690.9246 | J7: =Beta*Theta -> 14.4 | K7: =Beta*Theta -> 14.4 | L7: =kappa -> 90 | M7: =Gamma*Size -> 0 | N7: =Size*Beta*Phi -> 32.4 | O7: =-(EXP(alpha*a*psi)+EXP(alpha*b*psi)*(-1+Size*psi*alpha))*(Beta*Phi)/((alpha*psi)*(EXP(alpha*a*psi)-EXP(alpha*b*psi))) -> 12.294172 | P7: =(EXP(alpha*(zeta-a*psi))*Beta*Phi*(-EXP(alpha*a*psi)*(-2+(-1)*Size*alpha*psi)+EXP(alpha*b*psi)*(-2+Size*alpha*psi)))/((alpha^3)*(psi^3)) -> 78.836376 | Q7: =Tau*Beta -> 72 | R7: =Tau*Beta -> 72 | S7: =Tau -> 0.4 | T7: =Profit+Utility -> 2381.3722 | U7: =ij*BUTIJ+BUTII -> 2247.4998 | V7: =Revenue-Cost -> 133.87242 | W7: =(2*ij*BRIJ)+(2)*jj*BRJJ -> 484.44261 | X7: =2*(ij*BCCIJ)+(2*jj*BCCJJ)+BCS+jj*BCPTJJ+2*(ij*BCPTIJ)+BCPTII+BCk -> 350.57018
A8: =A7+0.1 -> 0.5 | B8: 0.6 | C8: 10 | D8: 0 | E8: =Size-a -> 10 | F8: =(EXP(alpha*(Tau+OldTau+zeta-2*a*psi))*((EXP(alpha*a*psi)-EXP(alpha*b*psi))^2))/((EXP(alpha*a*psi)-EXP(alpha*(2*OldTau+b*psi)))*(alpha^2)*(psi^2)) -> 2.7978337 | G8: =(EXP(alpha*(zeta+(2*b-a)*psi))*(-1+EXP(alpha*(-1)*Size*psi))*(EXP(alpha*(2*(Tau+OldTau)+a*psi))-EXP(alpha*(2*(Tau+OldTau)+b*psi))))/(((EXP(alpha*a*psi)-EXP(alpha*(2*OldTau+b*psi)))^2)*(alpha^2)*(psi^2)) -> 0.22277696 | H8: =-Beta/alpha -> 180 | I8: =(-EXP(alpha*zeta)*Beta*(-1+EXP(alpha*Size*psi)-Size*alpha*psi))/((alpha^3)*(psi^2)) -> 1690.9246 | J8: =Beta*Theta -> 14.4 | K8: =Beta*Theta -> 14.4 | L8: =kappa -> 90 | M8: =Gamma*Size -> 0 | N8: =Size*Beta*Phi -> 32.4 | O8: =-(EXP(alpha*a*psi)+EXP(alpha*b*psi)*(-1+Size*psi*alpha))*(Beta*Phi)/((alpha*psi)*(EXP(alpha*a*psi)-EXP(alpha*b*psi))) -> 12.294172 | P8: =(EXP(alpha*(zeta-a*psi))*Beta*Phi*(-EXP(alpha*a*psi)*(-2+(-1)*Size*alpha*psi)+EXP(alpha*b*psi)*(-2+Size*alpha*psi)))/((alpha^3)*(psi^3)) -> 78.836376 | Q8: =Tau*Beta -> 90 | R8: =Tau*Beta -> 90 | S8: =Tau -> 0.5 | T8: =Profit+Utility -> 2406.4026 | U8: =ij*BUTIJ+BUTII -> 2194.5347 | V8: =Revenue-Cost -> 211.86788 | W8: =(2*ij*BRIJ)+(2)*jj*BRJJ -> 543.70991 | X8: =2*(ij*BCCIJ)+(2*jj*BCCJJ)+BCS+jj*BCPTJJ+2*(ij*BCPTIJ)+BCPTII+BCk -> 331.84203
A9: =A8+0.1 -> 0.6 | B9: 0.6 | C9: 10 | D9: 0 | E9: =Size-a -> 10 | F9: =(EXP(alpha*(Tau+OldTau+zeta-2*a*psi))*((EXP(alpha*a*psi)-EXP(alpha*b*psi))^2))/((EXP(alpha*a*psi)-EXP(alpha*(2*OldTau+b*psi)))*(alpha^2)*(psi^2)) -> 2.5315846 | G9: =(EXP(alpha*(zeta+(2*b-a)*psi))*(-1+EXP(alpha*(-1)*Size*psi))*(EXP(alpha*(2*(Tau+OldTau)+a*psi))-EXP(alpha*(2*(Tau+OldTau)+b*psi))))/(((EXP(alpha*a*psi)-EXP(alpha*(2*OldTau+b*psi)))^2)*(alpha^2)*(psi^2)) -> 0.18239435 | H9: =-Beta/alpha -> 180 | I9: =(-EXP(alpha*zeta)*Beta*(-1+EXP(alpha*Size*psi)-Size*alpha*psi))/((alpha^3)*(psi^2)) -> 1690.9246 | J9: =Beta*Theta -> 14.4 | K9: =Beta*Theta -> 14.4 | L9: =kappa -> 90 | M9: =Gamma*Size -> 0 | N9: =Size*Beta*Phi -> 32.4 | O9: =-(EXP(alpha*a*psi)+EXP(alpha*b*psi)*(-1+Size*psi*alpha))*(Beta*Phi)/((alpha*psi)*(EXP(alpha*a*psi)-EXP(alpha*b*psi))) -> 12.294172 | P9: =(EXP(alpha*(zeta-a*psi))*Beta*Phi*(-EXP(alpha*a*psi)*(-2+(-1)*Size*alpha*psi)+EXP(alpha*b*psi)*(-2+Size*alpha*psi)))/((alpha^3)*(psi^3)) -> 78.836376 | Q9: =Tau*Beta -> 108 | R9: =Tau*Beta -> 108 | S9: =Tau -> 0.6 | T9: =Profit+Utility -> 2417.6733 | U9: =ij*BUTIJ+BUTII -> 2146.6099 | V9: =Revenue-Cost -> 271.06343 | W9: =(2*ij*BRIJ)+(2)*jj*BRJJ -> 586.21945 | X9: =2*(ij*BCCIJ)+(2*jj*BCCJJ)+BCS+jj*BCPTJJ+2*(ij*BCPTIJ)+BCPTII+BCk -> 315.15602
A10: =A9+0.1 -> 0.7 | B10: 0.6 | C10: 10 | D10: 0 | E10: =Size-a -> 10 | F10: =(EXP(alpha*(Tau+OldTau+zeta-2*a*psi))*((EXP(alpha*a*psi)-EXP(alpha*b*psi))^2))/((EXP(alpha*a*psi)-EXP(alpha*(2*OldTau+b*psi)))*(alpha^2)*(psi^2)) -> 2.2906725 | G10: =(EXP(alpha*(zeta+(2*b-a)*psi))*(-1+EXP(alpha*(-1)*Size*psi))*(EXP(alpha*(2*(Tau+OldTau)+a*psi))-EXP(alpha*(2*(Tau+OldTau)+b*psi))))/(((EXP(alpha*a*psi)-EXP(alpha*(2*OldTau+b*psi)))^2)*(alpha^2)*(psi^2)) -> 0.14933186 | H10: =-Beta/alpha -> 180 | I10: =(-EXP(alpha*zeta)*Beta*(-1+EXP(alpha*Size*psi)-Size*alpha*psi))/((alpha^3)*(psi^2)) -> 1690.9246 | J10: =Beta*Theta -> 14.4 | K10: =Beta*Theta -> 14.4 | L10: =kappa -> 90 | M10: =Gamma*Size -> 0 | N10: =Size*Beta*Phi -> 32.4 | O10: =-(EXP(alpha*a*psi)+EXP(alpha*b*psi)*(-1+Size*psi*alpha))*(Beta*Phi)/((alpha*psi)*(EXP(alpha*a*psi)-EXP(alpha*b*psi))) -> 12.294172 | P10: =(EXP(alpha*(zeta-a*psi))*Beta*Phi*(-EXP(alpha*a*psi)*(-2+(-1)*Size*alpha*psi)+EXP(alpha*b*psi)*(-2+Size*alpha*psi)))/((alpha^3)*(psi^3)) -> 78.836376 | Q10: =Tau*Beta -> 126 | R10: =Tau*Beta -> 126 | S10: =Tau -> 0.7 | T10: =Profit+Utility -> 2417.8561 | U10: =ij*BUTIJ+BUTII -> 2103.2457 | V10: =Revenue-Cost -> 314.61039 | W10: =(2*ij*BRIJ)+(2)*jj*BRJJ -> 614.88109 | X10: =2*(ij*BCCIJ)+(2*jj*BCCJJ)+BCS+jj*BCPTJJ+2*(ij*BCPTIJ)+BCPTII+BCk -> 300.27069
A11: =A10+0.1 -> 0.8 | B11: 0.6 | C11: 10 | D11: 0 | E11: =Size-a -> 10 | F11: =(EXP(alpha*(Tau+OldTau+zeta-2*a*psi))*((EXP(alpha*a*psi)-EXP(alpha*b*psi))^2))/((EXP(alpha*a*psi)-EXP(alpha*(2*OldTau+b*psi)))*(alpha^2)*(psi^2)) -> 2.0726862 | G11: =(EXP(alpha*(zeta+(2*b-a)*psi))*(-1+EXP(alpha*(-1)*Size*psi))*(EXP(alpha*(2*(Tau+OldTau)+a*psi))-EXP(alpha*(2*(Tau+OldTau)+b*psi))))/(((EXP(alpha*a*psi)-EXP(alpha*(2*OldTau+b*psi)))^2)*(alpha^2)*(psi^2)) -> 0.12226259 | H11: =-Beta/alpha -> 180 | I11: =(-EXP(alpha*zeta)*Beta*(-1+EXP(alpha*Size*psi)-Size*alpha*psi))/((alpha^3)*(psi^2)) -> 1690.9246 | J11: =Beta*Theta -> 14.4 | K11: =Beta*Theta -> 14.4 | L11: =kappa -> 90 | M11: =Gamma*Size -> 0 | N11: =Size*Beta*Phi -> 32.4 | O11: =-(EXP(alpha*a*psi)+EXP(alpha*b*psi)*(-1+Size*psi*alpha))*(Beta*Phi)/((alpha*psi)*(EXP(alpha*a*psi)-EXP(alpha*b*psi))) -> 12.294172 | P11: =(EXP(alpha*(zeta-a*psi))*Beta*Phi*(-EXP(alpha*a*psi)*(-2+(-1)*Size*alpha*psi)+EXP(alpha*b*psi)*(-2+Size*alpha*psi)))/((alpha^3)*(psi^3)) -> 78.836376 | Q11: =Tau*Beta -> 144 | R11: =Tau*Beta -> 144 | S11: =Tau -> 0.8 | T11: =Profit+Utility -> 2409.1772 | U11: =ij*BUTIJ+BUTII -> 2064.0081 | V11: =Revenue-Cost -> 345.16911 | W11: =(2*ij*BRIJ)+(2)*jj*BRJJ -> 632.14524 | X11: =2*(ij*BCCIJ)+(2*jj*BCCJJ)+BCS+jj*BCPTJJ+2*(ij*BCPTIJ)+BCPTII+BCk -> 286.97613
A12: =A11+0.1 -> 0.9 | B12: 0.6 | C12: 10 | D12: 0 | E12: =Size-a -> 10 | F12: =(EXP(alpha*(Tau+OldTau+zeta-2*a*psi))*((EXP(alpha*a*psi)-EXP(alpha*b*psi))^2))/((EXP(alpha*a*psi)-EXP(alpha*(2*OldTau+b*psi)))*(alpha^2)*(psi^2)) -> 1.875444 | G12: =(EXP(alpha*(zeta+(2*b-a)*psi))*(-1+EXP(alpha*(-1)*Size*psi))*(EXP(alpha*(2*(Tau+OldTau)+a*psi))-EXP(alpha*(2*(Tau+OldTau)+b*psi))))/(((EXP(alpha*a*psi)-EXP(alpha*(2*OldTau+b*psi)))^2)*(alpha^2)*(psi^2)) -> 0.10010014 | H12: =-Beta/alpha -> 180 | I12: =(-EXP(alpha*zeta)*Beta*(-1+EXP(alpha*Size*psi)-Size*alpha*psi))/((alpha^3)*(psi^2)) -> 1690.9246 | J12: =Beta*Theta -> 14.4 | K12: =Beta*Theta -> 14.4 | L12: =kappa -> 90 | M12: =Gamma*Size -> 0 | N12: =Size*Beta*Phi -> 32.4 | O12: =-(EXP(alpha*a*psi)+EXP(alpha*b*psi)*(-1+Size*psi*alpha))*(Beta*Phi)/((alpha*psi)*(EXP(alpha*a*psi)-EXP(alpha*b*psi))) -> 12.294172 | P12: =(EXP(alpha*(zeta-a*psi))*Beta*Phi*(-EXP(alpha*a*psi)*(-2+(-1)*Size*alpha*psi)+EXP(alpha*b*psi)*(-2+Size*alpha*psi)))/((alpha^3)*(psi^3)) -> 78.836376 | Q12: =Tau*Beta -> 162 | R12: =Tau*Beta -> 162 | S12: =Tau -> 0.9 | T12: =Profit+Utility -> 2393.4915 | U12: =ij*BUTIJ+BUTII -> 2028.5045 | V12: =Revenue-Cost -> 364.98694 | W12: =(2*ij*BRIJ)+(2)*jj*BRJJ -> 640.0763 | X12: =2*(ij*BCCIJ)+(2*jj*BCCJJ)+BCS+jj*BCPTJJ+2*(ij*BCPTIJ)+BCPTII+BCk -> 275.08935
A13: =A12+0.1 -> 1 | B13: 0.6 | C13: 10 | D13: 0 | E13: =Size-a -> 10 | F13: =(EXP(alpha*(Tau+OldTau+zeta-2*a*psi))*((EXP(alpha*a*psi)-EXP(alpha*b*psi))^2))/((EXP(alpha*a*psi)-EXP(alpha*(2*OldTau+b*psi)))*(alpha^2)*(psi^2)) -> 1.6969719 | G13: =(EXP(alpha*(zeta+(2*b-a)*psi))*(-1+EXP(alpha*(-1)*Size*psi))*(EXP(alpha*(2*(Tau+OldTau)+a*psi))-EXP(alpha*(2*(Tau+OldTau)+b*psi))))/(((EXP(alpha*a*psi)-EXP(alpha*(2*OldTau+b*psi)))^2)*(alpha^2)*(psi^2)) -> 0.081955062 | H13: =-Beta/alpha -> 180 | I13: =(-EXP(alpha*zeta)*Beta*(-1+EXP(alpha*Size*psi)-Size*alpha*psi))/((alpha^3)*(psi^2)) -> 1690.9246 | J13: =Beta*Theta -> 14.4 | K13: =Beta*Theta -> 14.4 | L13: =kappa -> 90 | M13: =Gamma*Size -> 0 | N13: =Size*Beta*Phi -> 32.4 | O13: =-(EXP(alpha*a*psi)+EXP(alpha*b*psi)*(-1+Size*psi*alpha))*(Beta*Phi)/((alpha*psi)*(EXP(alpha*a*psi)-EXP(alpha*b*psi))) -> 12.294172 | P13: =(EXP(alpha*(zeta-a*psi))*Beta*Phi*(-EXP(alpha*a*psi)*(-2+(-1)*Size*alpha*psi)+EXP(alpha*b*psi)*(-2+Size*alpha*psi)))/((alpha^3)*(psi^3)) -> 78.836376 | Q13: =Tau*Beta -> 180 | R13: =Tau*Beta -> 180 | S13: =Tau -> 1 | T13: =Profit+Utility -> 2372.3427 | U13: =ij*BUTIJ+BUTII -> 1996.3796 | V13: =Revenue-Cost -> 375.96316 | W13: =(2*ij*BRIJ)+(2)*jj*BRJJ -> 640.41371 | X13: =2*(ij*BCCIJ)+(2*jj*BCCJJ)+BCS+jj*BCPTJJ+2*(ij*BCPTIJ)+BCPTII+BCk -> 264.45054
A14: =A13+0.1 -> 1.1 | B14: 0.6 | C14: 10 | D14: 0 | E14: =Size-a -> 10 | F14: =(EXP(alpha*(Tau+OldTau+zeta-2*a*psi))*((EXP(alpha*a*psi)-EXP(alpha*b*psi))^2))/((EXP(alpha*a*psi)-EXP(alpha*(2*OldTau+b*psi)))*(alpha^2)*(psi^2)) -> 1.5354837 | G14: =(EXP(alpha*(zeta+(2*b-a)*psi))*(-1+EXP(alpha*(-1)*Size*psi))*(EXP(alpha*(2*(Tau+OldTau)+a*psi))-EXP(alpha*(2*(Tau+OldTau)+b*psi))))/(((EXP(alpha*a*psi)-EXP(alpha*(2*OldTau+b*psi)))^2)*(alpha^2)*(psi^2)) -> 0.06709913 | H14: =-Beta/alpha -> 180 | I14: =(-EXP(alpha*zeta)*Beta*(-1+EXP(alpha*Size*psi)-Size*alpha*psi))/((alpha^3)*(psi^2)) -> 1690.9246 | J14: =Beta*Theta -> 14.4 | K14: =Beta*Theta -> 14.4 | L14: =kappa -> 90 | M14: =Gamma*Size -> 0 | N14: =Size*Beta*Phi -> 32.4 | O14: =-(EXP(alpha*a*psi)+EXP(alpha*b*psi)*(-1+Size*psi*alpha))*(Beta*Phi)/((alpha*psi)*(EXP(alpha*a*psi)-EXP(alpha*b*psi))) -> 12.294172 | P14: =(EXP(alpha*(zeta-a*psi))*Beta*Phi*(-EXP(alpha*a*psi)*(-2+(-1)*Size*alpha*psi)+EXP(alpha*b*psi)*(-2+Size*alpha*psi)))/((alpha^3)*(psi^3)) -> 78.836376 | Q14: =Tau*Beta -> 198 | R14: =Tau*Beta -> 198 | S14: =Tau -> 1.1 | T14: =Profit+Utility -> 2347.0147 | U14: =ij*BUTIJ+BUTII -> 1967.3117 | V14: =Revenue-Cost -> 379.70302 | W14: =(2*ij*BRIJ)+(2)*jj*BRJJ -> 634.62279 | X14: =2*(ij*BCCIJ)+(2*jj*BCCJJ)+BCS+jj*BCPTJJ+2*(ij*BCPTIJ)+BCPTII+BCk -> 254.91977
A15: =A14+0.1 -> 1.2 | B15: 0.6 | C15: 10 | D15: 0 | E15: =Size-a -> 10 | F15: =(EXP(alpha*(Tau+OldTau+zeta-2*a*psi))*((EXP(alpha*a*psi)-EXP(alpha*b*psi))^2))/((EXP(alpha*a*psi)-EXP(alpha*(2*OldTau+b*psi)))*(alpha^2)*(psi^2)) -> 1.3893631 | G15: =(EXP(alpha*(zeta+(2*b-a)*psi))*(-1+EXP(alpha*(-1)*Size*psi))*(EXP(alpha*(2*(Tau+OldTau)+a*psi))-EXP(alpha*(2*(Tau+OldTau)+b*psi))))/(((EXP(alpha*a*psi)-EXP(alpha*(2*OldTau+b*psi)))^2)*(alpha^2)*(psi^2)) -> 0.054936121 | H15: =-Beta/alpha -> 180 | I15: =(-EXP(alpha*zeta)*Beta*(-1+EXP(alpha*Size*psi)-Size*alpha*psi))/((alpha^3)*(psi^2)) -> 1690.9246 | J15: =Beta*Theta -> 14.4 | K15: =Beta*Theta -> 14.4 | L15: =kappa -> 90 | M15: =Gamma*Size -> 0 | N15: =Size*Beta*Phi -> 32.4 | O15: =-(EXP(alpha*a*psi)+EXP(alpha*b*psi)*(-1+Size*psi*alpha))*(Beta*Phi)/((alpha*psi)*(EXP(alpha*a*psi)-EXP(alpha*b*psi))) -> 12.294172 | P15: =(EXP(alpha*(zeta-a*psi))*Beta*Phi*(-EXP(alpha*a*psi)*(-2+(-1)*Size*alpha*psi)+EXP(alpha*b*psi)*(-2+Size*alpha*psi)))/((alpha^3)*(psi^3)) -> 78.836376 | Q15: =Tau*Beta -> 216 | R15: =Tau*Beta -> 216 | S15: =Tau -> 1.2 | T15: =Profit+Utility -> 2318.573 | U15: =ij*BUTIJ+BUTII -> 1941.01 | V15: =Revenue-Cost -> 377.56299 | W15: =(2*ij*BRIJ)+(2)*jj*BRJJ -> 623.93725 | X15: =2*(ij*BCCIJ)+(2*jj*BCCJJ)+BCS+jj*BCPTJJ+2*(ij*BCPTIJ)+BCPTII+BCk -> 246.37426
A16: =A15+0.1 -> 1.3 | B16: 0.6 | C16: 10 | D16: 0 | E16: =Size-a -> 10 | F16: =(EXP(alpha*(Tau+OldTau+zeta-2*a*psi))*((EXP(alpha*a*psi)-EXP(alpha*b*psi))^2))/((EXP(alpha*a*psi)-EXP(alpha*(2*OldTau+b*psi)))*(alpha^2)*(psi^2)) -> 1.2571477 | G16: =(EXP(alpha*(zeta+(2*b-a)*psi))*(-1+EXP(alpha*(-1)*Size*psi))*(EXP(alpha*(2*(Tau+OldTau)+a*psi))-EXP(alpha*(2*(Tau+OldTau)+b*psi))))/(((EXP(alpha*a*psi)-EXP(alpha*(2*OldTau+b*psi)))^2)*(alpha^2)*(psi^2)) -> 0.044977892 | H16: =-Beta/alpha -> 180 | I16: =(-EXP(alpha*zeta)*Beta*(-1+EXP(alpha*Size*psi)-Size*alpha*psi))/((alpha^3)*(psi^2)) -> 1690.9246 | J16: =Beta*Theta -> 14.4 | K16: =Beta*Theta -> 14.4 | L16: =kappa -> 90 | M16: =Gamma*Size -> 0 | N16: =Size*Beta*Phi -> 32.4 | O16: =-(EXP(alpha*a*psi)+EXP(alpha*b*psi)*(-1+Size*psi*alpha))*(Beta*Phi)/((alpha*psi)*(EXP(alpha*a*psi)-EXP(alpha*b*psi))) -> 12.294172 | P16: =(EXP(alpha*(zeta-a*psi))*Beta*Phi*(-EXP(alpha*a*psi)*(-2+(-1)*Size*alpha*psi)+EXP(alpha*b*psi)*(-2+Size*alpha*psi)))/((alpha^3)*(psi^3)) -> 78.836376 | Q16: =Tau*Beta -> 234 | R16: =Tau*Beta -> 234 | S16: =Tau -> 1.3 | T16: =Profit+Utility -> 2287.8999 | U16: =ij*BUTIJ+BUTII -> 1917.2112 | V16: =Revenue-Cost -> 370.68872 | W16: =(2*ij*BRIJ)+(2)*jj*BRJJ -> 609.39478 | X16: =2*(ij*BCCIJ)+(2*jj*BCCJJ)+BCS+jj*BCPTJJ+2*(ij*BCPTIJ)+BCPTII+BCk -> 238.70606
... A51: =A50+0.1 -> 4.8 | B51: 0.6 | C51: 10 | D51: 0 | E51: =Size-a -> 10 | F51: =(EXP(alpha*(Tau+OldTau+zeta-2*a*psi))*((EXP(alpha*a*psi)-EXP(alpha*b*psi))^2))/((EXP(alpha*a*psi)-EXP(alpha*(2*OldTau+b*psi)))*(alpha^2)*(psi^2)) -> 0.037962571 | G51: =(EXP(alpha*(zeta+(2*b-a)*psi))*(-1+EXP(alpha*(-1)*Size*psi))*(EXP(alpha*(2*(Tau+OldTau)+a*psi))-EXP(alpha*(2*(Tau+OldTau)+b*psi))))/(((EXP(alpha*a*psi)-EXP(alpha*(2*OldTau+b*psi)))^2)*(alpha^2)*(psi^2)) -> 4.1014528e-05 | H51: =-Beta/alpha -> 180 | I51: =(-EXP(alpha*zeta)*Beta*(-1+EXP(alpha*Size*psi)-Size*alpha*psi))/((alpha^3)*(psi^2)) -> 1690.9246 | J51: =Beta*Theta -> 14.4 | K51: =Beta*Theta -> 14.4 | L51: =kappa -> 90 | M51: =Gamma*Size -> 0 | N51: =Size*Beta*Phi -> 32.4 | O51: =-(EXP(alpha*a*psi)+EXP(alpha*b*psi)*(-1+Size*psi*alpha))*(Beta*Phi)/((alpha*psi)*(EXP(alpha*a*psi)-EXP(alpha*b*psi))) -> 12.294172 | P51: =(EXP(alpha*(zeta-a*psi))*Beta*Phi*(-EXP(alpha*a*psi)*(-2+(-1)*Size*alpha*psi)+EXP(alpha*b*psi)*(-2+Size*alpha*psi)))/((alpha^3)*(psi^3)) -> 78.836376 | Q51: =Tau*Beta -> 864 | R51: =Tau*Beta -> 864 | S51: =Tau -> 4.8 | T51: =Profit+Utility -> 1592.5624 | U51: =ij*BUTIJ+BUTII -> 1697.7579 | V51: =Revenue-Cost -> -105.19545 | W51: =(2*ij*BRIJ)+(2)*jj*BRJJ -> 65.670196 | X51: =2*(ij*BCCIJ)+(2*jj*BCCJJ)+BCS+jj*BCPTJJ+2*(ij*BCPTIJ)+BCPTII+BCk -> 170.86564

Sheet S-Wcompare
B1: All-Tax Environment | E1: All-Toll Environment
A2: Toll | B2: Welfare-Tax Environment | C2: Consumers' Surplus-Tax Environment | D2: Profit-Tax Environment | E2: Welfare-Toll Enviornment | F2: Consumers' Surplus-Toll Environment | G2: Profit-Toll Environment
A3: 0 | B3: ='S-Toll (All-Tax)'!T2 -> 3086.6096 | C3: ='S-Toll (All-Tax)'!U2 -> 3507.5109 | D3: ='S-Toll (All-Tax)'!V2 -> -420.90131 | E3: ='S-Toll(All-Toll)'!T2 -> 2309.3581 | F3: ='S-Toll(All-Toll)'!U2 -> 2521.2372 | G3: ='S-Toll(All-Toll)'!V2 -> -211.87915
A4: 0 | B4: ='S-Toll (All-Tax)'!T3 -> 2622.4751 | C4: ='S-Toll (All-Tax)'!U3 -> 3507.5109 | D4: ='S-Toll (All-Tax)'!V3 -> -885.03581 | E4: ='S-Toll(All-Toll)'!T3 -> 2069.0676 | F4: ='S-Toll(All-Toll)'!U3 -> 2521.2372 | G4: ='S-Toll(All-Toll)'!V3 -> -452.1696
A5: 0.1 | B5: ='S-Toll (All-Tax)'!T4 -> 2947.2128 | C5: ='S-Toll (All-Tax)'!U4 -> 3334.6399 | D5: ='S-Toll (All-Tax)'!V4 -> -387.42709 | E5: ='S-Toll(All-Toll)'!T4 -> 2188.3152 | F5: ='S-Toll(All-Toll)'!U4 -> 2442.2226 | G5: ='S-Toll(All-Toll)'!V4 -> -253.90733
A6: 0.2 | B6: ='S-Toll (All-Tax)'!T5 -> 3184.1513 | C6: ='S-Toll (All-Tax)'!U5 -> 3178.2197 | D6: ='S-Toll (All-Tax)'!V5 -> 5.9316365 | E6: ='S-Toll(All-Toll)'!T5 -> 2276.565 | F6: ='S-Toll(All-Toll)'!U5 -> 2370.7271 | G6: ='S-Toll(All-Toll)'!V5 -> -94.162097
A7: 0.3 | B7: ='S-Toll (All-Tax)'!T6 -> 3350.5992 | C7: ='S-Toll (All-Tax)'!U6 -> 3036.6849 | D7: ='S-Toll (All-Tax)'!V6 -> 313.91437 | E7: ='S-Toll(All-Toll)'!T6 -> 2339.3761 | F7: ='S-Toll(All-Toll)'!U6 -> 2306.0353 | G7: ='S-Toll(All-Toll)'!V6 -> 33.340747
A8: 0.4 | B8: ='S-Toll (All-Tax)'!T7 -> 3460.6095 | C8: ='S-Toll (All-Tax)'!U7 -> 2908.6188 | D8: ='S-Toll (All-Tax)'!V7 -> 551.99066 | E8: ='S-Toll(All-Toll)'!T7 -> 2381.3722 | F8: ='S-Toll(All-Toll)'!U7 -> 2247.4998 | G8: ='S-Toll(All-Toll)'!V7 -> 133.87242
A9: 0.5 | B9: ='S-Toll (All-Tax)'!T8 -> 3525.6005 | C9: ='S-Toll (All-Tax)'!U8 -> 2792.7399 | D9: ='S-Toll (All-Tax)'!V8 -> 732.86057 | E9: ='S-Toll(All-Toll)'!T8 -> 2406.4026 | F9: ='S-Toll(All-Toll)'!U8 -> 2194.5347 | G9: ='S-Toll(All-Toll)'!V8 -> 211.86788
A10: 0.6 | B10: ='S-Toll (All-Tax)'!T9 -> 3554.8555 | C10: ='S-Toll (All-Tax)'!U9 -> 2687.8883 | D10: ='S-Toll (All-Tax)'!V9 -> 866.9672 | E10: ='S-Toll(All-Toll)'!T9 -> 2417.6733 | F10: ='S-Toll(All-Toll)'!U9 -> 2146.6099 | G10: ='S-Toll(All-Toll)'!V9 -> 271.06343
A11: 0.7 | B11: ='S-Toll (All-Tax)'!T10 -> 3555.9256 | C11: ='S-Toll (All-Tax)'!U10 -> 2593.0147 | D11: ='S-Toll (All-Tax)'!V10 -> 962.91089 | E11: ='S-Toll(All-Toll)'!T10 -> 2417.8561 | F11: ='S-Toll(All-Toll)'!U10 -> 2103.2457 | G11: ='S-Toll(All-Toll)'!V10 -> 314.61039
A12: 0.8 | B12: ='S-Toll (All-Tax)'!T11 -> 3534.9539 | C12: ='S-Toll (All-Tax)'!U11 -> 2507.1695 | D12: ='S-Toll (All-Tax)'!V11 -> 1027.7845 | E12: ='S-Toll(All-Toll)'!T11 -> 2409.1772 | F12: ='S-Toll(All-Toll)'!U11 -> 2064.0081 | G12: ='S-Toll(All-Toll)'!V11 -> 345.16911
A13: 0.9 | B13: ='S-Toll (All-Tax)'!T12 -> 3496.9385 | C13: ='S-Toll (All-Tax)'!U12 -> 2429.4935 | D13: ='S-Toll (All-Tax)'!V12 -> 1067.445 | E13: ='S-Toll(All-Toll)'!T12 -> 2393.4915 | F13: ='S-Toll(All-Toll)'!U12 -> 2028.5045 | G13: ='S-Toll(All-Toll)'!V12 -> 364.98694
A14: 1 | B14: ='S-Toll (All-Tax)'!T13 -> 3445.9435 | C14: ='S-Toll (All-Tax)'!U13 -> 2359.2094 | D14: ='S-Toll (All-Tax)'!V13 -> 1086.7341 | E14: ='S-Toll(All-Toll)'!T13 -> 2372.3427 | F14: ='S-Toll(All-Toll)'!U13 -> 1996.3796 | G14: ='S-Toll(All-Toll)'!V13 -> 375.96316
... A52: 4.8 | B52: ='S-Toll (All-Tax)'!T51 -> 1676.4518 | C52: ='S-Toll (All-Tax)'!U51 -> 1705.8747 | D52: ='S-Toll (All-Tax)'!V51 -> -29.422921 | E52: ='S-Toll(All-Toll)'!T51 -> 1592.5624 | F52: ='S-Toll(All-Toll)'!U51 -> 1697.7579 | G52: ='S-Toll(All-Toll)'!V51 -> -105.19545

Sheet W-React-JS=10
A1: Tau | B1: OldTau | C1: Size | D1: a | E1: b | F1: ij | G1: jj | H1: BUTIJ | I1: BUTII | J1: BCCIJ | K1: BCCJJ | L1: BCk | M1: BCS | N1: BCPTJJ | O1: BCPTIJ | P1: BCPTII | Q1: BRIJ | R1: BRJJ | S1: Toll | T1: Welfare | U1: Revenue | V1: Cost | W1: Utility | X1: Profit
A2: 0.65329456 | B2: 0 | C2: 10 | D2: 0 | E2: =Size-a -> 10 | F2: =(EXP(alpha*(Tau+OldTau+zeta-2*a*psi))*((EXP(alpha*a*psi)-EXP(alpha*b*psi))^2))/((EXP(alpha*a*psi)-EXP(alpha*(2*OldTau+b*psi)))*(alpha^2)*(psi^2)) -> 5.2512332 | G2: =(EXP(alpha*(zeta+(2*b-a)*psi))*(-1+EXP(alpha*(-1)*Size*psi))*(EXP(alpha*(2*(Tau+OldTau)+a*psi))-EXP(alpha*(2*(Tau+OldTau)+b*psi))))/(((EXP(alpha*a*psi)-EXP(alpha*(2*OldTau+b*psi)))^2)*(alpha^2)*(psi^2)) -> 0.78478212 | H2: =-Beta/alpha -> 180 | I2: =(-EXP(alpha*zeta)*Beta*(-1+EXP(alpha*Size*psi)-Size*alpha*psi))/((alpha^3)*(psi^2)) -> 1690.9246 | J2: =Beta*Theta -> 14.4 | K2: =Beta*Theta -> 14.4 | L2: =kappa -> 90 | M2: =Gamma*Size -> 0 | N2: =Size*Beta*Phi -> 32.4 | O2: =-(EXP(alpha*a*psi)+EXP(alpha*b*psi)*(-1+Size*psi*alpha))*(Beta*Phi)/((alpha*psi)*(EXP(alpha*a*psi)-EXP(alpha*b*psi))) -> 12.294172 | P2: =(EXP(alpha*(zeta-a*psi))*Beta*Phi*(-EXP(alpha*a*psi)*(-2+(-1)*Size*alpha*psi)+EXP(alpha*b*psi)*(-2+Size*alpha*psi)))/((alpha^3)*(psi^3)) -> 78.836376 | Q2: =Tau*Beta -> 117.59302 | R2: =Tau*Beta -> 117.59302 | S2: =Tau -> 0.65329456 | T2: =Profit+Utility -> 3558.5135 | U2: =(2*ij*BRIJ)+(2)*jj*BRJJ -> 1419.5866 | V2: =2*(ij*BCCIJ)+(2*jj*BCCJJ)+BCS+jj*BCPTJJ+2*(ij*BCPTIJ)+BCPTII+BCk -> 497.21969 | W2: =ij*BUTIJ+BUTII -> 2636.1466 | X2: =Revenue-Cost -> 922.36687
A3: 0.65119307 | B3: 0.5 | C3: 10 | D3: 0 | E3: =Size-a -> 10 | F3: =(EXP(alpha*(Tau+OldTau+zeta-2*a*psi))*((EXP(alpha*a*psi)-EXP(alpha*b*psi))^2))/((EXP(alpha*a*psi)-EXP(alpha*(2*OldTau+b*psi)))*(alpha^2)*(psi^2)) -> 2.7012982 | G3: =(EXP(alpha*(zeta+(2*b-a)*psi))*(-1+EXP(alpha*(-1)*Size*psi))*(EXP(alpha*(2*(Tau+OldTau)+a*psi))-EXP(alpha*(2*(Tau+OldTau)+b*psi))))/(((EXP(alpha*a*psi)-EXP(alpha*(2*OldTau+b*psi)))^2)*(alpha^2)*(psi^2)) -> 0.20766894 | H3: =-Beta/alpha -> 180 | I3: =(-EXP(alpha*zeta)*Beta*(-1+EXP(alpha*Size*psi)-Size*alpha*psi))/((alpha^3)*(psi^2)) -> 1690.9246 | J3: =Beta*Theta -> 14.4 | K3: =Beta*Theta -> 14.4 | L3: =kappa -> 90 | M3: =Gamma*Size -> 0 | N3: =Size*Beta*Phi -> 32.4 | O3: =-(EXP(alpha*a*psi)+EXP(alpha*b*psi)*(-1+Size*psi*alpha))*(Beta*Phi)/((alpha*psi)*(EXP(alpha*a*psi)-EXP(alpha*b*psi))) -> 12.294172 | P3: =(EXP(alpha*(zeta-a*psi))*Beta*Phi*(-EXP(alpha*a*psi)*(-2+(-1)*Size*alpha*psi)+EXP(alpha*b*psi)*(-2+Size*alpha*psi)))/((alpha^3)*(psi^3)) -> 78.836376 | Q3: =Tau*Beta -> 117.21475 | R3: =Tau*Beta -> 117.21475 | S3: =Tau -> 0.65119307 | T3: =Profit+Utility -> 2533.3425 | U3: =(2*ij*BRIJ)+(2)*jj*BRJJ -> 681.94772 | V3: =2*(ij*BCCIJ)+(2*jj*BCCJJ)+BCS+jj*BCPTJJ+2*(ij*BCPTIJ)+BCPTII+BCk -> 325.76355 | W3: =ij*BUTIJ+BUTII -> 2177.1583 | X3: =Revenue-Cost -> 356.18417
A4: 0.6500633 | B4: 1 | C4: 10 | D4: 0 | E4: =Size-a -> 10 | F4: =(EXP(alpha*(Tau+OldTau+zeta-2*a*psi))*((EXP(alpha*a*psi)-EXP(alpha*b*psi))^2))/((EXP(alpha*a*psi)-EXP(alpha*(2*OldTau+b*psi)))*(alpha^2)*(psi^2)) -> 1.5525123 | G4: =(EXP(alpha*(zeta+(2*b-a)*psi))*(-1+EXP(alpha*(-1)*Size*psi))*(EXP(alpha*(2*(Tau+OldTau)+a*psi))-EXP(alpha*(2*(Tau+OldTau)+b*psi))))/(((EXP(alpha*a*psi)-EXP(alpha*(2*OldTau+b*psi)))^2)*(alpha^2)*(psi^2)) -> 0.068595652 | H4: =-Beta/alpha -> 180 | I4: =(-EXP(alpha*zeta)*Beta*(-1+EXP(alpha*Size*psi)-Size*alpha*psi))/((alpha^3)*(psi^2)) -> 1690.9246 | J4: =Beta*Theta -> 14.4 | K4: =Beta*Theta -> 14.4 | L4: =kappa -> 90 | M4: =Gamma*Size -> 0 | N4: =Size*Beta*Phi -> 32.4 | O4: =-(EXP(alpha*a*psi)+EXP(alpha*b*psi)*(-1+Size*psi*alpha))*(Beta*Phi)/((alpha*psi)*(EXP(alpha*a*psi)-EXP(alpha*b*psi))) -> 12.294172 | P4: =(EXP(alpha*(zeta-a*psi))*Beta*Phi*(-EXP(alpha*a*psi)*(-2+(-1)*Size*alpha*psi)+EXP(alpha*b*psi)*(-2+Size*alpha*psi)))/((alpha^3)*(psi^3)) -> 78.836376 | Q4: =Tau*Beta -> 117.01139 | R4: =Tau*Beta -> 117.01139 | S4: =Tau -> 0.6500633 | T4: =Profit+Utility -> 2093.8326 | U4: =(2*ij*BRIJ)+(2)*jj*BRJJ -> 379.37621 | V4: =2*(ij*BCCIJ)+(2*jj*BCCJJ)+BCS+jj*BCPTJJ+2*(ij*BCPTIJ)+BCPTII+BCk -> 255.92049 | W4: =ij*BUTIJ+BUTII -> 1970.3768 | X4: =Revenue-Cost -> 123.45572
A5: 0.64938564 | B5: 1.5 | C5: 10 | D5: 0 | E5: =Size-a -> 10 | F5: =(EXP(alpha*(Tau+OldTau+zeta-2*a*psi))*((EXP(alpha*a*psi)-EXP(alpha*b*psi))^2))/((EXP(alpha*a*psi)-EXP(alpha*(2*OldTau+b*psi)))*(alpha^2)*(psi^2)) -> 0.9240959 | G5: =(EXP(alpha*(zeta+(2*b-a)*psi))*(-1+EXP(alpha*(-1)*Size*psi))*(EXP(alpha*(2*(Tau+OldTau)+a*psi))-EXP(alpha*(2*(Tau+OldTau)+b*psi))))/(((EXP(alpha*a*psi)-EXP(alpha*(2*OldTau+b*psi)))^2)*(alpha^2)*(psi^2)) -> 0.024303038 | H5: =-Beta/alpha -> 180 | I5: =(-EXP(alpha*zeta)*Beta*(-1+EXP(alpha*Size*psi)-Size*alpha*psi))/((alpha^3)*(psi^2)) -> 1690.9246 | J5: =Beta*Theta -> 14.4 | K5: =Beta*Theta -> 14.4 | L5: =kappa -> 90 | M5: =Gamma*Size -> 0 | N5: =Size*Beta*Phi -> 32.4 | O5: =-(EXP(alpha*a*psi)+EXP(alpha*b*psi)*(-1+Size*psi*alpha))*(Beta*Phi)/((alpha*psi)*(EXP(alpha*a*psi)-EXP(alpha*b*psi))) -> 12.294172 | P5: =(EXP(alpha*(zeta-a*psi))*Beta*Phi*(-EXP(alpha*a*psi)*(-2+(-1)*Size*alpha*psi)+EXP(alpha*b*psi)*(-2+Size*alpha*psi)))/((alpha^3)*(psi^3)) -> 78.836376 | Q5: =Tau*Beta -> 116.88942 | R5: =Tau*Beta -> 116.88942 | S5: =Tau -> 0.64938564 | T5: =Profit+Utility -> 1859.3178 | U5: =(2*ij*BRIJ)+(2)*jj*BRJJ -> 221.71559 | V5: =2*(ij*BCCIJ)+(2*jj*BCCJJ)+BCS+jj*BCPTJJ+2*(ij*BCPTIJ)+BCPTII+BCk -> 219.65967 | W5: =ij*BUTIJ+BUTII -> 1857.2619 | X5: =Revenue-Cost -> 2.0559232
A6: 0.64896782 | B6: 2 | C6: 10 | D6: 0 | E6: =Size-a -> 10 | F6: =(EXP(alpha*(Tau+OldTau+zeta-2*a*psi))*((EXP(alpha*a*psi)-EXP(alpha*b*psi))^2))/((EXP(alpha*a*psi)-EXP(alpha*(2*OldTau+b*psi)))*(alpha^2)*(psi^2)) -> 0.55677302 | G6: =(EXP(alpha*(zeta+(2*b-a)*psi))*(-1+EXP(alpha*(-1)*Size*psi))*(EXP(alpha*(2*(Tau+OldTau)+a*psi))-EXP(alpha*(2*(Tau+OldTau)+b*psi))))/(((EXP(alpha*a*psi)-EXP(alpha*(2*OldTau+b*psi)))^2)*(alpha^2)*(psi^2)) -> 0.008822321 | H6: =-Beta/alpha -> 180 | I6: =(-EXP(alpha*zeta)*Beta*(-1+EXP(alpha*Size*psi)-Size*alpha*psi))/((alpha^3)*(psi^2)) -> 1690.9246 | J6: =Beta*Theta -> 14.4 | K6: =Beta*Theta -> 14.4 | L6: =kappa -> 90 | M6: =Gamma*Size -> 0 | N6: =Size*Beta*Phi -> 32.4 | O6: =-(EXP(alpha*a*psi)+EXP(alpha*b*psi)*(-1+Size*psi*alpha))*(Beta*Phi)/((alpha*psi)*(EXP(alpha*a*psi)-EXP(alpha*b*psi))) -> 12.294172 | P6: =(EXP(alpha*(zeta-a*psi))*Beta*Phi*(-EXP(alpha*a*psi)*(-2+(-1)*Size*alpha*psi)+EXP(alpha*b*psi)*(-2+Size*alpha*psi)))/((alpha^3)*(psi^3)) -> 78.836376 | Q6: =Tau*Beta -> 116.81421 | R6: =Tau*Beta -> 116.81421 | S6: =Tau -> 0.64896782 | T6: =Profit+Utility -> 1724.1814 | U6: =(2*ij*BRIJ)+(2)*jj*BRJJ -> 132.13914 | V6: =2*(ij*BCCIJ)+(2*jj*BCCJJ)+BCS+jj*BCPTJJ+2*(ij*BCPTIJ)+BCPTII+BCk -> 199.10149 | W6: =ij*BUTIJ+BUTII -> 1791.1438 | X6: =Revenue-Cost -> -66.962348
A7: 0.64870987 | B7: 2.5 | C7: 10 | D7: 0 | E7: =Size-a -> 10 | F7: =(EXP(alpha*(Tau+OldTau+zeta-2*a*psi))*((EXP(alpha*a*psi)-EXP(alpha*b*psi))^2))/((EXP(alpha*a*psi)-EXP(alpha*(2*OldTau+b*psi)))*(alpha^2)*(psi^2)) -> 0.3369131 | G7: =(EXP(alpha*(zeta+(2*b-a)*psi))*(-1+EXP(alpha*(-1)*Size*psi))*(EXP(alpha*(2*(Tau+OldTau)+a*psi))-EXP(alpha*(2*(Tau+OldTau)+b*psi))))/(((EXP(alpha*a*psi)-EXP(alpha*(2*OldTau+b*psi)))^2)*(alpha^2)*(psi^2)) -> 0.0032304444 | H7: =-Beta/alpha -> 180 | I7: =(-EXP(alpha*zeta)*Beta*(-1+EXP(alpha*Size*psi)-Size*alpha*psi))/((alpha^3)*(psi^2)) -> 1690.9246 | J7: =Beta*Theta -> 14.4 | K7: =Beta*Theta -> 14.4 | L7: =kappa -> 90 | M7: =Gamma*Size -> 0 | N7: =Size*Beta*Phi -> 32.4 | O7: =-(EXP(alpha*a*psi)+EXP(alpha*b*psi)*(-1+Size*psi*alpha))*(Beta*Phi)/((alpha*psi)*(EXP(alpha*a*psi)-EXP(alpha*b*psi))) -> 12.294172 | P7: =(EXP(alpha*(zeta-a*psi))*Beta*Phi*(-EXP(alpha*a*psi)*(-2+(-1)*Size*alpha*psi)+EXP(alpha*b*psi)*(-2+Size*alpha*psi)))/((alpha^3)*(psi^3)) -> 78.836376 | Q7: =Tau*Beta -> 116.76778 | R7: =Tau*Beta -> 116.76778 | S7: =Tau -> 0.64870987 | T7: =Profit+Utility -> 1643.9833 | U7: =(2*ij*BRIJ)+(2)*jj*BRJJ -> 79.435611 | V7: =2*(ij*BCCIJ)+(2*jj*BCCJJ)+BCS+jj*BCPTJJ+2*(ij*BCPTIJ)+BCPTII+BCk -> 187.02131 | W7: =ij*BUTIJ+BUTII -> 1751.569 | X7: =Revenue-Cost -> -107.5857
A8: 0.64855112 | B8: 3 | C8: 10 | D8: 0 | E8: =Size-a -> 10 | F8: =(EXP(alpha*(Tau+OldTau+zeta-2*a*psi))*((EXP(alpha*a*psi)-EXP(alpha*b*psi))^2))/((EXP(alpha*a*psi)-EXP(alpha*(2*OldTau+b*psi)))*(alpha^2)*(psi^2)) -> 0.20418623 | G8: =(EXP(alpha*(zeta+(2*b-a)*psi))*(-1+EXP(alpha*(-1)*Size*psi))*(EXP(alpha*(2*(Tau+OldTau)+a*psi))-EXP(alpha*(2*(Tau+OldTau)+b*psi))))/(((EXP(alpha*a*psi)-EXP(alpha*(2*OldTau+b*psi)))^2)*(alpha^2)*(psi^2)) -> 0.0011865318 | H8: =-Beta/alpha -> 180 | I8: =(-EXP(alpha*zeta)*Beta*(-1+EXP(alpha*Size*psi)-Size*alpha*psi))/((alpha^3)*(psi^2)) -> 1690.9246 | J8: =Beta*Theta -> 14.4 | K8: =Beta*Theta -> 14.4 | L8: =kappa -> 90 | M8: =Gamma*Size -> 0 | N8: =Size*Beta*Phi -> 32.4 | O8: =-(EXP(alpha*a*psi)+EXP(alpha*b*psi)*(-1+Size*psi*alpha))*(Beta*Phi)/((alpha*psi)*(EXP(alpha*a*psi)-EXP(alpha*b*psi))) -> 12.294172 | P8: =(EXP(alpha*(zeta-a*psi))*Beta*Phi*(-EXP(alpha*a*psi)*(-2+(-1)*Size*alpha*psi)+EXP(alpha*b*psi)*(-2+Size*alpha*psi)))/((alpha^3)*(psi^3)) -> 78.836376 | Q8: =Tau*Beta -> 116.7392 | R8: =Tau*Beta -> 116.7392 | S8: =Tau -> 0.64855112 | T8: =Profit+Utility -> 1595.8181 | U8: =(2*ij*BRIJ)+(2)*jj*BRJJ -> 47.950103 | V8: =2*(ij*BCCIJ)+(2*jj*BCCJJ)+BCS+jj*BCPTJJ+2*(ij*BCPTIJ)+BCPTII+BCk -> 179.81016 | W8: =ij*BUTIJ+BUTII -> 1727.6781 | X8: =Revenue-Cost -> -131.86005
A9: 0.64845367 | B9: 3.5 | C9: 10 | D9: 0 | E9: =Size-a -> 10 | F9: =(EXP(alpha*(Tau+OldTau+zeta-2*a*psi))*((EXP(alpha*a*psi)-EXP(alpha*b*psi))^2))/((EXP(alpha*a*psi)-EXP(alpha*(2*OldTau+b*psi)))*(alpha^2)*(psi^2)) -> 0.12381396 | G9: =(EXP(alpha*(zeta+(2*b-a)*psi))*(-1+EXP(alpha*(-1)*Size*psi))*(EXP(alpha*(2*(Tau+OldTau)+a*psi))-EXP(alpha*(2*(Tau+OldTau)+b*psi))))/(((EXP(alpha*a*psi)-EXP(alpha*(2*OldTau+b*psi)))^2)*(alpha^2)*(psi^2)) -> 0.00043628044 | H9: =-Beta/alpha -> 180 | I9: =(-EXP(alpha*zeta)*Beta*(-1+EXP(alpha*Size*psi)-Size*alpha*psi))/((alpha^3)*(psi^2)) -> 1690.9246 | J9: =Beta*Theta -> 14.4 | K9: =Beta*Theta -> 14.4 | L9: =kappa -> 90 | M9: =Gamma*Size -> 0 | N9: =Size*Beta*Phi -> 32.4 | O9: =-(EXP(alpha*a*psi)+EXP(alpha*b*psi)*(-1+Size*psi*alpha))*(Beta*Phi)/((alpha*psi)*(EXP(alpha*a*psi)-EXP(alpha*b*psi))) -> 12.294172 | P9: =(EXP(alpha*(zeta-a*psi))*Beta*Phi*(-EXP(alpha*a*psi)*(-2+(-1)*Size*alpha*psi)+EXP(alpha*b*psi)*(-2+Size*alpha*psi)))/((alpha^3)*(psi^3)) -> 78.836376 | Q9: =Tau*Beta -> 116.72166 | R9: =Tau*Beta -> 116.72166 | S9: =Tau -> 0.64845367 | T9: =Profit+Utility -> 1566.7432 | U9: =(2*ij*BRIJ)+(2)*jj*BRJJ -> 29.00539 | V9: =2*(ij*BCCIJ)+(2*jj*BCCJJ)+BCS+jj*BCPTJJ+2*(ij*BCPTIJ)+BCPTII+BCk -> 175.4733 | W9: =ij*BUTIJ+BUTII -> 1713.2111 | X9: =Revenue-Cost -> -146.46791
A10: 0.64901074 | B10: 4 | C10: 10 | D10: 0 | E10: =Size-a -> 10 | F10: =(EXP(alpha*(Tau+OldTau+zeta-2*a*psi))*((EXP(alpha*a*psi)-EXP(alpha*b*psi))^2))/((EXP(alpha*a*psi)-EXP(alpha*(2*OldTau+b*psi)))*(alpha^2)*(psi^2)) -> 0.075045488 | G10: =(EXP(alpha*(zeta+(2*b-a)*psi))*(-1+EXP(alpha*(-1)*Size*psi))*(EXP(alpha*(2*(Tau+OldTau)+a*psi))-EXP(alpha*(2*(Tau+OldTau)+b*psi))))/(((EXP(alpha*a*psi)-EXP(alpha*(2*OldTau+b*psi)))^2)*(alpha^2)*(psi^2)) -> 0.00016027864 | H10: =-Beta/alpha -> 180 | I10: =(-EXP(alpha*zeta)*Beta*(-1+EXP(alpha*Size*psi)-Size*alpha*psi))/((alpha^3)*(psi^2)) -> 1690.9246 | J10: =Beta*Theta -> 14.4 | K10: =Beta*Theta -> 14.4 | L10: =kappa -> 90 | M10: =Gamma*Size -> 0 | N10: =Size*Beta*Phi -> 32.4 | O10: =-(EXP(alpha*a*psi)+EXP(alpha*b*psi)*(-1+Size*psi*alpha))*(Beta*Phi)/((alpha*psi)*(EXP(alpha*a*psi)-EXP(alpha*b*psi))) -> 12.294172 | P10: =(EXP(alpha*(zeta-a*psi))*Beta*Phi*(-EXP(alpha*a*psi)*(-2+(-1)*Size*alpha*psi)+EXP(alpha*b*psi)*(-2+Size*alpha*psi)))/((alpha^3)*(psi^3)) -> 78.836376 | Q10: =Tau*Beta -> 116.82193 | R10: =Tau*Beta -> 116.82193 | S10: =Tau -> 0.64901074 | T10: =Profit+Utility -> 1549.1514 | U10: =(2*ij*BRIJ)+(2)*jj*BRJJ -> 17.571366 | V10: =2*(ij*BCCIJ)+(2*jj*BCCJJ)+BCS+jj*BCPTJJ+2*(ij*BCPTIJ)+BCPTII+BCk -> 172.85274 | W10: =ij*BUTIJ+BUTII -> 1704.4328 | X10: =Revenue-Cost -> -155.28137
