Workbook

Sheet Defaults
B1: Values in Model | C1: Original
A2: v | B2: =1/psi -> 6.6666667 | C2: =1/psi -> 6.6666667
A3: w | B3: =1/alpha -> -1 | C3: =1/alpha -> -1
A4: y | B4: =EXP(alpha*zeta) -> 0.29229258 | C4: =EXP(alpha*zeta) -> 0.29229258
A5: Beta | B5: 180 | C5: 180
A6: Theta | B6: 0.08 | C6: 0.017
A7: Gamma | B7: 0 | C7: 0
A8: Phi | B8: 0.018 | C8: 0.018
A9: alpha | B9: -1 | C9: -1
A10: psi | B10: 0.15 | C10: 0.15
A11: zeta | B11: 1.23 | C11: 1.23
A12: kappa | B12: 90 | C12: 90

Sheet W-Tax(All-Tax)
A1: Tau | B1: OldTau | C1: Size | D1: a | E1: b | F1: ij | G1: jj | H1: BUTIJ | I1: BUTII | J1: BCCIJ | K1: BCCJJ | L1: BCk | M1: BCS | N1: BCPTJJ | O1: BCPTIJ | P1: BCPTII | Q1: BRIJ | R1: BRJJ | S1: Toll | T1: Welfare | U1: Revenue | V1: Cost | W1: Utility | X1: Profit | Y1: Size2 | Z1: W/Size | AA1: ∏/Size | AB1: U/Size
A2: 0 | B2: =Tau -> 0 | C2: 1 | D2: 0 | E2: =Size-a -> 1 | F2: =(EXP(alpha*(Tau+OldTau+zeta-2*a*psi))*((EXP(alpha*a*psi)-EXP(alpha*b*psi))^2))/((EXP(alpha*a*psi)-EXP(alpha*(2*OldTau+b*psi)))*(alpha^2)*(psi^2)) -> 1.8095122 | G2: =(EXP(alpha*(zeta+(2*b-a)*psi))*(-1+EXP(alpha*(-1)*Size*psi))*(EXP(alpha*(2*(Tau+OldTau)+a*psi))-EXP(alpha*(2*(Tau+OldTau)+b*psi))))/(((EXP(alpha*a*psi)-EXP(alpha*(2*OldTau+b*psi)))^2)*(alpha^2)*(psi^2)) -> 11.181269 | H2: =-Beta/alpha -> 180 | I2: =(-EXP(alpha*zeta)*Beta*(-1+EXP(alpha*Size*psi)-Size*alpha*psi))/((alpha^3)*(psi^2)) -> 25.038896 | J2: 0 | K2: 0 | L2: 0 | M2: =Gamma*Size -> 0 | N2: =Size*Beta*Phi -> 3.24 | O2: =-(EXP(alpha*a*psi)+EXP(alpha*b*psi)*(-1+Size*psi*alpha))*(Beta*Phi)/((alpha*psi)*(EXP(alpha*a*psi)-EXP(alpha*b*psi))) -> 1.5795152 | P2: =(EXP(alpha*(zeta-a*psi))*Beta*Phi*(-EXP(alpha*a*psi)*(-2+(-1)*Size*alpha*psi)+EXP(alpha*b*psi)*(-2+Size*alpha*psi)))/((alpha^3)*(psi^3)) -> 0.14651555 | Q2: =Tau*Beta -> 0 | R2: =Tau*Beta -> 0 | S2: =Tau -> 0 | T2: =Profit+Utility -> 308.66096 | U2: =(2*ij*BRIJ)+2*jj*BRJJ -> 0 | V2: =2*(ij*BCCIJ)+(2*jj*BCCJJ)+BCS+jj*BCPTJJ+2*(ij*BCPTIJ)+BCPTII+BCk -> 42.090131 | W2: =ij*BUTIJ+BUTII -> 350.75109 | X2: =Revenue-Cost -> -42.090131 | Y2: =Size -> 1 | Z2: =Welfare/(Size) -> 308.66096 | AA2: =Profit/(Size) -> -42.090131 | AB2: =Utility/(Size) -> 350.75109
A3: 0 | B3: =Tau -> 0 | C3: 2 | D3: 0 | E3: =Size-a -> 2 | F3: =(EXP(alpha*(Tau+OldTau+zeta-2*a*psi))*((EXP(alpha*a*psi)-EXP(alpha*b*psi))^2))/((EXP(alpha*a*psi)-EXP(alpha*(2*OldTau+b*psi)))*(alpha^2)*(psi^2)) -> 3.3669738 | G3: =(EXP(alpha*(zeta+(2*b-a)*psi))*(-1+EXP(alpha*(-1)*Size*psi))*(EXP(alpha*(2*(Tau+OldTau)+a*psi))-EXP(alpha*(2*(Tau+OldTau)+b*psi))))/(((EXP(alpha*a*psi)-EXP(alpha*(2*OldTau+b*psi)))^2)*(alpha^2)*(psi^2)) -> 9.6238074 | H3: =-Beta/alpha -> 180 | I3: =(-EXP(alpha*zeta)*Beta*(-1+EXP(alpha*Size*psi)-Size*alpha*psi))/((alpha^3)*(psi^2)) -> 95.446904 | J3: 0 | K3: 0 | L3: 0 | M3: =Gamma*Size -> 0 | N3: =Size*Beta*Phi -> 6.48 | O3: =-(EXP(alpha*a*psi)+EXP(alpha*b*psi)*(-1+Size*psi*alpha))*(Beta*Phi)/((alpha*psi)*(EXP(alpha*a*psi)-EXP(alpha*b*psi))) -> 3.0782425 | P3: =(EXP(alpha*(zeta-a*psi))*Beta*Phi*(-EXP(alpha*a*psi)*(-2+(-1)*Size*alpha*psi)+EXP(alpha*b*psi)*(-2+Size*alpha*psi)))/((alpha^3)*(psi^3)) -> 1.0892667 | Q3: =Tau*Beta -> 0 | R3: =Tau*Beta -> 0 | S3: =Tau -> 0 | T3: =Profit+Utility -> 617.32192 | U3: =(2*ij*BRIJ)+2*jj*BRJJ -> 0 | V3: =2*(ij*BCCIJ)+(2*jj*BCCJJ)+BCS+jj*BCPTJJ+2*(ij*BCPTIJ)+BCPTII+BCk -> 84.180262 | W3: =ij*BUTIJ+BUTII -> 701.50219 | X3: =Revenue-Cost -> -84.180262 | Y3: =Size -> 2 | Z3: =Welfare/(Size) -> 308.66096 | AA3: =Profit/(Size) -> -42.090131 | AB3: =Utility/(Size) -> 350.75109
A4: 0 | B4: =Tau -> 0 | C4: 5 | D4: 0 | E4: =Size-a -> 5 | F4: =(EXP(alpha*(Tau+OldTau+zeta-2*a*psi))*((EXP(alpha*a*psi)-EXP(alpha*b*psi))^2))/((EXP(alpha*a*psi)-EXP(alpha*(2*OldTau+b*psi)))*(alpha^2)*(psi^2)) -> 6.8543707 | G4: =(EXP(alpha*(zeta+(2*b-a)*psi))*(-1+EXP(alpha*(-1)*Size*psi))*(EXP(alpha*(2*(Tau+OldTau)+a*psi))-EXP(alpha*(2*(Tau+OldTau)+b*psi))))/(((EXP(alpha*a*psi)-EXP(alpha*(2*OldTau+b*psi)))^2)*(alpha^2)*(psi^2)) -> 6.1364105 | H4: =-Beta/alpha -> 180 | I4: =(-EXP(alpha*zeta)*Beta*(-1+EXP(alpha*Size*psi)-Size*alpha*psi))/((alpha^3)*(psi^2)) -> 519.96874 | J4: 0 | K4: 0 | L4: 0 | M4: =Gamma*Size -> 0 | N4: =Size*Beta*Phi -> 16.2 | O4: =-(EXP(alpha*a*psi)+EXP(alpha*b*psi)*(-1+Size*psi*alpha))*(Beta*Phi)/((alpha*psi)*(EXP(alpha*a*psi)-EXP(alpha*b*psi))) -> 7.0968668 | P4: =(EXP(alpha*(zeta-a*psi))*Beta*Phi*(-EXP(alpha*a*psi)*(-2+(-1)*Size*alpha*psi)+EXP(alpha*b*psi)*(-2+Size*alpha*psi)))/((alpha^3)*(psi^3)) -> 13.751693 | Q4: =Tau*Beta -> 0 | R4: =Tau*Beta -> 0 | S4: =Tau -> 0 | T4: =Profit+Utility -> 1543.3048 | U4: =(2*ij*BRIJ)+2*jj*BRJJ -> 0 | V4: =2*(ij*BCCIJ)+(2*jj*BCCJJ)+BCS+jj*BCPTJJ+2*(ij*BCPTIJ)+BCPTII+BCk -> 210.45066 | W4: =ij*BUTIJ+BUTII -> 1753.7555 | X4: =Revenue-Cost -> -210.45066 | Y4: =Size -> 5 | Z4: =Welfare/(Size) -> 308.66096 | AA4: =Profit/(Size) -> -42.090131 | AB4: =Utility/(Size) -> 350.75109
A5: 0 | B5: =Tau -> 0 | C5: 10 | D5: 0 | E5: =Size-a -> 10 | F5: =(EXP(alpha*(Tau+OldTau+zeta-2*a*psi))*((EXP(alpha*a*psi)-EXP(alpha*b*psi))^2))/((EXP(alpha*a*psi)-EXP(alpha*(2*OldTau+b*psi)))*(alpha^2)*(psi^2)) -> 10.092146 | G5: =(EXP(alpha*(zeta+(2*b-a)*psi))*(-1+EXP(alpha*(-1)*Size*psi))*(EXP(alpha*(2*(Tau+OldTau)+a*psi))-EXP(alpha*(2*(Tau+OldTau)+b*psi))))/(((EXP(alpha*a*psi)-EXP(alpha*(2*OldTau+b*psi)))^2)*(alpha^2)*(psi^2)) -> 2.8986351 | H5: =-Beta/alpha -> 180 | I5: =(-EXP(alpha*zeta)*Beta*(-1+EXP(alpha*Size*psi)-Size*alpha*psi))/((alpha^3)*(psi^2)) -> 1690.9246 | J5: 0 | K5: 0 | L5: 0 | M5: =Gamma*Size -> 0 | N5: =Size*Beta*Phi -> 32.4 | O5: =-(EXP(alpha*a*psi)+EXP(alpha*b*psi)*(-1+Size*psi*alpha))*(Beta*Phi)/((alpha*psi)*(EXP(alpha*a*psi)-EXP(alpha*b*psi))) -> 12.294172 | P5: =(EXP(alpha*(zeta-a*psi))*Beta*Phi*(-EXP(alpha*a*psi)*(-2+(-1)*Size*alpha*psi)+EXP(alpha*b*psi)*(-2+Size*alpha*psi)))/((alpha^3)*(psi^3)) -> 78.836376 | Q5: =Tau*Beta -> 0 | R5: =Tau*Beta -> 0 | S5: =Tau -> 0 | T5: =Profit+Utility -> 3086.6096 | U5: =(2*ij*BRIJ)+2*jj*BRJJ -> 0 | V5: =2*(ij*BCCIJ)+(2*jj*BCCJJ)+BCS+jj*BCPTJJ+2*(ij*BCPTIJ)+BCPTII+BCk -> 420.90131 | W5: =ij*BUTIJ+BUTII -> 3507.5109 | X5: =Revenue-Cost -> -420.90131 | Y5: =Size -> 10 | Z5: =Welfare/(Size) -> 308.66096 | AA5: =Profit/(Size) -> -42.090131 | AB5: =Utility/(Size) -> 350.75109
A6: 0 | B6: =Tau -> 0 | C6: 20 | D6: 0 | E6: =Size-a -> 20 | F6: =(EXP(alpha*(Tau+OldTau+zeta-2*a*psi))*((EXP(alpha*a*psi)-EXP(alpha*b*psi))^2))/((EXP(alpha*a*psi)-EXP(alpha*(2*OldTau+b*psi)))*(alpha^2)*(psi^2)) -> 12.344008 | G6: =(EXP(alpha*(zeta+(2*b-a)*psi))*(-1+EXP(alpha*(-1)*Size*psi))*(EXP(alpha*(2*(Tau+OldTau)+a*psi))-EXP(alpha*(2*(Tau+OldTau)+b*psi))))/(((EXP(alpha*a*psi)-EXP(alpha*(2*OldTau+b*psi)))^2)*(alpha^2)*(psi^2)) -> 0.64677291 | H6: =-Beta/alpha -> 180 | I6: =(-EXP(alpha*zeta)*Beta*(-1+EXP(alpha*Size*psi)-Size*alpha*psi))/((alpha^3)*(psi^2)) -> 4793.1004 | J6: 0 | K6: 0 | L6: 0 | M6: =Gamma*Size -> 0 | N6: =Size*Beta*Phi -> 64.8 | O6: =-(EXP(alpha*a*psi)+EXP(alpha*b*psi)*(-1+Size*psi*alpha))*(Beta*Phi)/((alpha*psi)*(EXP(alpha*a*psi)-EXP(alpha*b*psi))) -> 18.204759 | P6: =(EXP(alpha*(zeta-a*psi))*Beta*Phi*(-EXP(alpha*a*psi)*(-2+(-1)*Size*alpha*psi)+EXP(alpha*b*psi)*(-2+Size*alpha*psi)))/((alpha^3)*(psi^3)) -> 350.45235 | Q6: =Tau*Beta -> 0 | R6: =Tau*Beta -> 0 | S6: =Tau -> 0 | T6: =Profit+Utility -> 6173.2192 | U6: =(2*ij*BRIJ)+2*jj*BRJJ -> 0 | V6: =2*(ij*BCCIJ)+(2*jj*BCCJJ)+BCS+jj*BCPTJJ+2*(ij*BCPTIJ)+BCPTII+BCk -> 841.80262 | W6: =ij*BUTIJ+BUTII -> 7015.0219 | X6: =Revenue-Cost -> -841.80262 | Y6: =Size -> 20 | Z6: =Welfare/(Size) -> 308.66096 | AA6: =Profit/(Size) -> -42.090131 | AB6: =Utility/(Size) -> 350.75109
A7: 0 | B7: =Tau -> 0 | C7: 50 | D7: 0 | E7: =Size-a -> 50 | F7: =(EXP(alpha*(Tau+OldTau+zeta-2*a*psi))*((EXP(alpha*a*psi)-EXP(alpha*b*psi))^2))/((EXP(alpha*a*psi)-EXP(alpha*(2*OldTau+b*psi)))*(alpha^2)*(psi^2)) -> 12.983596 | G7: =(EXP(alpha*(zeta+(2*b-a)*psi))*(-1+EXP(alpha*(-1)*Size*psi))*(EXP(alpha*(2*(Tau+OldTau)+a*psi))-EXP(alpha*(2*(Tau+OldTau)+b*psi))))/(((EXP(alpha*a*psi)-EXP(alpha*(2*OldTau+b*psi)))^2)*(alpha^2)*(psi^2)) -> 0.0071849981 | H7: =-Beta/alpha -> 180 | I7: =(-EXP(alpha*zeta)*Beta*(-1+EXP(alpha*Size*psi)-Size*alpha*psi))/((alpha^3)*(psi^2)) -> 15200.507 | J7: 0 | K7: 0 | L7: 0 | M7: =Gamma*Size -> 0 | N7: =Size*Beta*Phi -> 162 | O7: =-(EXP(alpha*a*psi)+EXP(alpha*b*psi)*(-1+Size*psi*alpha))*(Beta*Phi)/((alpha*psi)*(EXP(alpha*a*psi)-EXP(alpha*b*psi))) -> 21.510351 | P7: =(EXP(alpha*(zeta-a*psi))*Beta*Phi*(-EXP(alpha*a*psi)*(-2+(-1)*Size*alpha*psi)+EXP(alpha*b*psi)*(-2+Size*alpha*psi)))/((alpha^3)*(psi^3)) -> 1544.7792 | Q7: =Tau*Beta -> 0 | R7: =Tau*Beta -> 0 | S7: =Tau -> 0 | T7: =Profit+Utility -> 15433.048 | U7: =(2*ij*BRIJ)+2*jj*BRJJ -> 0 | V7: =2*(ij*BCCIJ)+(2*jj*BCCJJ)+BCS+jj*BCPTJJ+2*(ij*BCPTIJ)+BCPTII+BCk -> 2104.5066 | W7: =ij*BUTIJ+BUTII -> 17537.555 | X7: =Revenue-Cost -> -2104.5066 | Y7: =Size -> 50 | Z7: =Welfare/(Size) -> 308.66096 | AA7: =Profit/(Size) -> -42.090131 | AB7: =Utility/(Size) -> 350.75109
A8: 0 | B8: =Tau -> 0 | C8: 100 | D8: 0 | E8: =Size-a -> 100 | F8: =(EXP(alpha*(Tau+OldTau+zeta-2*a*psi))*((EXP(alpha*a*psi)-EXP(alpha*b*psi))^2))/((EXP(alpha*a*psi)-EXP(alpha*(2*OldTau+b*psi)))*(alpha^2)*(psi^2)) -> 12.990777 | G8: =(EXP(alpha*(zeta+(2*b-a)*psi))*(-1+EXP(alpha*(-1)*Size*psi))*(EXP(alpha*(2*(Tau+OldTau)+a*psi))-EXP(alpha*(2*(Tau+OldTau)+b*psi))))/(((EXP(alpha*a*psi)-EXP(alpha*(2*OldTau+b*psi)))^2)*(alpha^2)*(psi^2)) -> 3.9739101e-06 | H8: =-Beta/alpha -> 180 | I8: =(-EXP(alpha*zeta)*Beta*(-1+EXP(alpha*Size*psi)-Size*alpha*psi))/((alpha^3)*(psi^2)) -> 32736.769 | J8: 0 | K8: 0 | L8: 0 | M8: =Gamma*Size -> 0 | N8: =Size*Beta*Phi -> 324 | O8: =-(EXP(alpha*a*psi)+EXP(alpha*b*psi)*(-1+Size*psi*alpha))*(Beta*Phi)/((alpha*psi)*(EXP(alpha*a*psi)-EXP(alpha*b*psi))) -> 21.599901 | P8: =(EXP(alpha*(zeta-a*psi))*Beta*Phi*(-EXP(alpha*a*psi)*(-2+(-1)*Size*alpha*psi)+EXP(alpha*b*psi)*(-2+Size*alpha*psi)))/((alpha^3)*(psi^3)) -> 3647.8128 | Q8: =Tau*Beta -> 0 | R8: =Tau*Beta -> 0 | S8: =Tau -> 0 | T8: =Profit+Utility -> 30866.096 | U8: =(2*ij*BRIJ)+2*jj*BRJJ -> 0 | V8: =2*(ij*BCCIJ)+(2*jj*BCCJJ)+BCS+jj*BCPTJJ+2*(ij*BCPTIJ)+BCPTII+BCk -> 4209.0131 | W8: =ij*BUTIJ+BUTII -> 35075.109 | X8: =Revenue-Cost -> -4209.0131 | Y8: =Size -> 100 | Z8: =Welfare/(Size) -> 308.66096 | AA8: =Profit/(Size) -> -42.090131 | AB8: =Utility/(Size) -> 350.75109
A9: 0 | B9: =Tau -> 0 | C9: 200 | D9: 0 | E9: =Size-a -> 200 | F9: =(EXP(alpha*(Tau+OldTau+zeta-2*a*psi))*((EXP(alpha*a*psi)-EXP(alpha*b*psi))^2))/((EXP(alpha*a*psi)-EXP(alpha*(2*OldTau+b*psi)))*(alpha^2)*(psi^2)) -> 12.990781 | G9: =(EXP(alpha*(zeta+(2*b-a)*psi))*(-1+EXP(alpha*(-1)*Size*psi))*(EXP(alpha*(2*(Tau+OldTau)+a*psi))-EXP(alpha*(2*(Tau+OldTau)+b*psi))))/(((EXP(alpha*a*psi)-EXP(alpha*(2*OldTau+b*psi)))^2)*(alpha^2)*(psi^2)) -> 1.2156283e-12 | H9: =-Beta/alpha -> 180 | I9: =(-EXP(alpha*zeta)*Beta*(-1+EXP(alpha*Size*psi)-Size*alpha*psi))/((alpha^3)*(psi^2)) -> 67811.878 | J9: 0 | K9: 0 | L9: 0 | M9: =Gamma*Size -> 0 | N9: =Size*Beta*Phi -> 648 | O9: =-(EXP(alpha*a*psi)+EXP(alpha*b*psi)*(-1+Size*psi*alpha))*(Beta*Phi)/((alpha*psi)*(EXP(alpha*a*psi)-EXP(alpha*b*psi))) -> 21.6 | P9: =(EXP(alpha*(zeta-a*psi))*Beta*Phi*(-EXP(alpha*a*psi)*(-2+(-1)*Size*alpha*psi)+EXP(alpha*b*psi)*(-2+Size*alpha*psi)))/((alpha^3)*(psi^3)) -> 7856.8245 | Q9: =Tau*Beta -> 0 | R9: =Tau*Beta -> 0 | S9: =Tau -> 0 | T9: =Profit+Utility -> 61732.192 | U9: =(2*ij*BRIJ)+2*jj*BRJJ -> 0 | V9: =2*(ij*BCCIJ)+(2*jj*BCCJJ)+BCS+jj*BCPTJJ+2*(ij*BCPTIJ)+BCPTII+BCk -> 8418.0262 | W9: =ij*BUTIJ+BUTII -> 70150.219 | X9: =Revenue-Cost -> -8418.0262 | Y9: =Size -> 200 | Z9: =Welfare/(Size) -> 308.66096 | AA9: =Profit/(Size) -> -42.090131 | AB9: =Utility/(Size) -> 350.75109
A10: 0 | B10: =Tau -> 0 | C10: 500 | D10: 0 | E10: =Size-a -> 500 | F10: =(EXP(alpha*(Tau+OldTau+zeta-2*a*psi))*((EXP(alpha*a*psi)-EXP(alpha*b*psi))^2))/((EXP(alpha*a*psi)-EXP(alpha*(2*OldTau+b*psi)))*(alpha^2)*(psi^2)) -> 12.990781 | G10: =(EXP(alpha*(zeta+(2*b-a)*psi))*(-1+EXP(alpha*(-1)*Size*psi))*(EXP(alpha*(2*(Tau+OldTau)+a*psi))-EXP(alpha*(2*(Tau+OldTau)+b*psi))))/(((EXP(alpha*a*psi)-EXP(alpha*(2*OldTau+b*psi)))^2)*(alpha^2)*(psi^2)) -> 3.4797587e-32 | H10: =-Beta/alpha -> 180 | I10: =(-EXP(alpha*zeta)*Beta*(-1+EXP(alpha*Size*psi)-Size*alpha*psi))/((alpha^3)*(psi^2)) -> 173037.21 | J10: 0 | K10: 0 | L10: 0 | M10: =Gamma*Size -> 0 | N10: =Size*Beta*Phi -> 1620 | O10: =-(EXP(alpha*a*psi)+EXP(alpha*b*psi)*(-1+Size*psi*alpha))*(Beta*Phi)/((alpha*psi)*(EXP(alpha*a*psi)-EXP(alpha*b*psi))) -> 21.6 | P10: =(EXP(alpha*(zeta-a*psi))*Beta*Phi*(-EXP(alpha*a*psi)*(-2+(-1)*Size*alpha*psi)+EXP(alpha*b*psi)*(-2+Size*alpha*psi)))/((alpha^3)*(psi^3)) -> 20483.864 | Q10: =Tau*Beta -> 0 | R10: =Tau*Beta -> 0 | S10: =Tau -> 0 | T10: =Profit+Utility -> 154330.48 | U10: =(2*ij*BRIJ)+2*jj*BRJJ -> 0 | V10: =2*(ij*BCCIJ)+(2*jj*BCCJJ)+BCS+jj*BCPTJJ+2*(ij*BCPTIJ)+BCPTII+BCk -> 21045.066 | W10: =ij*BUTIJ+BUTII -> 175375.55 | X10: =Revenue-Cost -> -21045.066 | Y10: =Size -> 500 | Z10: =Welfare/(Size) -> 308.66096 | AA10: =Profit/(Size) -> -42.090131 | AB10: =Utility/(Size) -> 350.75109
A11: 0 | B11: =Tau -> 0 | C11: 1000 | D11: 0 | E11: =Size-a -> 1000 | F11: =(EXP(alpha*(Tau+OldTau+zeta-2*a*psi))*((EXP(alpha*a*psi)-EXP(alpha*b*psi))^2))/((EXP(alpha*a*psi)-EXP(alpha*(2*OldTau+b*psi)))*(alpha^2)*(psi^2)) -> 12.990781 | G11: =(EXP(alpha*(zeta+(2*b-a)*psi))*(-1+EXP(alpha*(-1)*Size*psi))*(EXP(alpha*(2*(Tau+OldTau)+a*psi))-EXP(alpha*(2*(Tau+OldTau)+b*psi))))/(((EXP(alpha*a*psi)-EXP(alpha*(2*OldTau+b*psi)))^2)*(alpha^2)*(psi^2)) -> 9.3210102e-65 | H11: =-Beta/alpha -> 180 | I11: =(-EXP(alpha*zeta)*Beta*(-1+EXP(alpha*Size*psi)-Size*alpha*psi))/((alpha^3)*(psi^2)) -> 348412.75 | J11: 0 | K11: 0 | L11: 0 | M11: =Gamma*Size -> 0 | N11: =Size*Beta*Phi -> 3240 | O11: =-(EXP(alpha*a*psi)+EXP(alpha*b*psi)*(-1+Size*psi*alpha))*(Beta*Phi)/((alpha*psi)*(EXP(alpha*a*psi)-EXP(alpha*b*psi))) -> 21.6 | P11: =(EXP(alpha*(zeta-a*psi))*Beta*Phi*(-EXP(alpha*a*psi)*(-2+(-1)*Size*alpha*psi)+EXP(alpha*b*psi)*(-2+Size*alpha*psi)))/((alpha^3)*(psi^3)) -> 41528.929 | Q11: =Tau*Beta -> 0 | R11: =Tau*Beta -> 0 | S11: =Tau -> 0 | T11: =Profit+Utility -> 308660.96 | U11: =(2*ij*BRIJ)+2*jj*BRJJ -> 0 | V11: =2*(ij*BCCIJ)+(2*jj*BCCJJ)+BCS+jj*BCPTJJ+2*(ij*BCPTIJ)+BCPTII+BCk -> 42090.131 | W11: =ij*BUTIJ+BUTII -> 350751.09 | X11: =Revenue-Cost -> -42090.131 | Y11: =Size -> 1000 | Z11: =Welfare/(Size) -> 308.66096 | AA11: =Profit/(Size) -> -42.090131 | AB11: =Utility/(Size) -> 350.75109

Sheet W-Toll(All-Tax)
A1: Tau | B1: OldTau | C1: Size | D1: a | E1: b | F1: ij | G1: jj | H1: BUTIJ | I1: BUTII | J1: BCCIJ | K1: BCCJJ | L1: BCk | M1: BCS | N1: BCPTJJ | O1: BCPTIJ | P1: BCPTII | Q1: BRIJ | R1: BRJJ | S1: Toll | T1: Welfare | U1: Revenue | V1: Cost | W1: Utility | X1: Profit | Y1: Size2 | Z1: W-Toll/Size | AA1: ∏/Size | AB1: U/Size | AC1: W-Tax/Size
A2: 0.5889719 | B2: 0 | C2: 1 | D2: 0 | E2: =Size-a -> 1 | F2: =(EXP(alpha*(Tau+OldTau+zeta-2*a*psi))*((EXP(alpha*a*psi)-EXP(alpha*b*psi))^2))/((EXP(alpha*a*psi)-EXP(alpha*(2*OldTau+b*psi)))*(alpha^2)*(psi^2)) -> 1.0040938 | G2: =(EXP(alpha*(zeta+(2*b-a)*psi))*(-1+EXP(alpha*(-1)*Size*psi))*(EXP(alpha*(2*(Tau+OldTau)+a*psi))-EXP(alpha*(2*(Tau+OldTau)+b*psi))))/(((EXP(alpha*a*psi)-EXP(alpha*(2*OldTau+b*psi)))^2)*(alpha^2)*(psi^2)) -> 3.4428382 | H2: =-Beta/alpha -> 180 | I2: =(-EXP(alpha*zeta)*Beta*(-1+EXP(alpha*Size*psi)-Size*alpha*psi))/((alpha^3)*(psi^2)) -> 25.038896 | J2: =Beta*Theta -> 14.4 | K2: =Beta*Theta -> 14.4 | L2: =kappa -> 90 | M2: =Gamma*Size -> 0 | N2: =Size*Beta*Phi -> 3.24 | O2: =-(EXP(alpha*a*psi)+EXP(alpha*b*psi)*(-1+Size*psi*alpha))*(Beta*Phi)/((alpha*psi)*(EXP(alpha*a*psi)-EXP(alpha*b*psi))) -> 1.5795152 | P2: =(EXP(alpha*(zeta-a*psi))*Beta*Phi*(-EXP(alpha*a*psi)*(-2+(-1)*Size*alpha*psi)+EXP(alpha*b*psi)*(-2+Size*alpha*psi)))/((alpha^3)*(psi^3)) -> 0.14651555 | Q2: =Tau*Beta -> 106.01494 | R2: =Tau*Beta -> 106.01494 | S2: =Tau -> 0.5889719 | T2: =Profit+Utility -> 916.11332 | U2: =(2*ij*BRIJ)+2*jj*BRJJ -> 942.88245 | V2: =2*(ij*BCCIJ)+(2*jj*BCCJJ)+BCS+jj*BCPTJJ+2*(ij*BCPTIJ)+BCPTII+BCk -> 232.54491 | W2: =ij*BUTIJ+BUTII -> 205.77577 | X2: =Revenue-Cost -> 710.33754 | Y2: =Size -> 1 | Z2: =Welfare/(Size) -> 916.11332 | AA2: =Profit/(Size) -> 710.33754 | AB2: =Utility/(Size) -> 205.77577 | AC2: 308.66096
A3: 0.5977839 | B3: 0 | C3: 2 | D3: 0 | E3: =Size-a -> 2 | F3: =(EXP(alpha*(Tau+OldTau+zeta-2*a*psi))*((EXP(alpha*a*psi)-EXP(alpha*b*psi))^2))/((EXP(alpha*a*psi)-EXP(alpha*(2*OldTau+b*psi)))*(alpha^2)*(psi^2)) -> 1.8519339 | G3: =(EXP(alpha*(zeta+(2*b-a)*psi))*(-1+EXP(alpha*(-1)*Size*psi))*(EXP(alpha*(2*(Tau+OldTau)+a*psi))-EXP(alpha*(2*(Tau+OldTau)+b*psi))))/(((EXP(alpha*a*psi)-EXP(alpha*(2*OldTau+b*psi)))^2)*(alpha^2)*(psi^2)) -> 2.9115109 | H3: =-Beta/alpha -> 180 | I3: =(-EXP(alpha*zeta)*Beta*(-1+EXP(alpha*Size*psi)-Size*alpha*psi))/((alpha^3)*(psi^2)) -> 95.446904 | J3: =Beta*Theta -> 14.4 | K3: =Beta*Theta -> 14.4 | L3: =kappa -> 90 | M3: =Gamma*Size -> 0 | N3: =Size*Beta*Phi -> 6.48 | O3: =-(EXP(alpha*a*psi)+EXP(alpha*b*psi)*(-1+Size*psi*alpha))*(Beta*Phi)/((alpha*psi)*(EXP(alpha*a*psi)-EXP(alpha*b*psi))) -> 3.0782425 | P3: =(EXP(alpha*(zeta-a*psi))*Beta*Phi*(-EXP(alpha*a*psi)*(-2+(-1)*Size*alpha*psi)+EXP(alpha*b*psi)*(-2+Size*alpha*psi)))/((alpha^3)*(psi^3)) -> 1.0892667 | Q3: =Tau*Beta -> 107.6011 | R3: =Tau*Beta -> 107.6011 | S3: =Tau -> 0.5977839 | T3: =Profit+Utility -> 1195.3544 | U3: =(2*ij*BRIJ)+2*jj*BRJJ -> 1025.1038 | V3: =2*(ij*BCCIJ)+(2*jj*BCCJJ)+BCS+jj*BCPTJJ+2*(ij*BCPTIJ)+BCPTII+BCk -> 258.54447 | W3: =ij*BUTIJ+BUTII -> 428.79501 | X3: =Revenue-Cost -> 766.55936 | Y3: =Size -> 2 | Z3: =Welfare/(Size) -> 597.67718 | AA3: =Profit/(Size) -> 383.27968 | AB3: =Utility/(Size) -> 214.3975 | AC3: 308.66096
A4: 0.62215872 | B4: 0 | C4: 5 | D4: 0 | E4: =Size-a -> 5 | F4: =(EXP(alpha*(Tau+OldTau+zeta-2*a*psi))*((EXP(alpha*a*psi)-EXP(alpha*b*psi))^2))/((EXP(alpha*a*psi)-EXP(alpha*(2*OldTau+b*psi)))*(alpha^2)*(psi^2)) -> 3.6793194 | G4: =(EXP(alpha*(zeta+(2*b-a)*psi))*(-1+EXP(alpha*(-1)*Size*psi))*(EXP(alpha*(2*(Tau+OldTau)+a*psi))-EXP(alpha*(2*(Tau+OldTau)+b*psi))))/(((EXP(alpha*a*psi)-EXP(alpha*(2*OldTau+b*psi)))^2)*(alpha^2)*(psi^2)) -> 1.7681301 | H4: =-Beta/alpha -> 180 | I4: =(-EXP(alpha*zeta)*Beta*(-1+EXP(alpha*Size*psi)-Size*alpha*psi))/((alpha^3)*(psi^2)) -> 519.96874 | J4: =Beta*Theta -> 14.4 | K4: =Beta*Theta -> 14.4 | L4: =kappa -> 90 | M4: =Gamma*Size -> 0 | N4: =Size*Beta*Phi -> 16.2 | O4: =-(EXP(alpha*a*psi)+EXP(alpha*b*psi)*(-1+Size*psi*alpha))*(Beta*Phi)/((alpha*psi)*(EXP(alpha*a*psi)-EXP(alpha*b*psi))) -> 7.0968668 | P4: =(EXP(alpha*(zeta-a*psi))*Beta*Phi*(-EXP(alpha*a*psi)*(-2+(-1)*Size*alpha*psi)+EXP(alpha*b*psi)*(-2+Size*alpha*psi)))/((alpha^3)*(psi^3)) -> 13.751693 | Q4: =Tau*Beta -> 111.98857 | R4: =Tau*Beta -> 111.98857 | S4: =Tau -> 0.62215872 | T4: =Profit+Utility -> 2060.8452 | U4: =(2*ij*BRIJ)+2*jj*BRJJ -> 1220.1041 | V4: =2*(ij*BCCIJ)+(2*jj*BCCJJ)+BCS+jj*BCPTJJ+2*(ij*BCPTIJ)+BCPTII+BCk -> 341.50522 | W4: =ij*BUTIJ+BUTII -> 1182.2462 | X4: =Revenue-Cost -> 878.59892 | Y4: =Size -> 5 | Z4: =Welfare/(Size) -> 412.16903 | AA4: =Profit/(Size) -> 175.71978 | AB4: =Utility/(Size) -> 236.44925 | AC4: 308.66096
A5: 0.65329456 | B5: 0 | C5: 10 | D5: 0 | E5: =Size-a -> 10 | F5: =(EXP(alpha*(Tau+OldTau+zeta-2*a*psi))*((EXP(alpha*a*psi)-EXP(alpha*b*psi))^2))/((EXP(alpha*a*psi)-EXP(alpha*(2*OldTau+b*psi)))*(alpha^2)*(psi^2)) -> 5.2512332 | G5: =(EXP(alpha*(zeta+(2*b-a)*psi))*(-1+EXP(alpha*(-1)*Size*psi))*(EXP(alpha*(2*(Tau+OldTau)+a*psi))-EXP(alpha*(2*(Tau+OldTau)+b*psi))))/(((EXP(alpha*a*psi)-EXP(alpha*(2*OldTau+b*psi)))^2)*(alpha^2)*(psi^2)) -> 0.78478212 | H5: =-Beta/alpha -> 180 | I5: =(-EXP(alpha*zeta)*Beta*(-1+EXP(alpha*Size*psi)-Size*alpha*psi))/((alpha^3)*(psi^2)) -> 1690.9246 | J5: =Beta*Theta -> 14.4 | K5: =Beta*Theta -> 14.4 | L5: =kappa -> 90 | M5: =Gamma*Size -> 0 | N5: =Size*Beta*Phi -> 32.4 | O5: =-(EXP(alpha*a*psi)+EXP(alpha*b*psi)*(-1+Size*psi*alpha))*(Beta*Phi)/((alpha*psi)*(EXP(alpha*a*psi)-EXP(alpha*b*psi))) -> 12.294172 | P5: =(EXP(alpha*(zeta-a*psi))*Beta*Phi*(-EXP(alpha*a*psi)*(-2+(-1)*Size*alpha*psi)+EXP(alpha*b*psi)*(-2+Size*alpha*psi)))/((alpha^3)*(psi^3)) -> 78.836376 | Q5: =Tau*Beta -> 117.59302 | R5: =Tau*Beta -> 117.59302 | S5: =Tau -> 0.65329456 | T5: =Profit+Utility -> 3558.5135 | U5: =(2*ij*BRIJ)+2*jj*BRJJ -> 1419.5866 | V5: =2*(ij*BCCIJ)+(2*jj*BCCJJ)+BCS+jj*BCPTJJ+2*(ij*BCPTIJ)+BCPTII+BCk -> 497.21969 | W5: =ij*BUTIJ+BUTII -> 2636.1466 | X5: =Revenue-Cost -> 922.36687 | Y5: =Size -> 10 | Z5: =Welfare/(Size) -> 355.85135 | AA5: =Profit/(Size) -> 92.236687 | AB5: =Utility/(Size) -> 263.61466 | AC5: 308.66096
A6: 0.68509426 | B6: 0 | C6: 20 | D6: 0 | E6: =Size-a -> 20 | F6: =(EXP(alpha*(Tau+OldTau+zeta-2*a*psi))*((EXP(alpha*a*psi)-EXP(alpha*b*psi))^2))/((EXP(alpha*a*psi)-EXP(alpha*(2*OldTau+b*psi)))*(alpha^2)*(psi^2)) -> 6.2219075 | G6: =(EXP(alpha*(zeta+(2*b-a)*psi))*(-1+EXP(alpha*(-1)*Size*psi))*(EXP(alpha*(2*(Tau+OldTau)+a*psi))-EXP(alpha*(2*(Tau+OldTau)+b*psi))))/(((EXP(alpha*a*psi)-EXP(alpha*(2*OldTau+b*psi)))^2)*(alpha^2)*(psi^2)) -> 0.16431852 | H6: =-Beta/alpha -> 180 | I6: =(-EXP(alpha*zeta)*Beta*(-1+EXP(alpha*Size*psi)-Size*alpha*psi))/((alpha^3)*(psi^2)) -> 4793.1004 | J6: =Beta*Theta -> 14.4 | K6: =Beta*Theta -> 14.4 | L6: =kappa -> 90 | M6: =Gamma*Size -> 0 | N6: =Size*Beta*Phi -> 64.8 | O6: =-(EXP(alpha*a*psi)+EXP(alpha*b*psi)*(-1+Size*psi*alpha))*(Beta*Phi)/((alpha*psi)*(EXP(alpha*a*psi)-EXP(alpha*b*psi))) -> 18.204759 | P6: =(EXP(alpha*(zeta-a*psi))*Beta*Phi*(-EXP(alpha*a*psi)*(-2+(-1)*Size*alpha*psi)+EXP(alpha*b*psi)*(-2+Size*alpha*psi)))/((alpha^3)*(psi^3)) -> 350.45235 | Q6: =Tau*Beta -> 123.31697 | R6: =Tau*Beta -> 123.31697 | S6: =Tau -> 0.68509426 | T6: =Profit+Utility -> 6626.5436 | U6: =(2*ij*BRIJ)+2*jj*BRJJ -> 1575.06 | V6: =2*(ij*BCCIJ)+(2*jj*BCCJJ)+BCS+jj*BCPTJJ+2*(ij*BCPTIJ)+BCPTII+BCk -> 861.56015 | W6: =ij*BUTIJ+BUTII -> 5913.0437 | X6: =Revenue-Cost -> 713.49989 | Y6: =Size -> 20 | Z6: =Welfare/(Size) -> 331.32718 | AA6: =Profit/(Size) -> 35.674995 | AB6: =Utility/(Size) -> 295.65219 | AC6: 308.66096
A7: 0.69968374 | B7: 0 | C7: 50 | D7: 0 | E7: =Size-a -> 50 | F7: =(EXP(alpha*(Tau+OldTau+zeta-2*a*psi))*((EXP(alpha*a*psi)-EXP(alpha*b*psi))^2))/((EXP(alpha*a*psi)-EXP(alpha*(2*OldTau+b*psi)))*(alpha^2)*(psi^2)) -> 6.4495025 | G7: =(EXP(alpha*(zeta+(2*b-a)*psi))*(-1+EXP(alpha*(-1)*Size*psi))*(EXP(alpha*(2*(Tau+OldTau)+a*psi))-EXP(alpha*(2*(Tau+OldTau)+b*psi))))/(((EXP(alpha*a*psi)-EXP(alpha*(2*OldTau+b*psi)))^2)*(alpha^2)*(psi^2)) -> 0.0017729198 | H7: =-Beta/alpha -> 180 | I7: =(-EXP(alpha*zeta)*Beta*(-1+EXP(alpha*Size*psi)-Size*alpha*psi))/((alpha^3)*(psi^2)) -> 15200.507 | J7: =Beta*Theta -> 14.4 | K7: =Beta*Theta -> 14.4 | L7: =kappa -> 90 | M7: =Gamma*Size -> 0 | N7: =Size*Beta*Phi -> 162 | O7: =-(EXP(alpha*a*psi)+EXP(alpha*b*psi)*(-1+Size*psi*alpha))*(Beta*Phi)/((alpha*psi)*(EXP(alpha*a*psi)-EXP(alpha*b*psi))) -> 21.510351 | P7: =(EXP(alpha*(zeta-a*psi))*Beta*Phi*(-EXP(alpha*a*psi)*(-2+(-1)*Size*alpha*psi)+EXP(alpha*b*psi)*(-2+Size*alpha*psi)))/((alpha^3)*(psi^3)) -> 1544.7792 | Q7: =Tau*Beta -> 125.94307 | R7: =Tau*Beta -> 125.94307 | S7: =Tau -> 0.69968374 | T7: =Profit+Utility -> 15888.079 | U7: =(2*ij*BRIJ)+2*jj*BRJJ -> 1624.9869 | V7: =2*(ij*BCCIJ)+(2*jj*BCCJJ)+BCS+jj*BCPTJJ+2*(ij*BCPTIJ)+BCPTII+BCk -> 2098.3252 | W7: =ij*BUTIJ+BUTII -> 16361.418 | X7: =Revenue-Cost -> -473.33834 | Y7: =Size -> 50 | Z7: =Welfare/(Size) -> 317.76159 | AA7: =Profit/(Size) -> -9.4667667 | AB7: =Utility/(Size) -> 327.22836 | AC7: 308.66096
A8: 0.70000022 | B8: 0 | C8: 100 | D8: 0 | E8: =Size-a -> 100 | F8: =(EXP(alpha*(Tau+OldTau+zeta-2*a*psi))*((EXP(alpha*a*psi)-EXP(alpha*b*psi))^2))/((EXP(alpha*a*psi)-EXP(alpha*(2*OldTau+b*psi)))*(alpha^2)*(psi^2)) -> 6.4510276 | G8: =(EXP(alpha*(zeta+(2*b-a)*psi))*(-1+EXP(alpha*(-1)*Size*psi))*(EXP(alpha*(2*(Tau+OldTau)+a*psi))-EXP(alpha*(2*(Tau+OldTau)+b*psi))))/(((EXP(alpha*a*psi)-EXP(alpha*(2*OldTau+b*psi)))^2)*(alpha^2)*(psi^2)) -> 9.7995373e-07 | H8: =-Beta/alpha -> 180 | I8: =(-EXP(alpha*zeta)*Beta*(-1+EXP(alpha*Size*psi)-Size*alpha*psi))/((alpha^3)*(psi^2)) -> 32736.769 | J8: =Beta*Theta -> 14.4 | K8: =Beta*Theta -> 14.4 | L8: =kappa -> 90 | M8: =Gamma*Size -> 0 | N8: =Size*Beta*Phi -> 324 | O8: =-(EXP(alpha*a*psi)+EXP(alpha*b*psi)*(-1+Size*psi*alpha))*(Beta*Phi)/((alpha*psi)*(EXP(alpha*a*psi)-EXP(alpha*b*psi))) -> 21.599901 | P8: =(EXP(alpha*(zeta-a*psi))*Beta*Phi*(-EXP(alpha*a*psi)*(-2+(-1)*Size*alpha*psi)+EXP(alpha*b*psi)*(-2+Size*alpha*psi)))/((alpha^3)*(psi^3)) -> 3647.8128 | Q8: =Tau*Beta -> 126.00004 | R8: =Tau*Beta -> 126.00004 | S8: =Tau -> 0.70000022 | T8: =Profit+Utility -> 31321.328 | U8: =(2*ij*BRIJ)+2*jj*BRJJ -> 1625.6597 | V8: =2*(ij*BCCIJ)+(2*jj*BCCJJ)+BCS+jj*BCPTJJ+2*(ij*BCPTIJ)+BCPTII+BCk -> 4202.2859 | W8: =ij*BUTIJ+BUTII -> 33897.954 | X8: =Revenue-Cost -> -2576.6262 | Y8: =Size -> 100 | Z8: =Welfare/(Size) -> 313.21328 | AA8: =Profit/(Size) -> -25.766262 | AB8: =Utility/(Size) -> 338.97954 | AC8: 308.66096
A9: 0.70000093 | B9: 0 | C9: 200 | D9: 0 | E9: =Size-a -> 200 | F9: =(EXP(alpha*(Tau+OldTau+zeta-2*a*psi))*((EXP(alpha*a*psi)-EXP(alpha*b*psi))^2))/((EXP(alpha*a*psi)-EXP(alpha*(2*OldTau+b*psi)))*(alpha^2)*(psi^2)) -> 6.451025 | G9: =(EXP(alpha*(zeta+(2*b-a)*psi))*(-1+EXP(alpha*(-1)*Size*psi))*(EXP(alpha*(2*(Tau+OldTau)+a*psi))-EXP(alpha*(2*(Tau+OldTau)+b*psi))))/(((EXP(alpha*a*psi)-EXP(alpha*(2*OldTau+b*psi)))^2)*(alpha^2)*(psi^2)) -> 2.997697e-13 | H9: =-Beta/alpha -> 180 | I9: =(-EXP(alpha*zeta)*Beta*(-1+EXP(alpha*Size*psi)-Size*alpha*psi))/((alpha^3)*(psi^2)) -> 67811.878 | J9: =Beta*Theta -> 14.4 | K9: =Beta*Theta -> 14.4 | L9: =kappa -> 90 | M9: =Gamma*Size -> 0 | N9: =Size*Beta*Phi -> 648 | O9: =-(EXP(alpha*a*psi)+EXP(alpha*b*psi)*(-1+Size*psi*alpha))*(Beta*Phi)/((alpha*psi)*(EXP(alpha*a*psi)-EXP(alpha*b*psi))) -> 21.6 | P9: =(EXP(alpha*(zeta-a*psi))*Beta*Phi*(-EXP(alpha*a*psi)*(-2+(-1)*Size*alpha*psi)+EXP(alpha*b*psi)*(-2+Size*alpha*psi)))/((alpha^3)*(psi^3)) -> 7856.8245 | Q9: =Tau*Beta -> 126.00017 | R9: =Tau*Beta -> 126.00017 | S9: =Tau -> 0.70000093 | T9: =Profit+Utility -> 62187.425 | U9: =(2*ij*BRIJ)+2*jj*BRJJ -> 1625.6605 | V9: =2*(ij*BCCIJ)+(2*jj*BCCJJ)+BCS+jj*BCPTJJ+2*(ij*BCPTIJ)+BCPTII+BCk -> 8411.2983 | W9: =ij*BUTIJ+BUTII -> 68973.063 | X9: =Revenue-Cost -> -6785.6378 | Y9: =Size -> 200 | Z9: =Welfare/(Size) -> 310.93712 | AA9: =Profit/(Size) -> -33.928189 | AB9: =Utility/(Size) -> 344.86531 | AC9: 308.66096
A10: 0.70065908 | B10: 0 | C10: 500 | D10: 0 | E10: =Size-a -> 500 | F10: =(EXP(alpha*(Tau+OldTau+zeta-2*a*psi))*((EXP(alpha*a*psi)-EXP(alpha*b*psi))^2))/((EXP(alpha*a*psi)-EXP(alpha*(2*OldTau+b*psi)))*(alpha^2)*(psi^2)) -> 6.4467807 | G10: =(EXP(alpha*(zeta+(2*b-a)*psi))*(-1+EXP(alpha*(-1)*Size*psi))*(EXP(alpha*(2*(Tau+OldTau)+a*psi))-EXP(alpha*(2*(Tau+OldTau)+b*psi))))/(((EXP(alpha*a*psi)-EXP(alpha*(2*OldTau+b*psi)))^2)*(alpha^2)*(psi^2)) -> 8.5696755e-33 | H10: =-Beta/alpha -> 180 | I10: =(-EXP(alpha*zeta)*Beta*(-1+EXP(alpha*Size*psi)-Size*alpha*psi))/((alpha^3)*(psi^2)) -> 173037.21 | J10: =Beta*Theta -> 14.4 | K10: =Beta*Theta -> 14.4 | L10: =kappa -> 90 | M10: =Gamma*Size -> 0 | N10: =Size*Beta*Phi -> 1620 | O10: =-(EXP(alpha*a*psi)+EXP(alpha*b*psi)*(-1+Size*psi*alpha))*(Beta*Phi)/((alpha*psi)*(EXP(alpha*a*psi)-EXP(alpha*b*psi))) -> 21.6 | P10: =(EXP(alpha*(zeta-a*psi))*Beta*Phi*(-EXP(alpha*a*psi)*(-2+(-1)*Size*alpha*psi)+EXP(alpha*b*psi)*(-2+Size*alpha*psi)))/((alpha^3)*(psi^3)) -> 20483.864 | Q10: =Tau*Beta -> 126.11864 | R10: =Tau*Beta -> 126.11864 | S10: =Tau -> 0.70065908 | T10: =Profit+Utility -> 154785.71 | U10: =(2*ij*BRIJ)+2*jj*BRJJ -> 1626.1184 | V10: =2*(ij*BCCIJ)+(2*jj*BCCJJ)+BCS+jj*BCPTJJ+2*(ij*BCPTIJ)+BCPTII+BCk -> 21038.032 | W10: =ij*BUTIJ+BUTII -> 174197.63 | X10: =Revenue-Cost -> -19411.914 | Y10: =Size -> 500 | Z10: =Welfare/(Size) -> 309.57143 | AA10: =Profit/(Size) -> -38.823827 | AB10: =Utility/(Size) -> 348.39525 | AC10: 308.66096
A11: 0.70065908 | B11: 0 | C11: 1000 | D11: 0 | E11: =Size-a -> 1000 | F11: =(EXP(alpha*(Tau+OldTau+zeta-2*a*psi))*((EXP(alpha*a*psi)-EXP(alpha*b*psi))^2))/((EXP(alpha*a*psi)-EXP(alpha*(2*OldTau+b*psi)))*(alpha^2)*(psi^2)) -> 6.4467807 | G11: =(EXP(alpha*(zeta+(2*b-a)*psi))*(-1+EXP(alpha*(-1)*Size*psi))*(EXP(alpha*(2*(Tau+OldTau)+a*psi))-EXP(alpha*(2*(Tau+OldTau)+b*psi))))/(((EXP(alpha*a*psi)-EXP(alpha*(2*OldTau+b*psi)))^2)*(alpha^2)*(psi^2)) -> 2.295505e-65 | H11: =-Beta/alpha -> 180 | I11: =(-EXP(alpha*zeta)*Beta*(-1+EXP(alpha*Size*psi)-Size*alpha*psi))/((alpha^3)*(psi^2)) -> 348412.75 | J11: =Beta*Theta -> 14.4 | K11: =Beta*Theta -> 14.4 | L11: =kappa -> 90 | M11: =Gamma*Size -> 0 | N11: =Size*Beta*Phi -> 3240 | O11: =-(EXP(alpha*a*psi)+EXP(alpha*b*psi)*(-1+Size*psi*alpha))*(Beta*Phi)/((alpha*psi)*(EXP(alpha*a*psi)-EXP(alpha*b*psi))) -> 21.6 | P11: =(EXP(alpha*(zeta-a*psi))*Beta*Phi*(-EXP(alpha*a*psi)*(-2+(-1)*Size*alpha*psi)+EXP(alpha*b*psi)*(-2+Size*alpha*psi)))/((alpha^3)*(psi^3)) -> 41528.929 | Q11: =Tau*Beta -> 126.11864 | R11: =Tau*Beta -> 126.11864 | S11: =Tau -> 0.70065908 | T11: =Profit+Utility -> 309116.19 | U11: =(2*ij*BRIJ)+2*jj*BRJJ -> 1626.1184 | V11: =2*(ij*BCCIJ)+(2*jj*BCCJJ)+BCS+jj*BCPTJJ+2*(ij*BCPTIJ)+BCPTII+BCk -> 42083.098 | W11: =ij*BUTIJ+BUTII -> 349573.17 | X11: =Revenue-Cost -> -40456.979 | Y11: =Size -> 1000 | Z11: =Welfare/(Size) -> 309.11619 | AA11: =Profit/(Size) -> -40.456979 | AB11: =Utility/(Size) -> 349.57317 | AC11: 308.66096

Sheet W-Toll(All-Tax) (theta)
A1: Theta | B1: Ccv' | C1: Theta-necessary | D1: Tau | E1: OldTau | F1: Size | G1: a | H1: b | I1: ij | J1: jj | K1: BUTIJ | L1: BUTII | M1: BCCIJ | N1: BCCJJ | O1: BCk | P1: BCS | Q1: BCPTJJ | R1: BCPTIJ | S1: BCPTII | T1: BRIJ | U1: BRJJ | V1: Toll | W1: Welfare | X1: Revenue | Y1: Cost | Z1: Utility | AA1: Profit | AB1: Size2 | AC1: W/Size | AD1: ∏/Size | AE1: U/Size | AF1: W-Tax(All-Tax)
A2: 0.08 | B2: =(I2+J2)*Beta*2 -> 1600.8953 | C2: =(W2+B2*Theta-'W-Tax(All-Tax)'!$T$2)/B2 -> 0.4594454 | D2: 0.58897197 | E2: 0 | F2: 1 | G2: 0 | H2: =Size-a -> 1 | I2: =(EXP(alpha*(Tau+OldTau+zeta-2*a*psi))*((EXP(alpha*a*psi)-EXP(alpha*b*psi))^2))/((EXP(alpha*a*psi)-EXP(alpha*(2*OldTau+b*psi)))*(alpha^2)*(psi^2)) -> 1.0040937 | J2: =(EXP(alpha*(zeta+(2*b-a)*psi))*(-1+EXP(alpha*(-1)*Size*psi))*(EXP(alpha*(2*(Tau+OldTau)+a*psi))-EXP(alpha*(2*(Tau+OldTau)+b*psi))))/(((EXP(alpha*a*psi)-EXP(alpha*(2*OldTau+b*psi)))^2)*(alpha^2)*(psi^2)) -> 3.4428377 | K2: =-Beta/alpha -> 180 | L2: =(-EXP(alpha*zeta)*Beta*(-1+EXP(alpha*Size*psi)-Size*alpha*psi))/((alpha^3)*(psi^2)) -> 25.038896 | M2: =Beta*Theta -> 14.4 | N2: =Beta*Theta -> 14.4 | O2: =kappa -> 90 | P2: =Gamma*Size -> 0 | Q2: =Size*Beta*Phi -> 3.24 | R2: =-(EXP(alpha*a*psi)+EXP(alpha*b*psi)*(-1+Size*psi*alpha))*(Beta*Phi)/((alpha*psi)*(EXP(alpha*a*psi)-EXP(alpha*b*psi))) -> 1.5795152 | S2: =(EXP(alpha*(zeta-a*psi))*Beta*Phi*(-EXP(alpha*a*psi)*(-2+(-1)*Size*alpha*psi)+EXP(alpha*b*psi)*(-2+Size*alpha*psi)))/((alpha^3)*(psi^3)) -> 0.14651555 | T2: =Tau*Beta -> 106.01495 | U2: =Tau*Beta -> 106.01495 | V2: =Tau -> 0.58897197 | W2: =Profit+Utility -> 916.11332 | X2: =(2*ij*BRIJ)+2*jj*BRJJ -> 942.88245 | Y2: =2*(ij*BCCIJ)+(2*jj*BCCJJ)+BCS+jj*BCPTJJ+2*(ij*BCPTIJ)+BCPTII+BCk -> 232.5449 | Z2: =ij*BUTIJ+BUTII -> 205.77576 | AA2: =Revenue-Cost -> 710.33755 | AB2: =Size -> 1 | AC2: =Welfare/(Size) -> 916.11332 | AD2: =Profit/(Size) -> 710.33755 | AE2: =Utility/(Size) -> 205.77576 | AF2: 308.66096
A3: =C2 -> 0.4594454 | B3: =(I3+J3)*Beta*2 -> 827.6302 | C3: =(W3+B3*Theta-'W-Tax(All-Tax)'!$T$2)/B3 -> 0.65728556 | D3: 0.96840601 | E3: 0 | F3: 1 | G3: 0 | H3: =Size-a -> 1 | I3: =(EXP(alpha*(Tau+OldTau+zeta-2*a*psi))*((EXP(alpha*a*psi)-EXP(alpha*b*psi))^2))/((EXP(alpha*a*psi)-EXP(alpha*(2*OldTau+b*psi)))*(alpha^2)*(psi^2)) -> 0.68704966 | J3: =(EXP(alpha*(zeta+(2*b-a)*psi))*(-1+EXP(alpha*(-1)*Size*psi))*(EXP(alpha*(2*(Tau+OldTau)+a*psi))-EXP(alpha*(2*(Tau+OldTau)+b*psi))))/(((EXP(alpha*a*psi)-EXP(alpha*(2*OldTau+b*psi)))^2)*(alpha^2)*(psi^2)) -> 1.6119231 | K3: =-Beta/alpha -> 180 | L3: =(-EXP(alpha*zeta)*Beta*(-1+EXP(alpha*Size*psi)-Size*alpha*psi))/((alpha^3)*(psi^2)) -> 25.038896 | M3: =Beta*Theta -> 82.700172 | N3: =Beta*Theta -> 82.700172 | O3: =kappa -> 90 | P3: =Gamma*Size -> 0 | Q3: =Size*Beta*Phi -> 3.24 | R3: =-(EXP(alpha*a*psi)+EXP(alpha*b*psi)*(-1+Size*psi*alpha))*(Beta*Phi)/((alpha*psi)*(EXP(alpha*a*psi)-EXP(alpha*b*psi))) -> 1.5795152 | S3: =(EXP(alpha*(zeta-a*psi))*Beta*Phi*(-EXP(alpha*a*psi)*(-2+(-1)*Size*alpha*psi)+EXP(alpha*b*psi)*(-2+Size*alpha*psi)))/((alpha^3)*(psi^3)) -> 0.14651555 | T3: =Tau*Beta -> 174.31308 | U3: =Tau*Beta -> 174.31308 | V3: =Tau -> 0.96840601 | W3: =Profit+Utility -> 472.39945 | X3: =(2*ij*BRIJ)+2*jj*BRJJ -> 801.48206 | Y3: =2*(ij*BCCIJ)+(2*jj*BCCJJ)+BCS+jj*BCPTJJ+2*(ij*BCPTIJ)+BCPTII+BCk -> 477.79045 | Z3: =ij*BUTIJ+BUTII -> 148.70784 | AA3: =Revenue-Cost -> 323.69161 | AB3: =Size -> 1 | AC3: =Welfare/(Size) -> 472.39945 | AD3: =Profit/(Size) -> 323.69161 | AE3: =Utility/(Size) -> 148.70784 | AF3: 308.66096
A4: =C3 -> 0.65728556 | B4: =(I4+J4)*Beta*2 -> 593.61334 | C4: =(W4+B4*Theta-'W-Tax(All-Tax)'!$T$2)/B4 -> 0.69860437 | D4: 1.1662392 | E4: 0 | F4: 1 | G4: 0 | H4: =Size-a -> 1 | I4: =(EXP(alpha*(Tau+OldTau+zeta-2*a*psi))*((EXP(alpha*a*psi)-EXP(alpha*b*psi))^2))/((EXP(alpha*a*psi)-EXP(alpha*(2*OldTau+b*psi)))*(alpha^2)*(psi^2)) -> 0.56372887 | J4: =(EXP(alpha*(zeta+(2*b-a)*psi))*(-1+EXP(alpha*(-1)*Size*psi))*(EXP(alpha*(2*(Tau+OldTau)+a*psi))-EXP(alpha*(2*(Tau+OldTau)+b*psi))))/(((EXP(alpha*a*psi)-EXP(alpha*(2*OldTau+b*psi)))^2)*(alpha^2)*(psi^2)) -> 1.0851971 | K4: =-Beta/alpha -> 180 | L4: =(-EXP(alpha*zeta)*Beta*(-1+EXP(alpha*Size*psi)-Size*alpha*psi))/((alpha^3)*(psi^2)) -> 25.038896 | M4: =Beta*Theta -> 118.3114 | N4: =Beta*Theta -> 118.3114 | O4: =kappa -> 90 | P4: =Gamma*Size -> 0 | Q4: =Size*Beta*Phi -> 3.24 | R4: =-(EXP(alpha*a*psi)+EXP(alpha*b*psi)*(-1+Size*psi*alpha))*(Beta*Phi)/((alpha*psi)*(EXP(alpha*a*psi)-EXP(alpha*b*psi))) -> 1.5795152 | S4: =(EXP(alpha*(zeta-a*psi))*Beta*Phi*(-EXP(alpha*a*psi)*(-2+(-1)*Size*alpha*psi)+EXP(alpha*b*psi)*(-2+Size*alpha*psi)))/((alpha^3)*(psi^3)) -> 0.14651555 | T4: =Tau*Beta -> 209.92305 | U4: =Tau*Beta -> 209.92305 | V4: =Tau -> 1.1662392 | W4: =Profit+Utility -> 333.18836 | X4: =(2*ij*BRIJ)+2*jj*BRJJ -> 692.29514 | Y4: =2*(ij*BCCIJ)+(2*jj*BCCJJ)+BCS+jj*BCPTJJ+2*(ij*BCPTIJ)+BCPTII+BCk -> 485.61686 | Z4: =ij*BUTIJ+BUTII -> 126.51009 | AA4: =Revenue-Cost -> 206.67827 | AB4: =Size -> 1 | AC4: =Welfare/(Size) -> 333.18836 | AD4: =Profit/(Size) -> 206.67827 | AE4: =Utility/(Size) -> 126.51009 | AF4: 308.66096
A5: =C4 -> 0.69860437 | B5: =(I5+J5)*Beta*2 -> 554.41407 | C5: =(W5+B5*Theta-'W-Tax(All-Tax)'!$T$2)/B5 -> 0.70008308 | D5: 1.2075565 | E5: 0 | F5: 1 | G5: 0 | H5: =Size-a -> 1 | I5: =(EXP(alpha*(Tau+OldTau+zeta-2*a*psi))*((EXP(alpha*a*psi)-EXP(alpha*b*psi))^2))/((EXP(alpha*a*psi)-EXP(alpha*(2*OldTau+b*psi)))*(alpha^2)*(psi^2)) -> 0.54091172 | J5: =(EXP(alpha*(zeta+(2*b-a)*psi))*(-1+EXP(alpha*(-1)*Size*psi))*(EXP(alpha*(2*(Tau+OldTau)+a*psi))-EXP(alpha*(2*(Tau+OldTau)+b*psi))))/(((EXP(alpha*a*psi)-EXP(alpha*(2*OldTau+b*psi)))^2)*(alpha^2)*(psi^2)) -> 0.99912736 | K5: =-Beta/alpha -> 180 | L5: =(-EXP(alpha*zeta)*Beta*(-1+EXP(alpha*Size*psi)-Size*alpha*psi))/((alpha^3)*(psi^2)) -> 25.038896 | M5: =Beta*Theta -> 125.74879 | N5: =Beta*Theta -> 125.74879 | O5: =kappa -> 90 | P5: =Gamma*Size -> 0 | Q5: =Size*Beta*Phi -> 3.24 | R5: =-(EXP(alpha*a*psi)+EXP(alpha*b*psi)*(-1+Size*psi*alpha))*(Beta*Phi)/((alpha*psi)*(EXP(alpha*a*psi)-EXP(alpha*b*psi))) -> 1.5795152 | S5: =(EXP(alpha*(zeta-a*psi))*Beta*Phi*(-EXP(alpha*a*psi)*(-2+(-1)*Size*alpha*psi)+EXP(alpha*b*psi)*(-2+Size*alpha*psi)))/((alpha^3)*(psi^3)) -> 0.14651555 | T5: =Tau*Beta -> 217.36017 | U5: =Tau*Beta -> 217.36017 | V5: =Tau -> 1.2075565 | W5: =Profit+Utility -> 309.48078 | X5: =(2*ij*BRIJ)+2*jj*BRJJ -> 669.48631 | Y5: =2*(ij*BCCIJ)+(2*jj*BCCJJ)+BCS+jj*BCPTJJ+2*(ij*BCPTIJ)+BCPTII+BCk -> 482.40854 | Z5: =ij*BUTIJ+BUTII -> 122.40301 | AA5: =Revenue-Cost -> 187.07777 | AB5: =Size -> 1 | AC5: =Welfare/(Size) -> 309.48078 | AD5: =Profit/(Size) -> 187.07777 | AE5: =Utility/(Size) -> 122.40301 | AF5: 308.66096
A6: =C5 -> 0.70008308 | B6: =(I6+J6)*Beta*2 -> 553.06425 | C6: =(W6+B6*Theta-'W-Tax(All-Tax)'!$T$2)/B6 -> 0.70008489 | D6: 1.2090351 | E6: 0 | F6: 1 | G6: 0 | H6: =Size-a -> 1 | I6: =(EXP(alpha*(Tau+OldTau+zeta-2*a*psi))*((EXP(alpha*a*psi)-EXP(alpha*b*psi))^2))/((EXP(alpha*a*psi)-EXP(alpha*(2*OldTau+b*psi)))*(alpha^2)*(psi^2)) -> 0.54011251 | J6: =(EXP(alpha*(zeta+(2*b-a)*psi))*(-1+EXP(alpha*(-1)*Size*psi))*(EXP(alpha*(2*(Tau+OldTau)+a*psi))-EXP(alpha*(2*(Tau+OldTau)+b*psi))))/(((EXP(alpha*a*psi)-EXP(alpha*(2*OldTau+b*psi)))^2)*(alpha^2)*(psi^2)) -> 0.99617707 | K6: =-Beta/alpha -> 180 | L6: =(-EXP(alpha*zeta)*Beta*(-1+EXP(alpha*Size*psi)-Size*alpha*psi))/((alpha^3)*(psi^2)) -> 25.038896 | M6: =Beta*Theta -> 126.01495 | N6: =Beta*Theta -> 126.01495 | O6: =kappa -> 90 | P6: =Gamma*Size -> 0 | Q6: =Size*Beta*Phi -> 3.24 | R6: =-(EXP(alpha*a*psi)+EXP(alpha*b*psi)*(-1+Size*psi*alpha))*(Beta*Phi)/((alpha*psi)*(EXP(alpha*a*psi)-EXP(alpha*b*psi))) -> 1.5795152 | S6: =(EXP(alpha*(zeta-a*psi))*Beta*Phi*(-EXP(alpha*a*psi)*(-2+(-1)*Size*alpha*psi)+EXP(alpha*b*psi)*(-2+Size*alpha*psi)))/((alpha^3)*(psi^3)) -> 0.14651555 | T6: =Tau*Beta -> 217.62632 | U6: =Tau*Beta -> 217.62632 | V6: =Tau -> 1.2090351 | W6: =Profit+Utility -> 308.66196 | X6: =(2*ij*BRIJ)+2*jj*BRJJ -> 668.6741 | Y6: =2*(ij*BCCIJ)+(2*jj*BCCJJ)+BCS+jj*BCPTJJ+2*(ij*BCPTIJ)+BCPTII+BCk -> 482.27129 | Z6: =ij*BUTIJ+BUTII -> 122.25915 | AA6: =Revenue-Cost -> 186.40281 | AB6: =Size -> 1 | AC6: =Welfare/(Size) -> 308.66196 | AD6: =Profit/(Size) -> 186.40281 | AE6: =Utility/(Size) -> 122.25915 | AF6: 308.66096
A7: =C6 -> 0.70008489 | B7: =(I7+J7)*Beta*2 -> 553.0626 | C7: =(W7+B7*Theta-'W-Tax(All-Tax)'!$T$2)/B7 -> 0.70008489 | D7: 1.2090369 | E7: 0 | F7: 1 | G7: 0 | H7: =Size-a -> 1 | I7: =(EXP(alpha*(Tau+OldTau+zeta-2*a*psi))*((EXP(alpha*a*psi)-EXP(alpha*b*psi))^2))/((EXP(alpha*a*psi)-EXP(alpha*(2*OldTau+b*psi)))*(alpha^2)*(psi^2)) -> 0.54011154 | J7: =(EXP(alpha*(zeta+(2*b-a)*psi))*(-1+EXP(alpha*(-1)*Size*psi))*(EXP(alpha*(2*(Tau+OldTau)+a*psi))-EXP(alpha*(2*(Tau+OldTau)+b*psi))))/(((EXP(alpha*a*psi)-EXP(alpha*(2*OldTau+b*psi)))^2)*(alpha^2)*(psi^2)) -> 0.99617347 | K7: =-Beta/alpha -> 180 | L7: =(-EXP(alpha*zeta)*Beta*(-1+EXP(alpha*Size*psi)-Size*alpha*psi))/((alpha^3)*(psi^2)) -> 25.038896 | M7: =Beta*Theta -> 126.01528 | N7: =Beta*Theta -> 126.01528 | O7: =kappa -> 90 | P7: =Gamma*Size -> 0 | Q7: =Size*Beta*Phi -> 3.24 | R7: =-(EXP(alpha*a*psi)+EXP(alpha*b*psi)*(-1+Size*psi*alpha))*(Beta*Phi)/((alpha*psi)*(EXP(alpha*a*psi)-EXP(alpha*b*psi))) -> 1.5795152 | S7: =(EXP(alpha*(zeta-a*psi))*Beta*Phi*(-EXP(alpha*a*psi)*(-2+(-1)*Size*alpha*psi)+EXP(alpha*b*psi)*(-2+Size*alpha*psi)))/((alpha^3)*(psi^3)) -> 0.14651555 | T7: =Tau*Beta -> 217.62665 | U7: =Tau*Beta -> 217.62665 | V7: =Tau -> 1.2090369 | W7: =Profit+Utility -> 308.66096 | X7: =(2*ij*BRIJ)+2*jj*BRJJ -> 668.67311 | Y7: =2*(ij*BCCIJ)+(2*jj*BCCJJ)+BCS+jj*BCPTJJ+2*(ij*BCPTIJ)+BCPTII+BCk -> 482.27112 | Z7: =ij*BUTIJ+BUTII -> 122.25897 | AA7: =Revenue-Cost -> 186.40199 | AB7: =Size -> 1 | AC7: =Welfare/(Size) -> 308.66096 | AD7: =Profit/(Size) -> 186.40199 | AE7: =Utility/(Size) -> 122.25897 | AF7: 308.66096
A9: 0.08 | B9: =(I9+J9)*Beta*2 -> 2172.9655 | C9: =(W9+B9*Theta-'W-Tax(All-Tax)'!$T$5)/B9 -> 0.29717043 | D9: 0.65329456 | E9: 0 | F9: 10 | G9: 0 | H9: =Size-a -> 10 | I9: =(EXP(alpha*(Tau+OldTau+zeta-2*a*psi))*((EXP(alpha*a*psi)-EXP(alpha*b*psi))^2))/((EXP(alpha*a*psi)-EXP(alpha*(2*OldTau+b*psi)))*(alpha^2)*(psi^2)) -> 5.2512332 | J9: =(EXP(alpha*(zeta+(2*b-a)*psi))*(-1+EXP(alpha*(-1)*Size*psi))*(EXP(alpha*(2*(Tau+OldTau)+a*psi))-EXP(alpha*(2*(Tau+OldTau)+b*psi))))/(((EXP(alpha*a*psi)-EXP(alpha*(2*OldTau+b*psi)))^2)*(alpha^2)*(psi^2)) -> 0.78478212 | K9: =-Beta/alpha -> 180 | L9: =(-EXP(alpha*zeta)*Beta*(-1+EXP(alpha*Size*psi)-Size*alpha*psi))/((alpha^3)*(psi^2)) -> 1690.9246 | M9: =Beta*Theta -> 14.4 | N9: =Beta*Theta -> 14.4 | O9: =kappa -> 90 | P9: =Gamma*Size -> 0 | Q9: =Size*Beta*Phi -> 32.4 | R9: =-(EXP(alpha*a*psi)+EXP(alpha*b*psi)*(-1+Size*psi*alpha))*(Beta*Phi)/((alpha*psi)*(EXP(alpha*a*psi)-EXP(alpha*b*psi))) -> 12.294172 | S9: =(EXP(alpha*(zeta-a*psi))*Beta*Phi*(-EXP(alpha*a*psi)*(-2+(-1)*Size*alpha*psi)+EXP(alpha*b*psi)*(-2+Size*alpha*psi)))/((alpha^3)*(psi^3)) -> 78.836376 | T9: =Tau*Beta -> 117.59302 | U9: =Tau*Beta -> 117.59302 | V9: =Tau -> 0.65329456 | W9: =Profit+Utility -> 3558.5135 | X9: =(2*ij*BRIJ)+2*jj*BRJJ -> 1419.5866 | Y9: =2*(ij*BCCIJ)+(2*jj*BCCJJ)+BCS+jj*BCPTJJ+2*(ij*BCPTIJ)+BCPTII+BCk -> 497.21969 | Z9: =ij*BUTIJ+BUTII -> 2636.1466 | AA9: =Revenue-Cost -> 922.36687 | AB9: =Size -> 10 | AC9: =Welfare/(Size) -> 355.85135 | AD9: =Profit/(Size) -> 92.236687 | AE9: =Utility/(Size) -> 263.61466 | AF9: 308.66096
A10: =C9 -> 0.29717043 | B10: =(I10+J10)*Beta*2 -> 1705.8818 | C10: =(W10+B10*Theta-'W-Tax(All-Tax)'!$T$5)/B10 -> 0.32819765 | D10: 0.86968159 | E10: 0 | F10: 10 | G10: 0 | H10: =Size-a -> 10 | I10: =(EXP(alpha*(Tau+OldTau+zeta-2*a*psi))*((EXP(alpha*a*psi)-EXP(alpha*b*psi))^2))/((EXP(alpha*a*psi)-EXP(alpha*(2*OldTau+b*psi)))*(alpha^2)*(psi^2)) -> 4.2294667 | J10: =(EXP(alpha*(zeta+(2*b-a)*psi))*(-1+EXP(alpha*(-1)*Size*psi))*(EXP(alpha*(2*(Tau+OldTau)+a*psi))-EXP(alpha*(2*(Tau+OldTau)+b*psi))))/(((EXP(alpha*a*psi)-EXP(alpha*(2*OldTau+b*psi)))^2)*(alpha^2)*(psi^2)) -> 0.50909369 | K10: =-Beta/alpha -> 180 | L10: =(-EXP(alpha*zeta)*Beta*(-1+EXP(alpha*Size*psi)-Size*alpha*psi))/((alpha^3)*(psi^2)) -> 1690.9246 | M10: =Beta*Theta -> 53.490678 | N10: =Beta*Theta -> 53.490678 | O10: =kappa -> 90 | P10: =Gamma*Size -> 0 | Q10: =Size*Beta*Phi -> 32.4 | R10: =-(EXP(alpha*a*psi)+EXP(alpha*b*psi)*(-1+Size*psi*alpha))*(Beta*Phi)/((alpha*psi)*(EXP(alpha*a*psi)-EXP(alpha*b*psi))) -> 12.294172 | S10: =(EXP(alpha*(zeta-a*psi))*Beta*Phi*(-EXP(alpha*a*psi)*(-2+(-1)*Size*alpha*psi)+EXP(alpha*b*psi)*(-2+Size*alpha*psi)))/((alpha^3)*(psi^3)) -> 78.836376 | T10: =Tau*Beta -> 156.54269 | U10: =Tau*Beta -> 156.54269 | V10: =Tau -> 0.86968159 | W10: =Profit+Utility -> 3139.5384 | X10: =(2*ij*BRIJ)+2*jj*BRJJ -> 1483.574 | Y10: =2*(ij*BCCIJ)+(2*jj*BCCJJ)+BCS+jj*BCPTJJ+2*(ij*BCPTIJ)+BCPTII+BCk -> 796.26421 | Z10: =ij*BUTIJ+BUTII -> 2452.2286 | AA10: =Revenue-Cost -> 687.30975 | AB10: =Size -> 10 | AC10: =Welfare/(Size) -> 313.95384 | AD10: =Profit/(Size) -> 68.730975 | AE10: =Utility/(Size) -> 245.22286 | AF10: 308.66096
A11: =C10 -> 0.32819765 | B11: =(I11+J11)*Beta*2 -> 1648.5268 | C11: =(W11+B11*Theta-'W-Tax(All-Tax)'!$T$5)/B11 -> 0.32874071 | D11: 0.90060487 | E11: 0 | F11: 10 | G11: 0 | H11: =Size-a -> 10 | I11: =(EXP(alpha*(Tau+OldTau+zeta-2*a*psi))*((EXP(alpha*a*psi)-EXP(alpha*b*psi))^2))/((EXP(alpha*a*psi)-EXP(alpha*(2*OldTau+b*psi)))*(alpha^2)*(psi^2)) -> 4.1006793 | J11: =(EXP(alpha*(zeta+(2*b-a)*psi))*(-1+EXP(alpha*(-1)*Size*psi))*(EXP(alpha*(2*(Tau+OldTau)+a*psi))-EXP(alpha*(2*(Tau+OldTau)+b*psi))))/(((EXP(alpha*a*psi)-EXP(alpha*(2*OldTau+b*psi)))^2)*(alpha^2)*(psi^2)) -> 0.47856187 | K11: =-Beta/alpha -> 180 | L11: =(-EXP(alpha*zeta)*Beta*(-1+EXP(alpha*Size*psi)-Size*alpha*psi))/((alpha^3)*(psi^2)) -> 1690.9246 | M11: =Beta*Theta -> 59.075577 | N11: =Beta*Theta -> 59.075577 | O11: =kappa -> 90 | P11: =Gamma*Size -> 0 | Q11: =Size*Beta*Phi -> 32.4 | R11: =-(EXP(alpha*a*psi)+EXP(alpha*b*psi)*(-1+Size*psi*alpha))*(Beta*Phi)/((alpha*psi)*(EXP(alpha*a*psi)-EXP(alpha*b*psi))) -> 12.294172 | S11: =(EXP(alpha*(zeta-a*psi))*Beta*Phi*(-EXP(alpha*a*psi)*(-2+(-1)*Size*alpha*psi)+EXP(alpha*b*psi)*(-2+Size*alpha*psi)))/((alpha^3)*(psi^3)) -> 78.836376 | T11: =Tau*Beta -> 162.10888 | U11: =Tau*Beta -> 162.10888 | V11: =Tau -> 0.90060487 | W11: =Profit+Utility -> 3087.5049 | X11: =(2*ij*BRIJ)+2*jj*BRJJ -> 1484.6713 | Y11: =2*(ij*BCCIJ)+(2*jj*BCCJJ)+BCS+jj*BCPTJJ+2*(ij*BCPTIJ)+BCPTII+BCk -> 826.21332 | Z11: =ij*BUTIJ+BUTII -> 2429.0469 | AA11: =Revenue-Cost -> 658.45796 | AB11: =Size -> 10 | AC11: =Welfare/(Size) -> 308.75049 | AD11: =Profit/(Size) -> 65.845796 | AE11: =Utility/(Size) -> 242.90469 | AF11: 308.66096
A12: =C11 -> 0.32874071 | B12: =(I12+J12)*Beta*2 -> 1647.5416 | C12: =(W12+B12*Theta-'W-Tax(All-Tax)'!$T$5)/B12 -> 0.32874087 | D12: 0.90114613 | E12: 0 | F12: 10 | G12: 0 | H12: =Size-a -> 10 | I12: =(EXP(alpha*(Tau+OldTau+zeta-2*a*psi))*((EXP(alpha*a*psi)-EXP(alpha*b*psi))^2))/((EXP(alpha*a*psi)-EXP(alpha*(2*OldTau+b*psi)))*(alpha^2)*(psi^2)) -> 4.0984604 | J12: =(EXP(alpha*(zeta+(2*b-a)*psi))*(-1+EXP(alpha*(-1)*Size*psi))*(EXP(alpha*(2*(Tau+OldTau)+a*psi))-EXP(alpha*(2*(Tau+OldTau)+b*psi))))/(((EXP(alpha*a*psi)-EXP(alpha*(2*OldTau+b*psi)))^2)*(alpha^2)*(psi^2)) -> 0.47804411 | K12: =-Beta/alpha -> 180 | L12: =(-EXP(alpha*zeta)*Beta*(-1+EXP(alpha*Size*psi)-Size*alpha*psi))/((alpha^3)*(psi^2)) -> 1690.9246 | M12: =Beta*Theta -> 59.173327 | N12: =Beta*Theta -> 59.173327 | O12: =kappa -> 90 | P12: =Gamma*Size -> 0 | Q12: =Size*Beta*Phi -> 32.4 | R12: =-(EXP(alpha*a*psi)+EXP(alpha*b*psi)*(-1+Size*psi*alpha))*(Beta*Phi)/((alpha*psi)*(EXP(alpha*a*psi)-EXP(alpha*b*psi))) -> 12.294172 | S12: =(EXP(alpha*(zeta-a*psi))*Beta*Phi*(-EXP(alpha*a*psi)*(-2+(-1)*Size*alpha*psi)+EXP(alpha*b*psi)*(-2+Size*alpha*psi)))/((alpha^3)*(psi^3)) -> 78.836376 | T12: =Tau*Beta -> 162.2063 | U12: =Tau*Beta -> 162.2063 | V12: =Tau -> 0.90114613 | W12: =Profit+Utility -> 3086.6099 | X12: =(2*ij*BRIJ)+2*jj*BRJJ -> 1484.6757 | Y12: =2*(ij*BCCIJ)+(2*jj*BCCJJ)+BCS+jj*BCPTJJ+2*(ij*BCPTIJ)+BCPTII+BCk -> 826.71335 | Z12: =ij*BUTIJ+BUTII -> 2428.6475 | AA12: =Revenue-Cost -> 657.96239 | AB12: =Size -> 10 | AC12: =Welfare/(Size) -> 308.66099 | AD12: =Profit/(Size) -> 65.796239 | AE12: =Utility/(Size) -> 242.86475 | AF12: 308.66096
A14: 0.08 | B14: =(I14+J14)*Beta*2 -> 2322.0114 | C14: =(W14+B14*Theta-'W-Tax(All-Tax)'!$T$8)/B14 -> 0.27605072 | D14: 0.70015477 | E14: 0 | F14: 100 | G14: 0 | H14: =Size-a -> 100 | I14: =(EXP(alpha*(Tau+OldTau+zeta-2*a*psi))*((EXP(alpha*a*psi)-EXP(alpha*b*psi))^2))/((EXP(alpha*a*psi)-EXP(alpha*(2*OldTau+b*psi)))*(alpha^2)*(psi^2)) -> 6.4500307 | J14: =(EXP(alpha*(zeta+(2*b-a)*psi))*(-1+EXP(alpha*(-1)*Size*psi))*(EXP(alpha*(2*(Tau+OldTau)+a*psi))-EXP(alpha*(2*(Tau+OldTau)+b*psi))))/(((EXP(alpha*a*psi)-EXP(alpha*(2*OldTau+b*psi)))^2)*(alpha^2)*(psi^2)) -> 9.7965089e-07 | K14: =-Beta/alpha -> 180 | L14: =(-EXP(alpha*zeta)*Beta*(-1+EXP(alpha*Size*psi)-Size*alpha*psi))/((alpha^3)*(psi^2)) -> 32736.769 | M14: =Beta*Theta -> 14.4 | N14: =Beta*Theta -> 14.4 | O14: =kappa -> 90 | P14: =Gamma*Size -> 0 | Q14: =Size*Beta*Phi -> 324 | R14: =-(EXP(alpha*a*psi)+EXP(alpha*b*psi)*(-1+Size*psi*alpha))*(Beta*Phi)/((alpha*psi)*(EXP(alpha*a*psi)-EXP(alpha*b*psi))) -> 21.599901 | S14: =(EXP(alpha*(zeta-a*psi))*Beta*Phi*(-EXP(alpha*a*psi)*(-2+(-1)*Size*alpha*psi)+EXP(alpha*b*psi)*(-2+Size*alpha*psi)))/((alpha^3)*(psi^3)) -> 3647.8128 | T14: =Tau*Beta -> 126.02786 | U14: =Tau*Beta -> 126.02786 | V14: =Tau -> 0.70015477 | W14: =Profit+Utility -> 31321.328 | X14: =(2*ij*BRIJ)+2*jj*BRJJ -> 1625.7674 | Y14: =2*(ij*BCCIJ)+(2*jj*BCCJJ)+BCS+jj*BCPTJJ+2*(ij*BCPTIJ)+BCPTII+BCk -> 4202.2141 | Z14: =ij*BUTIJ+BUTII -> 33897.775 | AA14: =Revenue-Cost -> -2576.4467 | AB14: =Size -> 100 | AC14: =Welfare/(Size) -> 313.21328 | AD14: =Profit/(Size) -> -25.764467 | AE14: =Utility/(Size) -> 338.97775 | AF14: 308.66096
A15: =C14 -> 0.27605072 | B15: =(I15+J15)*Beta*2 -> 1908.9209 | C15: =(W15+B15*Theta-'W-Tax(All-Tax)'!$T$8)/B15 -> 0.29793821 | D15: 0.89605044 | E15: 0 | F15: 100 | G15: 0 | H15: =Size-a -> 100 | I15: =(EXP(alpha*(Tau+OldTau+zeta-2*a*psi))*((EXP(alpha*a*psi)-EXP(alpha*b*psi))^2))/((EXP(alpha*a*psi)-EXP(alpha*(2*OldTau+b*psi)))*(alpha^2)*(psi^2)) -> 5.3025574 | J15: =(EXP(alpha*(zeta+(2*b-a)*psi))*(-1+EXP(alpha*(-1)*Size*psi))*(EXP(alpha*(2*(Tau+OldTau)+a*psi))-EXP(alpha*(2*(Tau+OldTau)+b*psi))))/(((EXP(alpha*a*psi)-EXP(alpha*(2*OldTau+b*psi)))^2)*(alpha^2)*(psi^2)) -> 6.6209227e-07 | K15: =-Beta/alpha -> 180 | L15: =(-EXP(alpha*zeta)*Beta*(-1+EXP(alpha*Size*psi)-Size*alpha*psi))/((alpha^3)*(psi^2)) -> 32736.769 | M15: =Beta*Theta -> 49.689129 | N15: =Beta*Theta -> 49.689129 | O15: =kappa -> 90 | P15: =Gamma*Size -> 0 | Q15: =Size*Beta*Phi -> 324 | R15: =-(EXP(alpha*a*psi)+EXP(alpha*b*psi)*(-1+Size*psi*alpha))*(Beta*Phi)/((alpha*psi)*(EXP(alpha*a*psi)-EXP(alpha*b*psi))) -> 21.599901 | S15: =(EXP(alpha*(zeta-a*psi))*Beta*Phi*(-EXP(alpha*a*psi)*(-2+(-1)*Size*alpha*psi)+EXP(alpha*b*psi)*(-2+Size*alpha*psi)))/((alpha^3)*(psi^3)) -> 3647.8128 | T15: =Tau*Beta -> 161.28908 | U15: =Tau*Beta -> 161.28908 | V15: =Tau -> 0.89605044 | W15: =Profit+Utility -> 30907.878 | X15: =(2*ij*BRIJ)+2*jj*BRJJ -> 1710.4894 | Y15: =2*(ij*BCCIJ)+(2*jj*BCCJJ)+BCS+jj*BCPTJJ+2*(ij*BCPTIJ)+BCPTII+BCk -> 4493.8414 | Z15: =ij*BUTIJ+BUTII -> 33691.23 | AA15: =Revenue-Cost -> -2783.352 | AB15: =Size -> 100 | AC15: =Welfare/(Size) -> 309.07878 | AD15: =Profit/(Size) -> -27.83352 | AE15: =Utility/(Size) -> 336.9123 | AF15: 308.66096
A16: =C15 -> 0.29793821 | B16: =(I16+J16)*Beta*2 -> 1867.3263 | C16: =(W16+B16*Theta-'W-Tax(All-Tax)'!$T$8)/B16 -> 0.29818128 | D16: 0.91808092 | E16: 0 | F16: 100 | G16: 0 | H16: =Size-a -> 100 | I16: =(EXP(alpha*(Tau+OldTau+zeta-2*a*psi))*((EXP(alpha*a*psi)-EXP(alpha*b*psi))^2))/((EXP(alpha*a*psi)-EXP(alpha*(2*OldTau+b*psi)))*(alpha^2)*(psi^2)) -> 5.1870169 | J16: =(EXP(alpha*(zeta+(2*b-a)*psi))*(-1+EXP(alpha*(-1)*Size*psi))*(EXP(alpha*(2*(Tau+OldTau)+a*psi))-EXP(alpha*(2*(Tau+OldTau)+b*psi))))/(((EXP(alpha*a*psi)-EXP(alpha*(2*OldTau+b*psi)))^2)*(alpha^2)*(psi^2)) -> 6.335532e-07 | K16: =-Beta/alpha -> 180 | L16: =(-EXP(alpha*zeta)*Beta*(-1+EXP(alpha*Size*psi)-Size*alpha*psi))/((alpha^3)*(psi^2)) -> 32736.769 | M16: =Beta*Theta -> 53.628877 | N16: =Beta*Theta -> 53.628877 | O16: =kappa -> 90 | P16: =Gamma*Size -> 0 | Q16: =Size*Beta*Phi -> 324 | R16: =-(EXP(alpha*a*psi)+EXP(alpha*b*psi)*(-1+Size*psi*alpha))*(Beta*Phi)/((alpha*psi)*(EXP(alpha*a*psi)-EXP(alpha*b*psi))) -> 21.599901 | S16: =(EXP(alpha*(zeta-a*psi))*Beta*Phi*(-EXP(alpha*a*psi)*(-2+(-1)*Size*alpha*psi)+EXP(alpha*b*psi)*(-2+Size*alpha*psi)))/((alpha^3)*(psi^3)) -> 3647.8128 | T16: =Tau*Beta -> 165.25457 | U16: =Tau*Beta -> 165.25457 | V16: =Tau -> 0.91808092 | W16: =Profit+Utility -> 30866.55 | X16: =(2*ij*BRIJ)+2*jj*BRJJ -> 1714.3566 | Y16: =2*(ij*BCCIJ)+(2*jj*BCCJJ)+BCS+jj*BCPTJJ+2*(ij*BCPTIJ)+BCPTII+BCk -> 4518.239 | Z16: =ij*BUTIJ+BUTII -> 33670.432 | AA16: =Revenue-Cost -> -2803.8823 | AB16: =Size -> 100 | AC16: =Welfare/(Size) -> 308.6655 | AD16: =Profit/(Size) -> -28.038823 | AE16: =Utility/(Size) -> 336.70432 | AF16: 308.66096
A17: =C16 -> 0.29818128 | B17: =(I17+J17)*Beta*2 -> 1866.8782 | C17: =(W17+B17*Theta-'W-Tax(All-Tax)'!$T$8)/B17 -> 0.29818128 | D17: 0.91832091 | E17: 0 | F17: 100 | G17: 0 | H17: =Size-a -> 100 | I17: =(EXP(alpha*(Tau+OldTau+zeta-2*a*psi))*((EXP(alpha*a*psi)-EXP(alpha*b*psi))^2))/((EXP(alpha*a*psi)-EXP(alpha*(2*OldTau+b*psi)))*(alpha^2)*(psi^2)) -> 5.1857721 | J17: =(EXP(alpha*(zeta+(2*b-a)*psi))*(-1+EXP(alpha*(-1)*Size*psi))*(EXP(alpha*(2*(Tau+OldTau)+a*psi))-EXP(alpha*(2*(Tau+OldTau)+b*psi))))/(((EXP(alpha*a*psi)-EXP(alpha*(2*OldTau+b*psi)))^2)*(alpha^2)*(psi^2)) -> 6.3324917e-07 | K17: =-Beta/alpha -> 180 | L17: =(-EXP(alpha*zeta)*Beta*(-1+EXP(alpha*Size*psi)-Size*alpha*psi))/((alpha^3)*(psi^2)) -> 32736.769 | M17: =Beta*Theta -> 53.672631 | N17: =Beta*Theta -> 53.672631 | O17: =kappa -> 90 | P17: =Gamma*Size -> 0 | Q17: =Size*Beta*Phi -> 324 | R17: =-(EXP(alpha*a*psi)+EXP(alpha*b*psi)*(-1+Size*psi*alpha))*(Beta*Phi)/((alpha*psi)*(EXP(alpha*a*psi)-EXP(alpha*b*psi))) -> 21.599901 | S17: =(EXP(alpha*(zeta-a*psi))*Beta*Phi*(-EXP(alpha*a*psi)*(-2+(-1)*Size*alpha*psi)+EXP(alpha*b*psi)*(-2+Size*alpha*psi)))/((alpha^3)*(psi^3)) -> 3647.8128 | T17: =Tau*Beta -> 165.29776 | U17: =Tau*Beta -> 165.29776 | V17: =Tau -> 0.91832091 | W17: =Profit+Utility -> 30866.096 | X17: =(2*ij*BRIJ)+2*jj*BRJJ -> 1714.3933 | Y17: =2*(ij*BCCIJ)+(2*jj*BCCJJ)+BCS+jj*BCPTJJ+2*(ij*BCPTIJ)+BCPTII+BCk -> 4518.5055 | Z17: =ij*BUTIJ+BUTII -> 33670.208 | AA17: =Revenue-Cost -> -2804.1122 | AB17: =Size -> 100 | AC17: =Welfare/(Size) -> 308.66096 | AD17: =Profit/(Size) -> -28.041122 | AE17: =Utility/(Size) -> 336.70208 | AF17: 308.66096
A18: =C17 -> 0.29818128 | B18: =(I18+J18)*Beta*2 -> 1866.8782 | C18: =(W18+B18*Theta-'W-Tax(All-Tax)'!$T$8)/B18 -> 0.29818128 | D18: 0.91832091 | E18: 0 | F18: 100 | G18: 0 | H18: =Size-a -> 100 | I18: =(EXP(alpha*(Tau+OldTau+zeta-2*a*psi))*((EXP(alpha*a*psi)-EXP(alpha*b*psi))^2))/((EXP(alpha*a*psi)-EXP(alpha*(2*OldTau+b*psi)))*(alpha^2)*(psi^2)) -> 5.1857721 | J18: =(EXP(alpha*(zeta+(2*b-a)*psi))*(-1+EXP(alpha*(-1)*Size*psi))*(EXP(alpha*(2*(Tau+OldTau)+a*psi))-EXP(alpha*(2*(Tau+OldTau)+b*psi))))/(((EXP(alpha*a*psi)-EXP(alpha*(2*OldTau+b*psi)))^2)*(alpha^2)*(psi^2)) -> 6.3324917e-07 | K18: =-Beta/alpha -> 180 | L18: =(-EXP(alpha*zeta)*Beta*(-1+EXP(alpha*Size*psi)-Size*alpha*psi))/((alpha^3)*(psi^2)) -> 32736.769 | M18: =Beta*Theta -> 53.67263 | N18: =Beta*Theta -> 53.67263 | O18: =kappa -> 90 | P18: =Gamma*Size -> 0 | Q18: =Size*Beta*Phi -> 324 | R18: =-(EXP(alpha*a*psi)+EXP(alpha*b*psi)*(-1+Size*psi*alpha))*(Beta*Phi)/((alpha*psi)*(EXP(alpha*a*psi)-EXP(alpha*b*psi))) -> 21.599901 | S18: =(EXP(alpha*(zeta-a*psi))*Beta*Phi*(-EXP(alpha*a*psi)*(-2+(-1)*Size*alpha*psi)+EXP(alpha*b*psi)*(-2+Size*alpha*psi)))/((alpha^3)*(psi^3)) -> 3647.8128 | T18: =Tau*Beta -> 165.29776 | U18: =Tau*Beta -> 165.29776 | V18: =Tau -> 0.91832091 | W18: =Profit+Utility -> 30866.096 | X18: =(2*ij*BRIJ)+2*jj*BRJJ -> 1714.3933 | Y18: =2*(ij*BCCIJ)+(2*jj*BCCJJ)+BCS+jj*BCPTJJ+2*(ij*BCPTIJ)+BCPTII+BCk -> 4518.5055 | Z18: =ij*BUTIJ+BUTII -> 33670.208 | AA18: =Revenue-Cost -> -2804.1122 | AB18: =Size -> 100 | AC18: =Welfare/(Size) -> 308.66096 | AD18: =Profit/(Size) -> -28.041122 | AE18: =Utility/(Size) -> 336.70208 | AF18: 308.66096
A20: 0.08 | B20: =(I20+J20)*Beta*2 -> 2322.369 | C20: =(W20+B20*Theta-'W-Tax(All-Tax)'!$T$11)/B20 -> 0.27602066 | D20: 0.70000093 | E20: 0 | F20: 1000 | G20: 0 | H20: =Size-a -> 1000 | I20: =(EXP(alpha*(Tau+OldTau+zeta-2*a*psi))*((EXP(alpha*a*psi)-EXP(alpha*b*psi))^2))/((EXP(alpha*a*psi)-EXP(alpha*(2*OldTau+b*psi)))*(alpha^2)*(psi^2)) -> 6.451025 | J20: =(EXP(alpha*(zeta+(2*b-a)*psi))*(-1+EXP(alpha*(-1)*Size*psi))*(EXP(alpha*(2*(Tau+OldTau)+a*psi))-EXP(alpha*(2*(Tau+OldTau)+b*psi))))/(((EXP(alpha*a*psi)-EXP(alpha*(2*OldTau+b*psi)))^2)*(alpha^2)*(psi^2)) -> 2.2985285e-65 | K20: =-Beta/alpha -> 180 | L20: =(-EXP(alpha*zeta)*Beta*(-1+EXP(alpha*Size*psi)-Size*alpha*psi))/((alpha^3)*(psi^2)) -> 348412.75 | M20: =Beta*Theta -> 14.4 | N20: =Beta*Theta -> 14.4 | O20: =kappa -> 90 | P20: =Gamma*Size -> 0 | Q20: =Size*Beta*Phi -> 3240 | R20: =-(EXP(alpha*a*psi)+EXP(alpha*b*psi)*(-1+Size*psi*alpha))*(Beta*Phi)/((alpha*psi)*(EXP(alpha*a*psi)-EXP(alpha*b*psi))) -> 21.6 | S20: =(EXP(alpha*(zeta-a*psi))*Beta*Phi*(-EXP(alpha*a*psi)*(-2+(-1)*Size*alpha*psi)+EXP(alpha*b*psi)*(-2+Size*alpha*psi)))/((alpha^3)*(psi^3)) -> 41528.929 | T20: =Tau*Beta -> 126.00017 | U20: =Tau*Beta -> 126.00017 | V20: =Tau -> 0.70000093 | W20: =Profit+Utility -> 309116.19 | X20: =(2*ij*BRIJ)+2*jj*BRJJ -> 1625.6605 | Y20: =2*(ij*BCCIJ)+(2*jj*BCCJJ)+BCS+jj*BCPTJJ+2*(ij*BCPTIJ)+BCPTII+BCk -> 42083.403 | Z20: =ij*BUTIJ+BUTII -> 349573.94 | AA20: =Revenue-Cost -> -40457.743 | AB20: =Size -> 1000 | AC20: =Welfare/(Size) -> 309.11619 | AD20: =Profit/(Size) -> -40.457743 | AE20: =Utility/(Size) -> 349.57394 | AF20: 308.66096
A21: =C20 -> 0.27602066 | B21: =(I21+J21)*Beta*2 -> 1906.0267 | C21: =(W21+B21*Theta-'W-Tax(All-Tax)'!$T$11)/B21 -> 0.29797047 | D21: 0.8975679 | E21: 0 | F21: 1000 | G21: 0 | H21: =Size-a -> 1000 | I21: =(EXP(alpha*(Tau+OldTau+zeta-2*a*psi))*((EXP(alpha*a*psi)-EXP(alpha*b*psi))^2))/((EXP(alpha*a*psi)-EXP(alpha*(2*OldTau+b*psi)))*(alpha^2)*(psi^2)) -> 5.2945187 | J21: =(EXP(alpha*(zeta+(2*b-a)*psi))*(-1+EXP(alpha*(-1)*Size*psi))*(EXP(alpha*(2*(Tau+OldTau)+a*psi))-EXP(alpha*(2*(Tau+OldTau)+b*psi))))/(((EXP(alpha*a*psi)-EXP(alpha*(2*OldTau+b*psi)))^2)*(alpha^2)*(psi^2)) -> 1.5482654e-65 | K21: =-Beta/alpha -> 180 | L21: =(-EXP(alpha*zeta)*Beta*(-1+EXP(alpha*Size*psi)-Size*alpha*psi))/((alpha^3)*(psi^2)) -> 348412.75 | M21: =Beta*Theta -> 49.683719 | N21: =Beta*Theta -> 49.683719 | O21: =kappa -> 90 | P21: =Gamma*Size -> 0 | Q21: =Size*Beta*Phi -> 3240 | R21: =-(EXP(alpha*a*psi)+EXP(alpha*b*psi)*(-1+Size*psi*alpha))*(Beta*Phi)/((alpha*psi)*(EXP(alpha*a*psi)-EXP(alpha*b*psi))) -> 21.6 | S21: =(EXP(alpha*(zeta-a*psi))*Beta*Phi*(-EXP(alpha*a*psi)*(-2+(-1)*Size*alpha*psi)+EXP(alpha*b*psi)*(-2+Size*alpha*psi)))/((alpha^3)*(psi^3)) -> 41528.929 | T21: =Tau*Beta -> 161.56222 | U21: =Tau*Beta -> 161.56222 | V21: =Tau -> 0.8975679 | W21: =Profit+Utility -> 308702.8 | X21: =(2*ij*BRIJ)+2*jj*BRJJ -> 1710.7884 | Y21: =2*(ij*BCCIJ)+(2*jj*BCCJJ)+BCS+jj*BCPTJJ+2*(ij*BCPTIJ)+BCPTII+BCk -> 42373.755 | Z21: =ij*BUTIJ+BUTII -> 349365.77 | AA21: =Revenue-Cost -> -40662.967 | AB21: =Size -> 1000 | AC21: =Welfare/(Size) -> 308.7028 | AD21: =Profit/(Size) -> -40.662967 | AE21: =Utility/(Size) -> 349.36577 | AF21: 308.66096
A22: =C21 -> 0.29797047 | B22: =(I22+J22)*Beta*2 -> 2.2295919e-12 | C22: =(W22+B22*Theta-'W-Tax(All-Tax)'!$T$11)/B22 -> -837435263089555 | D22: 35.279547 | E22: 0 | F22: 1000 | G22: 0 | H22: =Size-a -> 1000 | I22: =(EXP(alpha*(Tau+OldTau+zeta-2*a*psi))*((EXP(alpha*a*psi)-EXP(alpha*b*psi))^2))/((EXP(alpha*a*psi)-EXP(alpha*(2*OldTau+b*psi)))*(alpha^2)*(psi^2)) -> 6.1933108e-15 | J22: =(EXP(alpha*(zeta+(2*b-a)*psi))*(-1+EXP(alpha*(-1)*Size*psi))*(EXP(alpha*(2*(Tau+OldTau)+a*psi))-EXP(alpha*(2*(Tau+OldTau)+b*psi))))/(((EXP(alpha*a*psi)-EXP(alpha*(2*OldTau+b*psi)))^2)*(alpha^2)*(psi^2)) -> 2.1185475e-95 | K22: =-Beta/alpha -> 180 | L22: =(-EXP(alpha*zeta)*Beta*(-1+EXP(alpha*Size*psi)-Size*alpha*psi))/((alpha^3)*(psi^2)) -> 348412.75 | M22: =Beta*Theta -> 53.634685 | N22: =Beta*Theta -> 53.634685 | O22: =kappa -> 90 | P22: =Gamma*Size -> 0 | Q22: =Size*Beta*Phi -> 3240 | R22: =-(EXP(alpha*a*psi)+EXP(alpha*b*psi)*(-1+Size*psi*alpha))*(Beta*Phi)/((alpha*psi)*(EXP(alpha*a*psi)-EXP(alpha*b*psi))) -> 21.6 | S22: =(EXP(alpha*(zeta-a*psi))*Beta*Phi*(-EXP(alpha*a*psi)*(-2+(-1)*Size*alpha*psi)+EXP(alpha*b*psi)*(-2+Size*alpha*psi)))/((alpha^3)*(psi^3)) -> 41528.929 | T22: =Tau*Beta -> 6350.3184 | U22: =Tau*Beta -> 6350.3184 | V22: =Tau -> 35.279547 | W22: =Profit+Utility -> 306793.82 | X22: =(2*ij*BRIJ)+2*jj*BRJJ -> 7.8658991e-11 | Y22: =2*(ij*BCCIJ)+(2*jj*BCCJJ)+BCS+jj*BCPTJJ+2*(ij*BCPTIJ)+BCPTII+BCk -> 41618.929 | Z22: =ij*BUTIJ+BUTII -> 348412.75 | AA22: =Revenue-Cost -> -41618.929 | AB22: =Size -> 1000 | AC22: =Welfare/(Size) -> 306.79382 | AD22: =Profit/(Size) -> -41.618929 | AE22: =Utility/(Size) -> 348.41275 | AF22: 308.66096
